Workbook

Sheet Overview
A2: July 2025 | F2: July 2026
B3: Revenue | C3: Nights | D3: Occupancy | G3: Revenue | H3: Nights | I3: Occupancy
A4: Tugela | B4: ='2026-7 F'!E7 -> 84001.48 | C4: ='2026-7 F'!E22 -> 14 | D4: =C4/31 -> 0.4516129 | F4: Tugela | G4: ='2026-7 F'!B7 -> 58684 | H4: ='2026-7 F'!B22 -> 9 | I4: =H4/31 -> 0.29032258
A5: Explorers Club | B5: ='2026-7 F'!Q7 -> 83212.5 | C5: ='2026-7 F'!Q22 -> 11 | D5: =C5/31 -> 0.35483871 | F5: Explorers Club | G5: ='2026-7 F'!N7 -> 30979.74 | H5: ='2026-7 F'!N22 -> 5 | I5: =H5/31 -> 0.16129032
A6: The Library | B6: ='2026-7 F'!AC7 -> 65340 | C6: ='2026-7 F'!AC22 -> 7 | D6: =C6/31 -> 0.22580645 | F6: The Library | G6: ='2026-7 F'!Z7 -> 25619.28 | H6: ='2026-7 F'!Z22 -> 4 | I6: =H6/31 -> 0.12903226
A7: Tockie's Cottage | B7: ='2026-7 F'!AO7 -> 44990 | C7: ='2026-7 F'!AO22 -> 13 | D7: =C7/31 -> 0.41935484 | F7: Tockie's Cottage | G7: ='2026-7 F'!AL7 -> 29145.22 | H7: ='2026-7 F'!AL22 -> 7 | I7: =H7/31 -> 0.22580645
A8: Kumbuk House | B8: ='2026-7 F'!BA7 -> 34133.08 | C8: ='2026-7 F'!BA22 -> 8 | D8: =C8/31 -> 0.25806452 | F8: Kumbuk House | G8: ='2026-7 F'!AX7 -> 0 | H8: ='2026-7 F'!AX22 -> 0 | I8: =H8/31 -> 0
A9: Cook's Cottage | B9: ='2026-7 F'!BM7 -> 36463.81 | C9: ='2026-7 F'!BM22 -> 10 | D9: =C9/31 -> 0.32258065 | F9: Cook's Cottage | G9: ='2026-7 F'!BJ7 -> 69148.925 | H9: ='2026-7 F'!BJ22 -> 17 | I9: =H9/31 -> 0.5483871
A11: Total | B11: =SUM(B4:B9) -> 348140.87 | C11: =SUM(C4:C9) -> 63 | D11: =C11/186 -> 0.33870968 | F11: Total | G11: =SUM(G4:G9) -> 213577.16 | H11: =SUM(H4:H9) -> 42 | I11: =H11/186 -> 0.22580645
A13: August 2025 | F13: 13 August 2026
B14: Revenue | C14: Nights | D14: Occupancy | G14: Revenue | H14: Nights | I14: Occupancy
A15: Tugela | B15: ='2026-7 F'!E8 -> 126106.36 | C15: ='2026-7 F'!E23 -> 21 | D15: =C15/31 -> 0.67741935 | F15: Tugela | G15: ='2026-7 F'!B8 -> 95953.56 | H15: ='2026-7 F'!B23 -> 13 | I15: =H15/31 -> 0.41935484
A16: Explorers Club | B16: ='2026-7 F'!Q8 -> 65215.59 | C16: ='2026-7 F'!Q23 -> 11 | D16: =C16/31 -> 0.35483871 | F16: Explorers Club | G16: ='2026-7 F'!N8 -> 62679.74 | H16: ='2026-7 F'!N23 -> 11 | I16: =H16/31 -> 0.35483871
A17: The Library | B17: ='2026-7 F'!AC8 -> 3000 | C17: ='2026-7 F'!AC23 -> 6 | D17: =C17/31 -> 0.19354839 | F17: The Library | G17: ='2026-7 F'!Z8 -> 10082.98 | H17: ='2026-7 F'!Z23 -> 2 | I17: =H17/31 -> 0.064516129
A18: Tockie's Cottage | B18: ='2026-7 F'!AO8 -> 37150 | C18: ='2026-7 F'!AO23 -> 7 | D18: =C18/31 -> 0.22580645 | F18: Tockie's Cottage | G18: ='2026-7 F'!AL8 -> 9074.68 | H18: ='2026-7 F'!AL23 -> 2 | I18: =H18/31 -> 0.064516129
A19: Kumbuk House | B19: ='2026-7 F'!BA8 -> 32080.32 | C19: ='2026-7 F'!BA23 -> 7 | D19: =C19/31 -> 0.22580645 | F19: Kumbuk House | G19: ='2026-7 F'!AX8 -> 0 | H19: ='2026-7 F'!AX23 -> 0 | I19: =H19/31 -> 0
A20: Cook's Cottage | B20: ='2026-7 F'!BM8 -> 49279.76 | C20: ='2026-7 F'!BM23 -> 15 | D20: =C20/31 -> 0.48387097 | F20: Cook's Cottage | G20: ='2026-7 F'!BJ8 -> 28264.8 | H20: ='2026-7 F'!BJ23 -> 8 | I20: =H20/31 -> 0.25806452
A22: Total | B22: =SUM(B15:B20) -> 312832.03 | C22: =SUM(C15:C20) -> 67 | D22: =C22/186 -> 0.36021505 | F22: Total | G22: =SUM(G15:G20) -> 206055.76 | H22: =SUM(H15:H20) -> 36 | I22: =H22/186 -> 0.19354839

Sheet Overall
A1: Franschhoek | 14 July 2026
B2: ='2026-7 F'!CH2 -> OTB @ 13 Aug 2026 | C2: ='2026-7 F'!CI2 -> OTB @ 30 Jul 2026 | D2: Variance | E2: Last Year Actual | F2: OTB vs LY
A3: Mar | B3: ='2026-7 F'!CH3 -> 898332 | C3: ='2026-7 F'!CI3 -> 898332 | D3: =B3-C3 -> 0 | E3: ='2026-7 F'!CK3 -> 980055.52 | F3: =B3-E3 -> -81723.52
A4: Apr | B4: ='2026-7 F'!CH4 -> 570496.93 | C4: ='2026-7 F'!CI4 -> 570496.93 | D4: =B4-C4 -> 0 | E4: ='2026-7 F'!CK4 -> 843064.17 | F4: =B4-E4 -> -272567.24
A5: May | B5: ='2026-7 F'!CH5 -> 258567.57 | C5: ='2026-7 F'!CI5 -> 258567.57 | D5: =B5-C5 -> 0 | E5: ='2026-7 F'!CK5 -> 361133.03 | F5: =B5-E5 -> -102565.46
A6: Jun | B6: ='2026-7 F'!CH6 -> 111926.77 | C6: ='2026-7 F'!CI6 -> 111926.77 | D6: =B6-C6 -> 0 | E6: ='2026-7 F'!CK6 -> 236124.58 | F6: =B6-E6 -> -124197.81
A7: Jul | B7: ='2026-7 F'!CH7 -> 213577.16 | C7: ='2026-7 F'!CI7 -> 212744.11 | D7: =B7-C7 -> 833.055 | E7: ='2026-7 F'!CK7 -> 348140.87 | F7: =B7-E7 -> -134563.71
A8: Aug | B8: ='2026-7 F'!CH8 -> 206055.76 | C8: ='2026-7 F'!CI8 -> 184336.96 | D8: =B8-C8 -> 21718.8 | E8: ='2026-7 F'!CK8 -> 312832.03 | F8: =B8-E8 -> -106776.27
A9: Sept | B9: ='2026-7 F'!CH9 -> 251828.98 | C9: ='2026-7 F'!CI9 -> 262164.58 | D9: =B9-C9 -> -10335.6 | E9: ='2026-7 F'!CK9 -> 278006.63 | F9: =B9-E9 -> -26177.65
A10: Oct | B10: ='2026-7 F'!CH10 -> 160578.46 | C10: ='2026-7 F'!CI10 -> 181249.66 | D10: =B10-C10 -> -20671.2 | E10: ='2026-7 F'!CK10 -> 610307.48 | F10: =B10-E10 -> -449729.02
A11: Nov | B11: ='2026-7 F'!CH11 -> 606454.37 | C11: ='2026-7 F'!CI11 -> 582170.18 | D11: =B11-C11 -> 24284.19 | E11: ='2026-7 F'!CK11 -> 912396.97 | F11: =B11-E11 -> -305942.6
A12: Dec | B12: ='2026-7 F'!CH12 -> 1182308.3 | C12: ='2026-7 F'!CI12 -> 1182308.3 | D12: =B12-C12 -> 0 | E12: ='2026-7 F'!CK12 -> 1216440.4 | F12: =B12-E12 -> -34132.09
A13: TOTAL | C13: =SUM(#REF!) -> #REF! | D13: =SUM(D3:D7) -> 833.055 | E13: =SUM(#REF!) -> #REF! | F13: =B13-E13 -> #REF!
A14: Room Nights | G14: Occupancy
B15: =B2 -> OTB @ 13 Aug 2026 | C15: =C2 -> OTB @ 30 Jul 2026 | D15: Variance | E15: Last Year Actual | F15: OTB vs LY | G15: =B2 -> OTB @ 13 Aug 2026 | H15: =C2 -> OTB @ 30 Jul 2026 | I15: Variance | J15: Last Year Actual | K15: OTB vs LY
A16: Jun | B16: ='2026-7 F'!CH21 -> 16 | C16: ='2026-7 F'!CI21 -> 16 | D16: =B16-C16 -> 0 | E16: ='2026-7 F'!CK21 -> 44 | F16: =B16-E16 -> -28 | G16: =B16/180 -> 0.088888889 | H16: =C16/180 -> 0.088888889 | I16: =G16-H16 -> 0 | J16: =E16/180 -> 0.24444444 | K16: =G16-J16 -> -0.15555556
A22: Jul | B22: ='2026-7 F'!CH22 -> 42 | C22: ='2026-7 F'!CI22 -> 42 | D22: =B22-C22 -> 0 | E22: ='2026-7 F'!CK22 -> 63 | F22: =B22-E22 -> -21 | G22: =B22/186 -> 0.22580645 | H22: =C22/186 -> 0.22580645 | I22: =G22-H22 -> 0 | J22: =E22/186 -> 0.33870968 | K22: =G22-J22 -> -0.11290323
A23: Aug | B23: ='2026-7 F'!CH23 -> 36 | C23: ='2026-7 F'!CI23 -> 33 | D23: =B23-C23 -> 3 | E23: ='2026-7 F'!CK23 -> 67 | F23: =B23-E23 -> -31 | G23: =B23/186 -> 0.19354839 | H23: =C23/186 -> 0.17741935 | I23: =G23-H23 -> 0.016129032 | J23: =E23/186 -> 0.36021505 | K23: =G23-J23 -> -0.16666667
A24: Sept | B24: ='2026-7 F'!CH24 -> 45 | C24: ='2026-7 F'!CI24 -> 46 | D24: =B24-C24 -> -1 | E24: ='2026-7 F'!CK24 -> 60 | F24: =B24-E24 -> -15 | G24: =B24/180 -> 0.25 | H24: =C24/180 -> 0.25555556 | I24: =G24-H24 -> -0.0055555556 | J24: =E24/180 -> 0.33333333 | K24: =G24-J24 -> -0.083333333
A25: Oct | B25: ='2026-7 F'!CH25 -> 20 | C25: ='2026-7 F'!CI25 -> 22 | D25: =B25-C25 -> -2 | E25: ='2026-7 F'!CK25 -> 72 | F25: =B25-E25 -> -52 | G25: =B25/186 -> 0.10752688 | H25: =C25/186 -> 0.11827957 | I25: =G25-H25 -> -0.010752688 | J25: =E25/186 -> 0.38709677 | K25: =G25-J25 -> -0.27956989
A26: Nov | B26: ='2026-7 F'!CH26 -> 80 | C26: ='2026-7 F'!CI26 -> 77 | D26: =B26-C26 -> 3 | E26: ='2026-7 F'!CK26 -> 115 | F26: =B26-E26 -> -35 | G26: =B26/180 -> 0.44444444 | H26: =C26/180 -> 0.42777778 | I26: =G26-H26 -> 0.016666667 | J26: =E26/180 -> 0.63888889 | K26: =G26-J26 -> -0.19444444
A27: Nov | B27: ='2026-7 F'!CH27 -> 129 | C27: ='2026-7 F'!CI27 -> 124 | D27: =B27-C27 -> 5 | E27: ='2026-7 F'!CK27 -> 137 | F27: =B27-E27 -> -8 | G27: =B27/186 -> 0.69354839 | H27: =C27/186 -> 0.66666667 | I27: =G27-H27 -> 0.02688172 | J27: =E27/186 -> 0.73655914 | K27: =G27-J27 -> -0.043010753
A28: ADR
B29: =B2 -> OTB @ 13 Aug 2026 | C29: =C2 -> OTB @ 30 Jul 2026 | D29: Variance | E29: Last Year Actual | F29: OTB vs LY
A30: Jun | B30: =#REF!/B16 -> #REF! | C30: =#REF!/C16 -> #REF! | D30: =B30-C30 -> #REF! | E30: =#REF!/E16 -> #REF! | F30: =B30-E30 -> #REF! | H30: Franschhoek properties only, excludes Willow Point
A36: Jul | B36: =B7/B22 -> 5085.1706 | C36: =C7/C22 -> 5065.336 | D36: =B36-C36 -> 19.834643 | E36: =E7/E22 -> 5526.0456 | F36: =B36-E36 -> -440.87496
A37: Aug | B37: =B8/B23 -> 5723.7711 | C37: =C8/C23 -> 5585.9685 | D37: =B37-C37 -> 137.80263 | E37: =E8/E23 -> 4669.1348 | F37: =B37-E37 -> 1054.6363
A38: Sept | B38: =B9/B24 -> 5596.1996 | C38: =C9/C24 -> 5699.23 | D38: =B38-C38 -> -103.03044 | E38: =E9/E24 -> 4633.4438 | F38: =B38-E38 -> 962.75572
A39: Oct | B39: =B10/B25 -> 8028.923 | C39: =C10/C25 -> 8238.6209 | D39: =B39-C39 -> -209.69791 | E39: =E10/E25 -> 8476.4928 | F39: =B39-E39 -> -447.56978
A40: Nov | B40: =B11/B26 -> 7580.6796 | C40: =C11/C26 -> 7560.6517 | D40: =B40-C40 -> 20.027937 | E40: =E11/E26 -> 7933.8867 | F40: =B40-E40 -> -353.20707
A41: Dec | B41: =B12/B27 -> 9165.1804 | C41: =C12/C27 -> 9534.7441 | D41: =B41-C41 -> -369.56373 | E41: =E12/E27 -> 8879.1267 | F41: =B41-E41 -> 286.05367

Sheet 2025-6 F
A1: Tugela | Finacial Year | 2025/26 | L1: Explorer's Club | Finacial Year | 2025/26 | W1: The Library | Finacial Year | 2025/26 | AH1: Tockie's Cottage | Finacial Year | 2025/26 | AS1: Kumbuk House | Finacial Year | 2025/26 | BD1: Cook's Cottage | Finacial Year | 2025/26 | BO1: Franschhoek | Financial Year | 2025/26
B2: OTB @ 17 Mar 2026 | C2: OTB @ 2 Mar 2026 | D2: Variance | E2: Previous FY | F2: OTB vs PY | M2: OTB @ 17 Mar 2026 | N2: OTB @ 2 Mar 2026 | O2: Variance | P2: Previous FY | Q2: OTB vs PY | X2: OTB @ 17 Mar 2026 | Y2: OTB @ 2 Mar 2026 | Z2: Variance | AA2: Previous FY | AB2: OTB vs PY | AI2: OTB @ 17 Mar 2026 | AJ2: OTB @ 2 Mar 2026 | AK2: Variance | AL2: Previous FY | AM2: OTB vs PY | AT2: OTB @ 17 Mar 2026 | AU2: OTB @ 2 Mar 2026 | AV2: Variance | AW2: Previous FY | AX2: OTB vs PY | BE2: OTB @ 17 Mar 2026 | BF2: OTB @ 2 Mar 2026 | BG2: Variance | BH2: Previous FY | BI2: OTB vs PY | BP2: OTB @ 17 Mar 2026 | BQ2: OTB @ 2 Mar 2026 | BR2: Variance | BS2: Previous FY | BT2: OTB vs PY
A3: Mar-25 | B3: 275157.56 | C3: 275157.56 | D3: =B3-C3 -> 0 | E3: 219376.63 | F3: =C3-E3 -> 55780.93 | L3: Mar-25 | M3: 214300 | N3: 214300 | O3: =M3-N3 -> 0 | P3: 135505 | Q3: =N3-P3 -> 78795 | W3: Mar-25 | X3: 169354 | Y3: 169354 | Z3: =X3-Y3 -> 0 | AA3: 75000 | AB3: =Y3-AA3 -> 94354 | AH3: Mar-25 | AI3: 136700 | AJ3: 136700 | AK3: =AI3-AJ3 -> 0 | AL3: 144524.97 | AM3: =AJ3-AL3 -> -7824.97 | AS3: Mar-25 | AT3: 42900 | AU3: 42900 | AV3: =AT3-AU3 -> 0 | AW3: 104906.37 | AX3: =AU3-AW3 -> -62006.37 | BD3: Mar-25 | BE3: 130393.96 | BF3: 130393.96 | BG3: =BE3-BF3 -> 0 | BH3: 102303.12 | BI3: =BF3-BH3 -> 28090.84 | BO3: Mar-25 | BP3: =B3+M3+X3+AI3+AT3+BE3 -> 968805.52 | BQ3: =C3+N3+Y3+AJ3+AU3+BF3 -> 968805.52 | BR3: =BP3-BQ3 -> 0 | BS3: =E3+P3+AA3+AL3+AW3+BH3 -> 781616.09 | BT3: =BQ3-BS3 -> 187189.43
A4: Apr-25 | B4: 228600 | C4: 228600 | D4: =B4-C4 -> 0 | E4: 154046.09 | F4: =C4-E4 -> 74553.91 | L4: Apr-25 | M4: 226776.92 | N4: 226776.92 | O4: =M4-N4 -> 0 | P4: 118397.85 | Q4: =N4-P4 -> 108379.07 | W4: Apr-25 | X4: 25946.25 | Y4: 25946.25 | Z4: =X4-Y4 -> 0 | AA4: 75000 | AB4: =Y4-AA4 -> -49053.75 | AH4: Apr-25 | AI4: 146841.43 | AJ4: 146841.43 | AK4: =AI4-AJ4 -> 0 | AL4: 77489.28 | AM4: =AJ4-AL4 -> 69352.15 | AS4: Apr-25 | AT4: 92760.24 | AU4: 92760.24 | AV4: =AT4-AU4 -> 0 | AW4: 56836.47 | AX4: =AU4-AW4 -> 35923.77 | BD4: Apr-25 | BE4: 111633.39 | BF4: 111633.39 | BG4: =BE4-BF4 -> 0 | BH4: 46277.29 | BI4: =BF4-BH4 -> 65356.1 | BO4: Apr-25 | BP4: =B4+M4+X4+AI4+AT4+BE4 -> 832558.23 | BQ4: =C4+N4+Y4+AJ4+AU4+BF4 -> 832558.23 | BR4: =BP4-BQ4 -> 0 | BS4: =E4+P4+AA4+AL4+AW4+BH4 -> 528046.98 | BT4: =BQ4-BS4 -> 304511.25
A5: May-25 | B5: 122925 | C5: 122925 | D5: =B5-C5 -> 0 | E5: 87739.56 | F5: =C5-E5 -> 35185.44 | L5: May-25 | M5: 68358.34 | N5: 68358.34 | O5: =M5-N5 -> 0 | P5: 66476.01 | Q5: =N5-P5 -> 1882.33 | W5: May-25 | X5: 43065 | Y5: 43065 | Z5: =X5-Y5 -> 0 | AA5: 39000 | AB5: =Y5-AA5 -> 4065 | AH5: May-25 | AI5: 46125.75 | AJ5: 46125.75 | AK5: =AI5-AJ5 -> 0 | AL5: 26100 | AM5: =AJ5-AL5 -> 20025.75 | AS5: May-25 | AT5: 19710.9 | AU5: 19710.9 | AV5: =AT5-AU5 -> 0 | AW5: 35065.26 | AX5: =AU5-AW5 -> -15354.36 | BD5: May-25 | BE5: 60948.04 | BF5: 60948.04 | BG5: =BE5-BF5 -> 0 | BH5: 7367.09 | BI5: =BF5-BH5 -> 53580.95 | BO5: May-25 | BP5: =B5+M5+X5+AI5+AT5+BE5 -> 361133.03 | BQ5: =C5+N5+Y5+AJ5+AU5+BF5 -> 361133.03 | BR5: =BP5-BQ5 -> 0 | BS5: =E5+P5+AA5+AL5+AW5+BH5 -> 261747.92 | BT5: =BQ5-BS5 -> 99385.11
A6: Jun-25 | B6: 53982.5 | C6: 53982.5 | D6: =B6-C6 -> 0 | E6: 16425.84 | F6: =C6-E6 -> 37556.66 | L6: Jun-25 | M6: 105182.25 | N6: 105182.25 | O6: =M6-N6 -> 0 | P6: 0 | Q6: =N6-P6 -> 105182.25 | W6: Jun-25 | X6: 23363.19 | Y6: 23363.19 | Z6: =X6-Y6 -> 0 | AA6: 29903.96 | AB6: =Y6-AA6 -> -6540.77 | AH6: Jun-25 | AI6: 42350 | AJ6: 42350 | AK6: =AI6-AJ6 -> 0 | AL6: 22575.56 | AM6: =AJ6-AL6 -> 19774.44 | AS6: Jun-25 | AT6: 11246.64 | AU6: 11246.64 | AV6: =AT6-AU6 -> 0 | AW6: 0 | AX6: =AU6-AW6 -> 11246.64 | BD6: Jun-25 | BE6: 0 | BF6: 0 | BG6: =BE6-BF6 -> 0 | BH6: 29465.88 | BI6: =BF6-BH6 -> -29465.88 | BO6: Jun-25 | BP6: =B6+M6+X6+AI6+AT6+BE6 -> 236124.58 | BQ6: =C6+N6+Y6+AJ6+AU6+BF6 -> 236124.58 | BR6: =BP6-BQ6 -> 0 | BS6: =E6+P6+AA6+AL6+AW6+BH6 -> 98371.24 | BT6: =BQ6-BS6 -> 137753.34
A7: Jul-25 | B7: 84001.48 | C7: 84001.48 | D7: =B7-C7 -> 0 | E7: 76478.65 | F7: =C7-E7 -> 7522.83 | L7: Jul-25 | M7: 83212.5 | N7: 83212.5 | O7: =M7-N7 -> 0 | P7: 59932.06 | Q7: =N7-P7 -> 23280.44 | W7: Jul-25 | X7: 65340 | Y7: 65340 | Z7: =X7-Y7 -> 0 | AA7: 35600 | AB7: =Y7-AA7 -> 29740 | AH7: Jul-25 | AI7: 44990 | AJ7: 44990 | AK7: =AI7-AJ7 -> 0 | AL7: 33499.84 | AM7: =AJ7-AL7 -> 11490.16 | AS7: Jul-25 | AT7: 34133.08 | AU7: 34133.08 | AV7: =AT7-AU7 -> 0 | AW7: 9900 | AX7: =AU7-AW7 -> 24233.08 | BD7: Jul-25 | BE7: 36463.81 | BF7: 36463.81 | BG7: =BE7-BF7 -> 0 | BH7: 38448.58 | BI7: =BF7-BH7 -> -1984.77 | BO7: Jul-25 | BP7: =B7+M7+X7+AI7+AT7+BE7 -> 348140.87 | BQ7: =C7+N7+Y7+AJ7+AU7+BF7 -> 348140.87 | BR7: =BP7-BQ7 -> 0 | BS7: =E7+P7+AA7+AL7+AW7+BH7 -> 253859.13 | BT7: =BQ7-BS7 -> 94281.74
A8: Aug-25 | B8: 126106.36 | C8: 126106.36 | D8: =B8-C8 -> 0 | E8: 70973.6 | F8: =C8-E8 -> 55132.76 | L8: Aug-25 | M8: 65215.59 | N8: 65215.59 | O8: =M8-N8 -> 0 | P8: 11700 | Q8: =N8-P8 -> 53515.59 | W8: Aug-25 | X8: 3000 | Y8: 3000 | Z8: =X8-Y8 -> 0 | AA8: 16110 | AB8: =Y8-AA8 -> -13110 | AH8: Aug-25 | AI8: 37150 | AJ8: 37150 | AK8: =AI8-AJ8 -> 0 | AL8: 17956.72 | AM8: =AJ8-AL8 -> 19193.28 | AS8: Aug-25 | AT8: 32080.32 | AU8: 32080.32 | AV8: =AT8-AU8 -> 0 | AW8: 0 | AX8: =AU8-AW8 -> 32080.32 | BD8: Aug-25 | BE8: 49279.76 | BF8: 49279.76 | BG8: =BE8-BF8 -> 0 | BH8: 75908.33 | BI8: =BF8-BH8 -> -26628.57 | BO8: Aug-25 | BP8: =B8+M8+X8+AI8+AT8+BE8 -> 312832.03 | BQ8: =C8+N8+Y8+AJ8+AU8+BF8 -> 312832.03 | BR8: =BP8-BQ8 -> 0 | BS8: =E8+P8+AA8+AL8+AW8+BH8 -> 192648.65 | BT8: =BQ8-BS8 -> 120183.38
A9: Sep-25 | B9: 88857.68 | C9: 88857.68 | D9: =B9-C9 -> 0 | E9: 114423.23 | F9: =C9-E9 -> -25565.55 | L9: Sep-25 | M9: 72719.16 | N9: 72719.16 | O9: =M9-N9 -> 0 | P9: 37291.26 | Q9: =N9-P9 -> 35427.9 | W9: Sep-25 | X9: 16494.15 | Y9: 16494.15 | Z9: =X9-Y9 -> 0 | AA9: 38190 | AB9: =Y9-AA9 -> -21695.85 | AH9: Sep-25 | AI9: 0 | AJ9: 0 | AK9: =AI9-AJ9 -> 0 | AL9: 42353.44 | AM9: =AJ9-AL9 -> -42353.44 | AS9: Sep-25 | AT9: 60683.76 | AU9: 60683.76 | AV9: =AT9-AU9 -> 0 | AW9: 41550 | AX9: =AU9-AW9 -> 19133.76 | BD9: Sep-25 | BE9: 39251.88 | BF9: 39251.88 | BG9: =BE9-BF9 -> 0 | BH9: 42278.5 | BI9: =BF9-BH9 -> -3026.62 | BO9: Sep-25 | BP9: =B9+M9+X9+AI9+AT9+BE9 -> 278006.63 | BQ9: =C9+N9+Y9+AJ9+AU9+BF9 -> 278006.63 | BR9: =BP9-BQ9 -> 0 | BS9: =E9+P9+AA9+AL9+AW9+BH9 -> 316086.43 | BT9: =BQ9-BS9 -> -38079.8
A10: Oct-25 | B10: 243705 | C10: 243705 | D10: =B10-C10 -> 0 | E10: 135900 | F10: =C10-E10 -> 107805 | L10: Oct-25 | M10: 170235.49 | N10: 170235.49 | O10: =M10-N10 -> 0 | P10: 85670 | Q10: =N10-P10 -> 84565.49 | W10: Oct-25 | X10: 55220 | Y10: 55220 | Z10: =X10-Y10 -> 0 | AA10: 62880 | AB10: =Y10-AA10 -> -7660 | AH10: Oct-25 | AI10: 49280 | AJ10: 49280 | AK10: =AI10-AJ10 -> 0 | AL10: 74750 | AM10: =AJ10-AL10 -> -25470 | AS10: Oct-25 | AT10: 0 | AU10: 0 | AV10: =AT10-AU10 -> 0 | AW10: 28600 | AX10: =AU10-AW10 -> -28600 | BD10: Oct-25 | BE10: 92166.99 | BF10: 92166.99 | BG10: =BE10-BF10 -> 0 | BH10: 60525 | BI10: =BF10-BH10 -> 31641.99 | BO10: Oct-25 | BP10: =B10+M10+X10+AI10+AT10+BE10 -> 610607.48 | BQ10: =C10+N10+Y10+AJ10+AU10+BF10 -> 610607.48 | BR10: =BP10-BQ10 -> 0 | BS10: =E10+P10+AA10+AL10+AW10+BH10 -> 448325 | BT10: =BQ10-BS10 -> 162282.48
A11: Nov-25 | B11: 273702.73 | C11: 273702.73 | D11: =B11-C11 -> 0 | E11: 304087.5 | F11: =C11-E11 -> -30384.77 | L11: Nov-25 | M11: 210442.34 | N11: 210442.34 | O11: =M11-N11 -> 0 | P11: 202913 | Q11: =N11-P11 -> 7529.34 | W11: Nov-25 | X11: 129515.4 | Y11: 129515.4 | Z11: =X11-Y11 -> 0 | AA11: 65250 | AB11: =Y11-AA11 -> 64265.4 | AH11: Nov-25 | AI11: 170104 | AJ11: 170104 | AK11: =AI11-AJ11 -> 0 | AL11: 156045 | AM11: =AJ11-AL11 -> 14059 | AS11: Nov-25 | AT11: 0 | AU11: 0 | AV11: =AT11-AU11 -> 0 | AW11: 120624.08 | AX11: =AU11-AW11 -> -120624.08 | BD11: Nov-25 | BE11: 128632.5 | BF11: 128632.5 | BG11: =BE11-BF11 -> 0 | BH11: 39420 | BI11: =BF11-BH11 -> 89212.5 | BO11: Nov-25 | BP11: =B11+M11+X11+AI11+AT11+BE11 -> 912396.97 | BQ11: =C11+N11+Y11+AJ11+AU11+BF11 -> 912396.97 | BR11: =BP11-BQ11 -> 0 | BS11: =E11+P11+AA11+AL11+AW11+BH11 -> 888339.58 | BT11: =BQ11-BS11 -> 24057.39
A12: Dec-25 | B12: 297198.24 | C12: 297198.24 | D12: =B12-C12 -> 0 | E12: 279330 | F12: =C12-E12 -> 17868.24 | L12: Dec-25 | M12: 282295.3 | N12: 282295.3 | O12: =M12-N12 -> 0 | P12: 219450 | Q12: =N12-P12 -> 62845.3 | W12: Dec-25 | X12: 188548.3 | Y12: 188548.3 | Z12: =X12-Y12 -> 0 | AA12: 240224 | AB12: =Y12-AA12 -> -51675.7 | AH12: Dec-25 | AI12: 237490 | AJ12: 237490 | AK12: =AI12-AJ12 -> 0 | AL12: 199600 | AM12: =AJ12-AL12 -> 37890 | AS12: Dec-25 | AT12: 122111.6 | AU12: 122111.6 | AV12: =AT12-AU12 -> 0 | AW12: 182827.17 | AX12: =AU12-AW12 -> -60715.57 | BD12: Dec-25 | BE12: 149955.71 | BF12: 149955.71 | BG12: =BE12-BF12 -> 0 | BH12: 150855 | BI12: =BF12-BH12 -> -899.29 | BO12: Dec-25 | BP12: =B12+M12+X12+AI12+AT12+BE12 -> 1277599.2 | BQ12: =C12+N12+Y12+AJ12+AU12+BF12 -> 1277599.2 | BR12: =BP12-BQ12 -> 0 | BS12: =E12+P12+AA12+AL12+AW12+BH12 -> 1272286.2 | BT12: =BQ12-BS12 -> 5312.98
A13: Jan-26 | B13: 331249.32 | C13: 331249.32 | D13: =B13-C13 -> 0 | E13: 294488.62 | F13: =C13-E13 -> 36760.7 | L13: Jan-26 | M13: 272540 | N13: 272540 | O13: =M13-N13 -> 0 | P13: 281378 | Q13: =N13-P13 -> -8838 | W13: Jan-26 | X13: 323097.67 | Y13: 323097.67 | Z13: =X13-Y13 -> 0 | AA13: 308400 | AB13: =Y13-AA13 -> 14697.67 | AH13: Jan-26 | AI13: 201907.01 | AJ13: 201907.01 | AK13: =AI13-AJ13 -> 0 | AL13: 192000 | AM13: =AJ13-AL13 -> 9907.01 | AS13: Jan-26 | AT13: 236635.77 | AU13: 236635.77 | AV13: =AT13-AU13 -> 0 | AW13: 213097.84 | AX13: =AU13-AW13 -> 23537.93 | BD13: Jan-26 | BE13: 134804.2 | BF13: 134804.2 | BG13: =BE13-BF13 -> 0 | BH13: 145295.73 | BI13: =BF13-BH13 -> -10491.53 | BO13: Jan-26 | BP13: =B13+M13+X13+AI13+AT13+BE13 -> 1500234 | BQ13: =C13+N13+Y13+AJ13+AU13+BF13 -> 1500234 | BR13: =BP13-BQ13 -> 0 | BS13: =E13+P13+AA13+AL13+AW13+BH13 -> 1434660.2 | BT13: =BQ13-BS13 -> 65573.78
A14: Feb-26 | B14: 305112.5 | C14: 305112.5 | D14: =B14-C14 -> 0 | E14: 202500 | F14: =C14-E14 -> 102612.5 | L14: Feb-26 | M14: 204584.9 | N14: 204584.9 | O14: =M14-N14 -> 0 | P14: 250100 | Q14: =N14-P14 -> -45515.1 | W14: Feb-26 | X14: 241860.09 | Y14: 241860.09 | Z14: =X14-Y14 -> 0 | AA14: 237875 | AB14: =Y14-AA14 -> 3985.09 | AH14: Feb-26 | AI14: 150116.45 | AJ14: 150116.45 | AK14: =AI14-AJ14 -> 0 | AL14: 134950 | AM14: =AJ14-AL14 -> 15166.45 | AS14: Feb-26 | AT14: 22440 | AU14: 22440 | AV14: =AT14-AU14 -> 0 | AW14: 122825.9 | AX14: =AU14-AW14 -> -100385.9 | BD14: Feb-26 | BE14: 119440.38 | BF14: 117013.53 | BG14: =BE14-BF14 -> 2426.85 | BH14: 135510.24 | BI14: =BF14-BH14 -> -18496.71 | BO14: Feb-26 | BP14: =B14+M14+X14+AI14+AT14+BE14 -> 1043554.3 | BQ14: =C14+N14+Y14+AJ14+AU14+BF14 -> 1041127.5 | BR14: =BP14-BQ14 -> 2426.85 | BS14: =E14+P14+AA14+AL14+AW14+BH14 -> 1083761.1 | BT14: =BQ14-BS14 -> -42633.67
A15: TOTAL | B15: =SUM(B3:B14) -> 2430598.4 | C15: =SUM(C3:C14) -> 2430598.4 | D15: =B15-C15 -> 0 | E15: =SUM(E3:E14) -> 1955769.7 | F15: =C15-E15 -> 474828.65 | L15: TOTAL | M15: =SUM(M3:M14) -> 1975862.8 | N15: =SUM(N3:N14) -> 1975862.8 | O15: =M15-N15 -> 0 | P15: =SUM(P3:P14) -> 1468813.2 | Q15: =N15-P15 -> 507049.61 | W15: TOTAL | X15: =SUM(X3:X14) -> 1284804.1 | Y15: =SUM(Y3:Y14) -> 1284804.1 | Z15: =X15-Y15 -> 0 | AA15: =SUM(AA3:AA14) -> 1223433 | AB15: =Y15-AA15 -> 61371.09 | AH15: TOTAL | AI15: =SUM(AI3:AI14) -> 1263054.6 | AJ15: =SUM(AJ3:AJ14) -> 1263054.6 | AK15: =AI15-AJ15 -> 0 | AL15: =SUM(AL3:AL14) -> 1121844.8 | AM15: =AJ15-AL15 -> 141209.83 | AS15: TOTAL | AT15: =SUM(AT3:AT14) -> 674702.31 | AU15: =SUM(AU3:AU14) -> 674702.31 | AV15: =AT15-AU15 -> 0 | AW15: =SUM(AW3:AW14) -> 916233.09 | AX15: =AU15-AW15 -> -241530.78 | BD15: TOTAL | BE15: =SUM(BE3:BE14) -> 1052970.6 | BF15: =SUM(BF3:BF14) -> 1050543.8 | BG15: =BE15-BF15 -> 2426.85 | BH15: =SUM(BH3:BH14) -> 873654.76 | BI15: =BF15-BH15 -> 176889.01 | BO15: TOTAL | BP15: =SUM(BP3:BP14) -> 8681992.8 | BQ15: =SUM(BQ3:BQ14) -> 8679565.9 | BR15: =BP15-BQ15 -> 2426.85 | BS15: =SUM(BS3:BS14) -> 7559748.5 | BT15: =BQ15-BS15 -> 1119817.4
A16: Room Nights | G16: Occupancy | L16: Room Nights | R16: Occupancy | W16: Room Nights | AC16: Occupancy | AH16: Room Nights | AN16: Occupancy | AS16: Room Nights | AY16: Occupancy | BD16: Room Nights | BJ16: Occupancy | BO16: Room Nights | BU16: Average Occupancy
B17: OTB @ 17 Mar 2026 | C17: OTB @ 2 Mar 2026 | D17: Variance | E17: Previous FY | F17: OTB vs PY | G17: OTB @ 17 Mar 2026 | H17: OTB @ 2 Mar 2026 | I17: Variance | J17: Previous FY | K17: OTB vs PY | M17: OTB @ 17 Mar 2026 | N17: OTB @ 2 Mar 2026 | O17: Variance | P17: Previous FY | Q17: OTB vs PY | R17: OTB @ 17 Mar 2026 | S17: OTB @ 2 Mar 2026 | T17: Variance | U17: Previous FY | V17: OTB vs PY | X17: OTB @ 17 Mar 2026 | Y17: OTB @ 2 Mar 2026 | Z17: Variance | AA17: Previous FY | AB17: OTB vs PY | AC17: OTB @ 17 Mar 2026 | AD17: OTB @ 2 Mar 2026 | AE17: Variance | AF17: Previous FY | AG17: OTB vs PY | AI17: OTB @ 17 Mar 2026 | AJ17: OTB @ 2 Mar 2026 | AK17: Variance | AL17: Previous FY | AM17: OTB vs PY | AN17: OTB @ 17 Mar 2026 | AO17: OTB @ 2 Mar 2026 | AP17: Variance | AQ17: Previous FY | AR17: OTB vs PY | AT17: OTB @ 17 Mar 2026 | AU17: OTB @ 2 Mar 2026 | AV17: Variance | AW17: Previous FY | AX17: OTB vs PY | AY17: OTB @ 17 Mar 2026 | AZ17: OTB @ 2 Mar 2026 | BA17: Variance | BB17: Previous FY | BC17: OTB vs PY | BE17: OTB @ 17 Mar 2026 | BF17: OTB @ 2 Mar 2026 | BG17: Variance | BH17: Previous FY | BI17: OTB vs PY | BJ17: OTB @ 17 Mar 2026 | BK17: OTB @ 2 Mar 2026 | BL17: Variance | BM17: Previous FY | BN17: OTB vs PY | BP17: OTB @ 17 Mar 2026 | BQ17: OTB @ 2 Mar 2026 | BR17: Variance | BS17: Previous FY | BT17: OTB vs PY | BU17: OTB @ 17 Mar 2026 | BV17: OTB @ 2 Mar 2026 | BW17: Variance | BX17: Previous FY | BY17: OTB vs PY
A18: Mar-25 | B18: 26 | C18: 26 | D18: =B18-C18 -> 0 | E18: 25 | F18: =C18-E18 -> 1 | G18: =B18/31 -> 0.83870968 | H18: =C18/31 -> 0.83870968 | I18: =G18-H18 -> 0 | J18: =E18/31 -> 0.80645161 | K18: =H18-J18 -> 0.032258065 | L18: Mar-25 | M18: 23 | N18: 23 | O18: =M18-N18 -> 0 | P18: 19 | Q18: =N18-P18 -> 4 | R18: =M18/31 -> 0.74193548 | S18: =N18/31 -> 0.74193548 | T18: =R18-S18 -> 0 | U18: =P18/31 -> 0.61290323 | V18: =S18-U18 -> 0.12903226 | W18: Mar-25 | X18: 16 | Y18: 16 | Z18: =X18-Y18 -> 0 | AA18: 0 | AB18: =Y18-AA18 -> 16 | AC18: =X18/31 -> 0.51612903 | AD18: =Y18/31 -> 0.51612903 | AE18: =AC18-AD18 -> 0 | AF18: =AA18/31 -> 0 | AG18: =AD18-AF18 -> 0.51612903 | AH18: Mar-25 | AI18: 24 | AJ18: 24 | AK18: =AI18-AJ18 -> 0 | AL18: 30 | AM18: =AJ18-AL18 -> -6 | AN18: =AI18/31 -> 0.77419355 | AO18: =AJ18/31 -> 0.77419355 | AP18: =AN18-AO18 -> 0 | AQ18: =AL18/31 -> 0.96774194 | AR18: =AO18-AQ18 -> -0.19354839 | AS18: Mar-25 | AT18: 6 | AU18: 6 | AV18: =AT18-AU18 -> 0 | AW18: 22 | AX18: =AU18-AW18 -> -16 | AY18: =AT18/31 -> 0.19354839 | AZ18: =AU18/31 -> 0.19354839 | BA18: =AY18-AZ18 -> 0 | BB18: =AW18/31 -> 0.70967742 | BC18: =AZ18-BB18 -> -0.51612903 | BD18: Mar-25 | BE18: 27 | BF18: 27 | BG18: =BE18-BF18 -> 0 | BH18: 25 | BI18: =BF18-BH18 -> 2 | BJ18: =BE18/31 -> 0.87096774 | BK18: =BF18/31 -> 0.87096774 | BL18: =BJ18-BK18 -> 0 | BM18: =BH18/31 -> 0.80645161 | BN18: =BK18-BM18 -> 0.064516129 | BO18: Mar-25 | BP18: =B18+M18+X18+AI18+AT18+BE18 -> 122 | BQ18: =C18+N18+Y18+AJ18+AU18+BF18 -> 122 | BR18: =BP18-BQ18 -> 0 | BS18: =E18+P18+AA18+AL18+AW18+BH18 -> 121 | BT18: =BQ18-BS18 -> 1 | BU18: =(BP18/31)/6 -> 0.65591398 | BV18: =(BQ18/31)/6 -> 0.65591398 | BW18: =BU18-BV18 -> 0 | BX18: =BS18/186 -> 0.65053763 | BY18: =BV18-BX18 -> 0.0053763441
A19: Apr-25 | B19: 20 | C19: 20 | D19: =B19-C19 -> 0 | E19: 20 | F19: =C19-E19 -> 0 | G19: =B19/30 -> 0.66666667 | H19: =C19/30 -> 0.66666667 | I19: =G19-H19 -> 0 | J19: =E19/30 -> 0.66666667 | K19: =H19-J19 -> 0 | L19: Apr-25 | M19: 24 | N19: 24 | O19: =M19-N19 -> 0 | P19: 14 | Q19: =N19-P19 -> 10 | R19: =M19/30 -> 0.8 | S19: =N19/30 -> 0.8 | T19: =R19-S19 -> 0 | U19: =P19/30 -> 0.46666667 | V19: =S19-U19 -> 0.33333333 | W19: Apr-25 | X19: 3 | Y19: 3 | Z19: =X19-Y19 -> 0 | AA19: 0 | AB19: =Y19-AA19 -> 3 | AC19: =X19/30 -> 0.1 | AD19: =Y19/30 -> 0.1 | AE19: =AC19-AD19 -> 0 | AF19: =AA19/30 -> 0 | AG19: =AD19-AF19 -> 0.1 | AH19: Apr-25 | AI19: 24 | AJ19: 24 | AK19: =AI19-AJ19 -> 0 | AL19: 20 | AM19: =AJ19-AL19 -> 4 | AN19: =AI19/30 -> 0.8 | AO19: =AJ19/30 -> 0.8 | AP19: =AN19-AO19 -> 0 | AQ19: =AL19/30 -> 0.66666667 | AR19: =AO19-AQ19 -> 0.13333333 | AS19: Apr-25 | AT19: 15 | AU19: 15 | AV19: =AT19-AU19 -> 0 | AW19: 14 | AX19: =AU19-AW19 -> 1 | AY19: =AT19/30 -> 0.5 | AZ19: =AU19/30 -> 0.5 | BA19: =AY19-AZ19 -> 0 | BB19: =AW19/30 -> 0.46666667 | BC19: =AZ19-BB19 -> 0.033333333 | BD19: Apr-25 | BE19: 21 | BF19: 21 | BG19: =BE19-BF19 -> 0 | BH19: 14 | BI19: =BF19-BH19 -> 7 | BJ19: =BE19/30 -> 0.7 | BK19: =BF19/30 -> 0.7 | BL19: =BJ19-BK19 -> 0 | BM19: =BH19/30 -> 0.46666667 | BN19: =BK19-BM19 -> 0.23333333 | BO19: Apr-25 | BP19: =B19+M19+X19+AI19+AT19+BE19 -> 107 | BQ19: =C19+N19+Y19+AJ19+AU19+BF19 -> 107 | BR19: =BP19-BQ19 -> 0 | BS19: =E19+P19+AA19+AL19+AW19+BH19 -> 82 | BT19: =BQ19-BS19 -> 25 | BU19: =(BP19/30)/6 -> 0.59444444 | BV19: =(BQ19/30)/6 -> 0.59444444 | BW19: =BU19-BV19 -> 0 | BX19: =BS19/180 -> 0.45555556 | BY19: =BV19-BX19 -> 0.13888889
A20: May-25 | B20: 16 | C20: 16 | D20: =B20-C20 -> 0 | E20: 12 | F20: =C20-E20 -> 4 | G20: =B20/31 -> 0.51612903 | H20: =C20/31 -> 0.51612903 | I20: =G20-H20 -> 0 | J20: =E20/31 -> 0.38709677 | K20: =H20-J20 -> 0.12903226 | L20: May-25 | M20: 14 | N20: 14 | O20: =M20-N20 -> 0 | P20: 11 | Q20: =N20-P20 -> 3 | R20: =M20/31 -> 0.4516129 | S20: =N20/31 -> 0.4516129 | T20: =R20-S20 -> 0 | U20: =P20/31 -> 0.35483871 | V20: =S20-U20 -> 0.096774194 | W20: May-25 | X20: 6 | Y20: 6 | Z20: =X20-Y20 -> 0 | AA20: 3 | AB20: =Y20-AA20 -> 3 | AC20: =X20/31 -> 0.19354839 | AD20: =Y20/31 -> 0.19354839 | AE20: =AC20-AD20 -> 0 | AF20: =AA20/31 -> 0.096774194 | AG20: =AD20-AF20 -> 0.096774194 | AH20: May-25 | AI20: 12 | AJ20: 12 | AK20: =AI20-AJ20 -> 0 | AL20: 6 | AM20: =AJ20-AL20 -> 6 | AN20: =AI20/31 -> 0.38709677 | AO20: =AJ20/31 -> 0.38709677 | AP20: =AN20-AO20 -> 0 | AQ20: =AL20/31 -> 0.19354839 | AR20: =AO20-AQ20 -> 0.19354839 | AS20: May-25 | AT20: 4 | AU20: 4 | AV20: =AT20-AU20 -> 0 | AW20: 7 | AX20: =AU20-AW20 -> -3 | AY20: =AT20/31 -> 0.12903226 | AZ20: =AU20/31 -> 0.12903226 | BA20: =AY20-AZ20 -> 0 | BB20: =AW20/31 -> 0.22580645 | BC20: =AZ20-BB20 -> -0.096774194 | BD20: May-25 | BE20: 20 | BF20: 20 | BG20: =BE20-BF20 -> 0 | BH20: 5 | BI20: =BF20-BH20 -> 15 | BJ20: =BE20/31 -> 0.64516129 | BK20: =BF20/31 -> 0.64516129 | BL20: =BJ20-BK20 -> 0 | BM20: =BH20/31 -> 0.16129032 | BN20: =BK20-BM20 -> 0.48387097 | BO20: May-25 | BP20: =B20+M20+X20+AI20+AT20+BE20 -> 72 | BQ20: =C20+N20+Y20+AJ20+AU20+BF20 -> 72 | BR20: =BP20-BQ20 -> 0 | BS20: =E20+P20+AA20+AL20+AW20+BH20 -> 44 | BT20: =BQ20-BS20 -> 28 | BU20: =(BP20/31)/6 -> 0.38709677 | BV20: =(BQ20/31)/6 -> 0.38709677 | BW20: =BU20-BV20 -> 0 | BX20: =BS20/186 -> 0.23655914 | BY20: =BV20-BX20 -> 0.15053763
A21: Jun-25 | B21: 10 | C21: 10 | D21: =B21-C21 -> 0 | E21: 3 | F21: =C21-E21 -> 7 | G21: =B21/30 -> 0.33333333 | H21: =C21/30 -> 0.33333333 | I21: =G21-H21 -> 0 | J21: =E21/30 -> 0.1 | K21: =H21-J21 -> 0.23333333 | L21: Jun-25 | M21: 16 | N21: 16 | O21: =M21-N21 -> 0 | P21: 0 | Q21: =N21-P21 -> 16 | R21: =M21/30 -> 0.53333333 | S21: =N21/30 -> 0.53333333 | T21: =R21-S21 -> 0 | U21: =P21/30 -> 0 | V21: =S21-U21 -> 0.53333333 | W21: Jun-25 | X21: 3 | Y21: 3 | Z21: =X21-Y21 -> 0 | AA21: 4 | AB21: =Y21-AA21 -> -1 | AC21: =X21/30 -> 0.1 | AD21: =Y21/30 -> 0.1 | AE21: =AC21-AD21 -> 0 | AF21: =AA21/30 -> 0.13333333 | AG21: =AD21-AF21 -> -0.033333333 | AH21: Jun-25 | AI21: 12 | AJ21: 12 | AK21: =AI21-AJ21 -> 0 | AL21: 7 | AM21: =AJ21-AL21 -> 5 | AN21: =AI21/30 -> 0.4 | AO21: =AJ21/30 -> 0.4 | AP21: =AN21-AO21 -> 0 | AQ21: =AL21/30 -> 0.23333333 | AR21: =AO21-AQ21 -> 0.16666667 | AS21: Jun-25 | AT21: 3 | AU21: 3 | AV21: =AT21-AU21 -> 0 | AW21: 0 | AX21: =AU21-AW21 -> 3 | AY21: =AT21/30 -> 0.1 | AZ21: =AU21/30 -> 0.1 | BA21: =AY21-AZ21 -> 0 | BB21: =AW21/30 -> 0 | BC21: =AZ21-BB21 -> 0.1 | BD21: Jun-25 | BE21: 0 | BF21: 0 | BG21: =BE21-BF21 -> 0 | BH21: 13 | BI21: =BF21-BH21 -> -13 | BJ21: =BE21/30 -> 0 | BK21: =BF21/30 -> 0 | BL21: =BJ21-BK21 -> 0 | BM21: =BH21/30 -> 0.43333333 | BN21: =BK21-BM21 -> -0.43333333 | BO21: Jun-25 | BP21: =B21+M21+X21+AI21+AT21+BE21 -> 44 | BQ21: =C21+N21+Y21+AJ21+AU21+BF21 -> 44 | BR21: =BP21-BQ21 -> 0 | BS21: =E21+P21+AA21+AL21+AW21+BH21 -> 27 | BT21: =BQ21-BS21 -> 17 | BU21: =(BP21/30)/6 -> 0.24444444 | BV21: =(BQ21/30)/6 -> 0.24444444 | BW21: =BU21-BV21 -> 0 | BX21: =BS21/180 -> 0.15 | BY21: =BV21-BX21 -> 0.094444444
A22: Jul-25 | B22: 14 | C22: 14 | D22: =B22-C22 -> 0 | E22: 14 | F22: =C22-E22 -> 0 | G22: =B22/31 -> 0.4516129 | H22: =C22/31 -> 0.4516129 | I22: =G22-H22 -> 0 | J22: =E22/31 -> 0.4516129 | K22: =H22-J22 -> 0 | L22: Jul-25 | M22: 11 | N22: 11 | O22: =M22-N22 -> 0 | P22: 10 | Q22: =N22-P22 -> 1 | R22: =M22/31 -> 0.35483871 | S22: =N22/31 -> 0.35483871 | T22: =R22-S22 -> 0 | U22: =P22/31 -> 0.32258065 | V22: =S22-U22 -> 0.032258065 | W22: Jul-25 | X22: 7 | Y22: 7 | Z22: =X22-Y22 -> 0 | AA22: 6 | AB22: =Y22-AA22 -> 1 | AC22: =X22/31 -> 0.22580645 | AD22: =Y22/31 -> 0.22580645 | AE22: =AC22-AD22 -> 0 | AF22: =AA22/31 -> 0.19354839 | AG22: =AD22-AF22 -> 0.032258065 | AH22: Jul-25 | AI22: 11 | AJ22: 11 | AK22: =AI22-AJ22 -> 0 | AL22: 9 | AM22: =AJ22-AL22 -> 2 | AN22: =AI22/31 -> 0.35483871 | AO22: =AJ22/31 -> 0.35483871 | AP22: =AN22-AO22 -> 0 | AQ22: =AL22/31 -> 0.29032258 | AR22: =AO22-AQ22 -> 0.064516129 | AS22: Jul-25 | AT22: 8 | AU22: 8 | AV22: =AT22-AU22 -> 0 | AW22: 2 | AX22: =AU22-AW22 -> 6 | AY22: =AT22/31 -> 0.25806452 | AZ22: =AU22/31 -> 0.25806452 | BA22: =AY22-AZ22 -> 0 | BB22: =AW22/31 -> 0.064516129 | BC22: =AZ22-BB22 -> 0.19354839 | BD22: Jul-25 | BE22: 10 | BF22: 10 | BG22: =BE22-BF22 -> 0 | BH22: 14 | BI22: =BF22-BH22 -> -4 | BJ22: =BE22/31 -> 0.32258065 | BK22: =BF22/31 -> 0.32258065 | BL22: =BJ22-BK22 -> 0 | BM22: =BH22/31 -> 0.4516129 | BN22: =BK22-BM22 -> -0.12903226 | BO22: Jul-25 | BP22: =B22+M22+X22+AI22+AT22+BE22 -> 61 | BQ22: =C22+N22+Y22+AJ22+AU22+BF22 -> 61 | BR22: =BP22-BQ22 -> 0 | BS22: =E22+P22+AA22+AL22+AW22+BH22 -> 55 | BT22: =BQ22-BS22 -> 6 | BU22: =(BP22/31)/6 -> 0.32795699 | BV22: =(BQ22/31)/6 -> 0.32795699 | BW22: =BU22-BV22 -> 0 | BX22: =BS22/186 -> 0.29569892 | BY22: =BV22-BX22 -> 0.032258065
A23: Aug-25 | B23: 21 | C23: 21 | D23: =B23-C23 -> 0 | E23: 13 | F23: =C23-E23 -> 8 | G23: =B23/31 -> 0.67741935 | H23: =C23/31 -> 0.67741935 | I23: =G23-H23 -> 0 | J23: =E23/31 -> 0.41935484 | K23: =H23-J23 -> 0.25806452 | L23: Aug-25 | M23: 11 | N23: 11 | O23: =M23-N23 -> 0 | P23: 2 | Q23: =N23-P23 -> 9 | R23: =M23/31 -> 0.35483871 | S23: =N23/31 -> 0.35483871 | T23: =R23-S23 -> 0 | U23: =P23/31 -> 0.064516129 | V23: =S23-U23 -> 0.29032258 | W23: Aug-25 | X23: 5 | Y23: 5 | Z23: =X23-Y23 -> 0 | AA23: 3 | AB23: =Y23-AA23 -> 2 | AC23: =X23/31 -> 0.16129032 | AD23: =Y23/31 -> 0.16129032 | AE23: =AC23-AD23 -> 0 | AF23: =AA23/31 -> 0.096774194 | AG23: =AD23-AF23 -> 0.064516129 | AH23: Aug-25 | AI23: 7 | AJ23: 7 | AK23: =AI23-AJ23 -> 0 | AL23: 6 | AM23: =AJ23-AL23 -> 1 | AN23: =AI23/31 -> 0.22580645 | AO23: =AJ23/31 -> 0.22580645 | AP23: =AN23-AO23 -> 0 | AQ23: =AL23/31 -> 0.19354839 | AR23: =AO23-AQ23 -> 0.032258065 | AS23: Aug-25 | AT23: 7 | AU23: 7 | AV23: =AT23-AU23 -> 0 | AW23: 0 | AX23: =AU23-AW23 -> 7 | AY23: =AT23/31 -> 0.22580645 | AZ23: =AU23/31 -> 0.22580645 | BA23: =AY23-AZ23 -> 0 | BB23: =AW23/31 -> 0 | BC23: =AZ23-BB23 -> 0.22580645 | BD23: Aug-25 | BE23: 15 | BF23: 15 | BG23: =BE23-BF23 -> 0 | BH23: 24 | BI23: =BF23-BH23 -> -9 | BJ23: =BE23/31 -> 0.48387097 | BK23: =BF23/31 -> 0.48387097 | BL23: =BJ23-BK23 -> 0 | BM23: =BH23/31 -> 0.77419355 | BN23: =BK23-BM23 -> -0.29032258 | BO23: Aug-25 | BP23: =B23+M23+X23+AI23+AT23+BE23 -> 66 | BQ23: =C23+N23+Y23+AJ23+AU23+BF23 -> 66 | BR23: =BP23-BQ23 -> 0 | BS23: =E23+P23+AA23+AL23+AW23+BH23 -> 48 | BT23: =BQ23-BS23 -> 18 | BU23: =(BP23/31)/6 -> 0.35483871 | BV23: =(BQ23/31)/6 -> 0.35483871 | BW23: =BU23-BV23 -> 0 | BX23: =BS23/186 -> 0.25806452 | BY23: =BV23-BX23 -> 0.096774194
A24: Sep-25 | B24: 15 | C24: 15 | D24: =B24-C24 -> 0 | E24: 19 | F24: =C24-E24 -> -4 | G24: =B24/30 -> 0.5 | H24: =C24/30 -> 0.5 | I24: =G24-H24 -> 0 | J24: =E24/30 -> 0.63333333 | K24: =H24-J24 -> -0.13333333 | L24: Sep-25 | M24: 15 | N24: 15 | O24: =M24-N24 -> 0 | P24: 5 | Q24: =N24-P24 -> 10 | R24: =M24/30 -> 0.5 | S24: =N24/30 -> 0.5 | T24: =R24-S24 -> 0 | U24: =P24/30 -> 0.16666667 | V24: =S24-U24 -> 0.33333333 | W24: Sep-25 | X24: 4 | Y24: 4 | Z24: =X24-Y24 -> 0 | AA24: 9 | AB24: =Y24-AA24 -> -5 | AC24: =X24/30 -> 0.13333333 | AD24: =Y24/30 -> 0.13333333 | AE24: =AC24-AD24 -> 0 | AF24: =AA24/30 -> 0.3 | AG24: =AD24-AF24 -> -0.16666667 | AH24: Sep-25 | AI24: 0 | AJ24: 0 | AK24: =AI24-AJ24 -> 0 | AL24: 12 | AM24: =AJ24-AL24 -> -12 | AN24: =AI24/30 -> 0 | AO24: =AJ24/30 -> 0 | AP24: =AN24-AO24 -> 0 | AQ24: =AL24/30 -> 0.4 | AR24: =AO24-AQ24 -> -0.4 | AS24: Sep-25 | AT24: 14 | AU24: 14 | AV24: =AT24-AU24 -> 0 | AW24: 9 | AX24: =AU24-AW24 -> 5 | AY24: =AT24/30 -> 0.46666667 | AZ24: =AU24/30 -> 0.46666667 | BA24: =AY24-AZ24 -> 0 | BB24: =AW24/30 -> 0.3 | BC24: =AZ24-BB24 -> 0.16666667 | BD24: Sep-25 | BE24: 12 | BF24: 12 | BG24: =BE24-BF24 -> 0 | BH24: 12 | BI24: =BF24-BH24 -> 0 | BJ24: =BE24/30 -> 0.4 | BK24: =BF24/30 -> 0.4 | BL24: =BJ24-BK24 -> 0 | BM24: =BH24/30 -> 0.4 | BN24: =BK24-BM24 -> 0 | BO24: Sep-25 | BP24: =B24+M24+X24+AI24+AT24+BE24 -> 60 | BQ24: =C24+N24+Y24+AJ24+AU24+BF24 -> 60 | BR24: =BP24-BQ24 -> 0 | BS24: =E24+P24+AA24+AL24+AW24+BH24 -> 66 | BT24: =BQ24-BS24 -> -6 | BU24: =(BP24/30)/6 -> 0.33333333 | BV24: =(BQ24/30)/6 -> 0.33333333 | BW24: =BU24-BV24 -> 0 | BX24: =BS24/180 -> 0.36666667 | BY24: =BV24-BX24 -> -0.033333333
A25: Oct-25 | B25: 22 | C25: 22 | D25: =B25-C25 -> 0 | E25: 12 | F25: =C25-E25 -> 10 | G25: =B25/31 -> 0.70967742 | H25: =C25/31 -> 0.70967742 | I25: =G25-H25 -> 0 | J25: =E25/31 -> 0.38709677 | K25: =H25-J25 -> 0.32258065 | L25: Oct-25 | M25: 20 | N25: 20 | O25: =M25-N25 -> 0 | P25: 9 | Q25: =N25-P25 -> 11 | R25: =M25/31 -> 0.64516129 | S25: =N25/31 -> 0.64516129 | T25: =R25-S25 -> 0 | U25: =P25/31 -> 0.29032258 | V25: =S25-U25 -> 0.35483871 | W25: Oct-25 | X25: 4 | Y25: 4 | Z25: =X25-Y25 -> 0 | AA25: 12 | AB25: =Y25-AA25 -> -8 | AC25: =X25/31 -> 0.12903226 | AD25: =Y25/31 -> 0.12903226 | AE25: =AC25-AD25 -> 0 | AF25: =AA25/31 -> 0.38709677 | AG25: =AD25-AF25 -> -0.25806452 | AH25: Oct-25 | AI25: 8 | AJ25: 8 | AK25: =AI25-AJ25 -> 0 | AL25: 13 | AM25: =AJ25-AL25 -> -5 | AN25: =AI25/31 -> 0.25806452 | AO25: =AJ25/31 -> 0.25806452 | AP25: =AN25-AO25 -> 0 | AQ25: =AL25/31 -> 0.41935484 | AR25: =AO25-AQ25 -> -0.16129032 | AS25: Oct-25 | AT25: 0 | AU25: 0 | AV25: =AT25-AU25 -> 0 | AW25: 4 | AX25: =AU25-AW25 -> -4 | AY25: =AT25/31 -> 0 | AZ25: =AU25/31 -> 0 | BA25: =AY25-AZ25 -> 0 | BB25: =AW25/31 -> 0.12903226 | BC25: =AZ25-BB25 -> -0.12903226 | BD25: Oct-25 | BE25: 18 | BF25: 18 | BG25: =BE25-BF25 -> 0 | BH25: 12 | BI25: =BF25-BH25 -> 6 | BJ25: =BE25/31 -> 0.58064516 | BK25: =BF25/31 -> 0.58064516 | BL25: =BJ25-BK25 -> 0 | BM25: =BH25/31 -> 0.38709677 | BN25: =BK25-BM25 -> 0.19354839 | BO25: Oct-25 | BP25: =B25+M25+X25+AI25+AT25+BE25 -> 72 | BQ25: =C25+N25+Y25+AJ25+AU25+BF25 -> 72 | BR25: =BP25-BQ25 -> 0 | BS25: =E25+P25+AA25+AL25+AW25+BH25 -> 62 | BT25: =BQ25-BS25 -> 10 | BU25: =(BP25/31)/6 -> 0.38709677 | BV25: =(BQ25/31)/6 -> 0.38709677 | BW25: =BU25-BV25 -> 0 | BX25: =BS25/186 -> 0.33333333 | BY25: =BV25-BX25 -> 0.053763441
A26: Nov-25 | B26: 25 | C26: 25 | D26: =B26-C26 -> 0 | E26: 27 | F26: =C26-E26 -> -2 | G26: =B26/30 -> 0.83333333 | H26: =C26/30 -> 0.83333333 | I26: =G26-H26 -> 0 | J26: =E26/30 -> 0.9 | K26: =H26-J26 -> -0.066666667 | L26: Nov-25 | M26: 25 | N26: 25 | O26: =M26-N26 -> 0 | P26: 22 | Q26: =N26-P26 -> 3 | R26: =M26/30 -> 0.83333333 | S26: =N26/30 -> 0.83333333 | T26: =R26-S26 -> 0 | U26: =P26/30 -> 0.73333333 | V26: =S26-U26 -> 0.1 | W26: Nov-25 | X26: 14 | Y26: 14 | Z26: =X26-Y26 -> 0 | AA26: 8 | AB26: =Y26-AA26 -> 6 | AC26: =X26/30 -> 0.46666667 | AD26: =Y26/30 -> 0.46666667 | AE26: =AC26-AD26 -> 0 | AF26: =AA26/30 -> 0.26666667 | AG26: =AD26-AF26 -> 0.2 | AH26: Nov-25 | AI26: 26 | AJ26: 26 | AK26: =AI26-AJ26 -> 0 | AL26: 27 | AM26: =AJ26-AL26 -> -1 | AN26: =AI26/30 -> 0.86666667 | AO26: =AJ26/30 -> 0.86666667 | AP26: =AN26-AO26 -> 0 | AQ26: =AL26/30 -> 0.9 | AR26: =AO26-AQ26 -> -0.033333333 | AS26: Nov-25 | AT26: 0 | AU26: 0 | AV26: =AT26-AU26 -> 0 | AW26: 18 | AX26: =AU26-AW26 -> -18 | AY26: =AT26/30 -> 0 | AZ26: =AU26/30 -> 0 | BA26: =AY26-AZ26 -> 0 | BB26: =AW26/30 -> 0.6 | BC26: =AZ26-BB26 -> -0.6 | BD26: Nov-25 | BE26: 25 | BF26: 25 | BG26: =BE26-BF26 -> 0 | BH26: 8 | BI26: =BF26-BH26 -> 17 | BJ26: =BE26/30 -> 0.83333333 | BK26: =BF26/30 -> 0.83333333 | BL26: =BJ26-BK26 -> 0 | BM26: =BH26/30 -> 0.26666667 | BN26: =BK26-BM26 -> 0.56666667 | BO26: Nov-25 | BP26: =B26+M26+X26+AI26+AT26+BE26 -> 115 | BQ26: =C26+N26+Y26+AJ26+AU26+BF26 -> 115 | BR26: =BP26-BQ26 -> 0 | BS26: =E26+P26+AA26+AL26+AW26+BH26 -> 110 | BT26: =BQ26-BS26 -> 5 | BU26: =(BP26/30)/6 -> 0.63888889 | BV26: =(BQ26/30)/6 -> 0.63888889 | BW26: =BU26-BV26 -> 0 | BX26: =BS26/180 -> 0.61111111 | BY26: =BV26-BX26 -> 0.027777778
A27: Dec-25 | B27: 26 | C27: 26 | D27: =B27-C27 -> 0 | E27: 24 | F27: =C27-E27 -> 2 | G27: =B27/31 -> 0.83870968 | H27: =C27/31 -> 0.83870968 | I27: =G27-H27 -> 0 | J27: =E27/31 -> 0.77419355 | K27: =H27-J27 -> 0.064516129 | L27: Dec-25 | M27: 29 | N27: 29 | O27: =M27-N27 -> 0 | P27: 20 | Q27: =N27-P27 -> 9 | R27: =M27/31 -> 0.93548387 | S27: =N27/31 -> 0.93548387 | T27: =R27-S27 -> 0 | U27: =P27/31 -> 0.64516129 | V27: =S27-U27 -> 0.29032258 | W27: Dec-25 | X27: 16 | Y27: 16 | Z27: =X27-Y27 -> 0 | AA27: 19 | AB27: =Y27-AA27 -> -3 | AC27: =X27/31 -> 0.51612903 | AD27: =Y27/31 -> 0.51612903 | AE27: =AC27-AD27 -> 0 | AF27: =AA27/31 -> 0.61290323 | AG27: =AD27-AF27 -> -0.096774194 | AH27: Dec-25 | AI27: 30 | AJ27: 30 | AK27: =AI27-AJ27 -> 0 | AL27: 30 | AM27: =AJ27-AL27 -> 0 | AN27: =AI27/31 -> 0.96774194 | AO27: =AJ27/31 -> 0.96774194 | AP27: =AN27-AO27 -> 0 | AQ27: =AL27/31 -> 0.96774194 | AR27: =AO27-AQ27 -> 0 | AS27: Dec-25 | AT27: 16 | AU27: 16 | AV27: =AT27-AU27 -> 0 | AW27: 26 | AX27: =AU27-AW27 -> -10 | AY27: =AT27/31 -> 0.51612903 | AZ27: =AU27/31 -> 0.51612903 | BA27: =AY27-AZ27 -> 0 | BB27: =AW27/31 -> 0.83870968 | BC27: =AZ27-BB27 -> -0.32258065 | BD27: Dec-25 | BE27: 27 | BF27: 27 | BG27: =BE27-BF27 -> 0 | BH27: 26 | BI27: =BF27-BH27 -> 1 | BJ27: =BE27/31 -> 0.87096774 | BK27: =BF27/31 -> 0.87096774 | BL27: =BJ27-BK27 -> 0 | BM27: =BH27/31 -> 0.83870968 | BN27: =BK27-BM27 -> 0.032258065 | BO27: Dec-25 | BP27: =B27+M27+X27+AI27+AT27+BE27 -> 144 | BQ27: =C27+N27+Y27+AJ27+AU27+BF27 -> 144 | BR27: =BP27-BQ27 -> 0 | BS27: =E27+P27+AA27+AL27+AW27+BH27 -> 145 | BT27: =BQ27-BS27 -> -1 | BU27: =(BP27/31)/6 -> 0.77419355 | BV27: =(BQ27/31)/6 -> 0.77419355 | BW27: =BU27-BV27 -> 0 | BX27: =BS27/186 -> 0.77956989 | BY27: =BV27-BX27 -> -0.0053763441
A28: Jan-26 | B28: 30 | C28: 30 | D28: =B28-C28 -> 0 | E28: 27 | F28: =C28-E28 -> 3 | G28: =B28/31 -> 0.96774194 | H28: =C28/31 -> 0.96774194 | I28: =G28-H28 -> 0 | J28: =E28/31 -> 0.87096774 | K28: =H28-J28 -> 0.096774194 | L28: Jan-26 | M28: 31 | N28: 31 | O28: =M28-N28 -> 0 | P28: 28 | Q28: =N28-P28 -> 3 | R28: =M28/31 -> 1 | S28: =N28/31 -> 1 | T28: =R28-S28 -> 0 | U28: =P28/31 -> 0.90322581 | V28: =S28-U28 -> 0.096774194 | W28: Jan-26 | X28: 30 | Y28: 30 | Z28: =X28-Y28 -> 0 | AA28: 29 | AB28: =Y28-AA28 -> 1 | AC28: =X28/31 -> 0.96774194 | AD28: =Y28/31 -> 0.96774194 | AE28: =AC28-AD28 -> 0 | AF28: =AA28/31 -> 0.93548387 | AG28: =AD28-AF28 -> 0.032258065 | AH28: Jan-26 | AI28: 31 | AJ28: 31 | AK28: =AI28-AJ28 -> 0 | AL28: 30 | AM28: =AJ28-AL28 -> 1 | AN28: =AI28/31 -> 1 | AO28: =AJ28/31 -> 1 | AP28: =AN28-AO28 -> 0 | AQ28: =AL28/31 -> 0.96774194 | AR28: =AO28-AQ28 -> 0.032258065 | AS28: Jan-26 | AT28: 31 | AU28: 31 | AV28: =AT28-AU28 -> 0 | AW28: 30 | AX28: =AU28-AW28 -> 1 | AY28: =AT28/31 -> 1 | AZ28: =AU28/31 -> 1 | BA28: =AY28-AZ28 -> 0 | BB28: =AW28/31 -> 0.96774194 | BC28: =AZ28-BB28 -> 0.032258065 | BD28: Jan-26 | BE28: 25 | BF28: 25 | BG28: =BE28-BF28 -> 0 | BH28: 29 | BI28: =BF28-BH28 -> -4 | BJ28: =BE28/31 -> 0.80645161 | BK28: =BF28/31 -> 0.80645161 | BL28: =BJ28-BK28 -> 0 | BM28: =BH28/31 -> 0.93548387 | BN28: =BK28-BM28 -> -0.12903226 | BO28: Jan-26 | BP28: =B28+M28+X28+AI28+AT28+BE28 -> 178 | BQ28: =C28+N28+Y28+AJ28+AU28+BF28 -> 178 | BR28: =BP28-BQ28 -> 0 | BS28: =E28+P28+AA28+AL28+AW28+BH28 -> 173 | BT28: =BQ28-BS28 -> 5 | BU28: =(BP28/31)/6 -> 0.95698925 | BV28: =(BQ28/31)/6 -> 0.95698925 | BW28: =BU28-BV28 -> 0 | BX28: =BS28/186 -> 0.93010753 | BY28: =BV28-BX28 -> 0.02688172
A29: Feb-26 | B29: 27 | C29: 27 | D29: =B29-C29 -> 0 | E29: 18 | F29: =C29-E29 -> 9 | G29: =B29/28 -> 0.96428571 | H29: =C29/28 -> 0.96428571 | I29: =G29-H29 -> 0 | J29: =E29/28 -> 0.64285714 | K29: =H29-J29 -> 0.32142857 | L29: Feb-26 | M29: 25 | N29: 25 | O29: =M29-N29 -> 0 | P29: 26 | Q29: =N29-P29 -> -1 | R29: =M29/28 -> 0.89285714 | S29: =N29/28 -> 0.89285714 | T29: =R29-S29 -> 0 | U29: =P29/28 -> 0.92857143 | V29: =S29-U29 -> -0.035714286 | W29: Feb-26 | X29: 23 | Y29: 23 | Z29: =X29-Y29 -> 0 | AA29: 23 | AB29: =Y29-AA29 -> 0 | AC29: =X29/28 -> 0.82142857 | AD29: =Y29/28 -> 0.82142857 | AE29: =AC29-AD29 -> 0 | AF29: =AA29/28 -> 0.82142857 | AG29: =AD29-AF29 -> 0 | AH29: Feb-26 | AI29: 27 | AJ29: 27 | AK29: =AI29-AJ29 -> 0 | AL29: 23 | AM29: =AJ29-AL29 -> 4 | AN29: =AI29/28 -> 0.96428571 | AO29: =AJ29/28 -> 0.96428571 | AP29: =AN29-AO29 -> 0 | AQ29: =AL29/28 -> 0.82142857 | AR29: =AO29-AQ29 -> 0.14285714 | AS29: Feb-26 | AT29: 3 | AU29: 3 | AV29: =AT29-AU29 -> 0 | AW29: 24 | AX29: =AU29-AW29 -> -21 | AY29: =AT29/28 -> 0.10714286 | AZ29: =AU29/28 -> 0.10714286 | BA29: =AY29-AZ29 -> 0 | BB29: =AW29/28 -> 0.85714286 | BC29: =AZ29-BB29 -> -0.75 | BD29: Feb-26 | BE29: 24 | BF29: 24 | BG29: =BE29-BF29 -> 0 | BH29: 26 | BI29: =BF29-BH29 -> -2 | BJ29: =BE29/28 -> 0.85714286 | BK29: =BF29/28 -> 0.85714286 | BL29: =BJ29-BK29 -> 0 | BM29: =BH29/28 -> 0.92857143 | BN29: =BK29-BM29 -> -0.071428571 | BO29: Feb-26 | BP29: =B29+M29+X29+AI29+AT29+BE29 -> 129 | BQ29: =C29+N29+Y29+AJ29+AU29+BF29 -> 129 | BR29: =BP29-BQ29 -> 0 | BS29: =E29+P29+AA29+AL29+AW29+BH29 -> 140 | BT29: =BQ29-BS29 -> -11 | BU29: =(BP29/28)/6 -> 0.76785714 | BV29: =(BQ29/28)/6 -> 0.76785714 | BW29: =BU29-BV29 -> 0 | BX29: =BS29/168 -> 0.83333333 | BY29: =BV29-BX29 -> -0.06547619
A30: ADR | L30: ADR | W30: ADR | AH30: ADR | AS30: ADR | BD30: ADR | BO30: ADR
B31: OTB @ 17 Mar 2026 | C31: OTB @ 2 Mar 2026 | D31: Variance | E31: Previous FY | F31: OTB vs PY | M31: OTB @ 17 Mar 2026 | N31: OTB @ 2 Mar 2026 | O31: Variance | P31: Previous FY | Q31: OTB vs PY | X31: OTB @ 17 Mar 2026 | Y31: OTB @ 2 Mar 2026 | Z31: Variance | AA31: Previous FY | AB31: OTB vs PY | AI31: OTB @ 17 Mar 2026 | AJ31: OTB @ 2 Mar 2026 | AK31: Variance | AL31: Previous FY | AM31: OTB vs PY | AT31: OTB @ 17 Mar 2026 | AU31: OTB @ 2 Mar 2026 | AV31: Variance | AW31: Previous FY | AX31: OTB vs PY | BE31: OTB @ 17 Mar 2026 | BF31: OTB @ 2 Mar 2026 | BG31: Variance | BH31: Previous FY | BI31: OTB vs PY | BP31: OTB @ 17 Mar 2026 | BQ31: OTB @ 2 Mar 2026 | BR31: Variance | BS31: Previous FY | BT31: OTB vs PY
A32: Mar-25 | B32: =B3/B18 -> 10582.983 | C32: =C3/C18 -> 10582.983 | D32: =B32-C32 -> 0 | E32: =E3/E18 -> 8775.0652 | F32: =C32-E32 -> 1807.9179 | L32: Mar-25 | M32: =M3/M18 -> 9317.3913 | N32: =N3/N18 -> 9317.3913 | O32: =M32-N32 -> 0 | P32: =P3/P18 -> 7131.8421 | Q32: =N32-P32 -> 2185.5492 | W32: Mar-25 | X32: =X3/X18 -> 10584.625 | Y32: =Y3/Y18 -> 10584.625 | Z32: =X32-Y32 -> 0 | AA32: - | AB32: - | AH32: Mar-25 | AI32: =AI3/AI18 -> 5695.8333 | AJ32: =AJ3/AJ18 -> 5695.8333 | AK32: =AI32-AJ32 -> 0 | AL32: =AL3/AL18 -> 4817.499 | AM32: =AJ32-AL32 -> 878.33433 | AS32: Mar-25 | AT32: =AT3/AT18 -> 7150 | AU32: =AU3/AU18 -> 7150 | AV32: =AT32-AU32 -> 0 | AW32: =AW3/AW18 -> 4768.4714 | AX32: =AU32-AW32 -> 2381.5286 | BD32: Mar-25 | BE32: =BE3/BE18 -> 4829.4059 | BF32: =BF3/BF18 -> 4829.4059 | BG32: =BE32-BF32 -> 0 | BH32: =BH3/BH18 -> 4092.1248 | BI32: =BF32-BH32 -> 737.28113 | BO32: Mar-25 | BP32: =BP3/BP18 -> 7941.0289 | BQ32: =BQ3/BQ18 -> 7941.0289 | BR32: =BP32-BQ32 -> 0 | BS32: =BS3/BS18 -> 6459.6371 | BT32: =BQ32-BS32 -> 1481.3917
A33: Apr-25 | B33: =B4/B19 -> 11430 | C33: =C4/C19 -> 11430 | D33: =B33-C33 -> 0 | E33: =E4/E19 -> 7702.3045 | F33: =C33-E33 -> 3727.6955 | L33: Apr-25 | M33: =M4/M19 -> 9449.0383 | N33: =N4/N19 -> 9449.0383 | O33: =M33-N33 -> 0 | P33: =P4/P19 -> 8456.9893 | Q33: =N33-P33 -> 992.04905 | W33: Apr-25 | X33: =X4/X19 -> 8648.75 | Y33: =Y4/Y19 -> 8648.75 | Z33: =X33-Y33 -> 0 | AA33: - | AB33: - | AH33: Apr-25 | AI33: =AI4/AI19 -> 6118.3929 | AJ33: =AJ4/AJ19 -> 6118.3929 | AK33: =AI33-AJ33 -> 0 | AL33: =AL4/AL19 -> 3874.464 | AM33: =AJ33-AL33 -> 2243.9289 | AS33: Apr-25 | AT33: =AT4/AT19 -> 6184.016 | AU33: =AU4/AU19 -> 6184.016 | AV33: =AT33-AU33 -> 0 | AW33: =AW4/AW19 -> 4059.7479 | AX33: =AU33-AW33 -> 2124.2681 | BD33: Apr-25 | BE33: =BE4/BE19 -> 5315.8757 | BF33: =BF4/BF19 -> 5315.8757 | BG33: =BE33-BF33 -> 0 | BH33: =BH4/BH19 -> 3305.5207 | BI33: =BF33-BH33 -> 2010.355 | BO33: Apr-25 | BP33: =BP4/BP19 -> 7780.918 | BQ33: =BQ4/BQ19 -> 7780.918 | BR33: =BP33-BQ33 -> 0 | BS33: =BS4/BS19 -> 6439.5973 | BT33: =BQ33-BS33 -> 1341.3207
A34: May-25 | B34: =B5/B20 -> 7682.8125 | C34: =C5/C20 -> 7682.8125 | D34: =B34-C34 -> 0 | E34: =E5/E20 -> 7311.63 | F34: =C34-E34 -> 371.1825 | L34: May-25 | M34: =M5/M20 -> 4882.7386 | N34: =N5/N20 -> 4882.7386 | O34: =M34-N34 -> 0 | P34: =P5/P20 -> 6043.2736 | Q34: =N34-P34 -> -1160.5351 | W34: May-25 | X34: =X5/X20 -> 7177.5 | Y34: =Y5/Y20 -> 7177.5 | Z34: =X34-Y34 -> 0 | AA34: =AA5/AA20 -> 13000 | AB34: =Y34-AA34 -> -5822.5 | AH34: May-25 | AI34: =AI5/AI20 -> 3843.8125 | AJ34: =AJ5/AJ20 -> 3843.8125 | AK34: =AI34-AJ34 -> 0 | AL34: =AL5/AL20 -> 4350 | AM34: =AJ34-AL34 -> -506.1875 | AS34: May-25 | AT34: =AT5/AT20 -> 4927.725 | AU34: =AU5/AU20 -> 4927.725 | AV34: =AT34-AU34 -> 0 | AW34: =AW5/AW20 -> 5009.3229 | AX34: =AU34-AW34 -> -81.597857 | BD34: May-25 | BE34: =BE5/BE20 -> 3047.402 | BF34: =BF5/BF20 -> 3047.402 | BG34: =BE34-BF34 -> 0 | BH34: =BH5/BH20 -> 1473.418 | BI34: =BF34-BH34 -> 1573.984 | BO34: May-25 | BP34: =BP5/BP20 -> 5015.7365 | BQ34: =BQ5/BQ20 -> 5015.7365 | BR34: =BP34-BQ34 -> 0 | BS34: =BS5/BS20 -> 5948.8164 | BT34: =BQ34-BS34 -> -933.07984
A35: Jun-25 | B35: =B6/B21 -> 5398.25 | C35: =C6/C21 -> 5398.25 | D35: =B35-C35 -> 0 | E35: =E6/E21 -> 5475.28 | F35: =C35-E35 -> -77.03 | L35: Jun-25 | M35: =M6/M21 -> 6573.8906 | N35: =N6/N21 -> 6573.8906 | O35: =M35-N35 -> 0 | P35: 0 | Q35: =N35-P35 -> 6573.8906 | W35: Jun-25 | X35: =X6/X21 -> 7787.73 | Y35: =Y6/Y21 -> 7787.73 | Z35: =X35-Y35 -> 0 | AA35: =AA6/AA21 -> 7475.99 | AB35: =Y35-AA35 -> 311.74 | AH35: Jun-25 | AI35: =AI6/AI21 -> 3529.1667 | AJ35: =AJ6/AJ21 -> 3529.1667 | AK35: =AI35-AJ35 -> 0 | AL35: =AL6/AL21 -> 3225.08 | AM35: =AJ35-AL35 -> 304.08667 | AS35: Jun-25 | AT35: =AT6/AT21 -> 3748.88 | AU35: =AU6/AU21 -> 3748.88 | AV35: =AT35-AU35 -> 0 | AW35: 0 | AX35: =AU35-AW35 -> 3748.88 | BD35: Jun-25 | BE35: 0 | BF35: 0 | BG35: =BE35-BF35 -> 0 | BH35: =BH6/BH21 -> 2266.6062 | BI35: =BF35-BH35 -> -2266.6062 | BO35: Jun-25 | BP35: =BP6/BP21 -> 5366.4677 | BQ35: =BQ6/BQ21 -> 5366.4677 | BR35: =BP35-BQ35 -> 0 | BS35: =BS6/BS21 -> 3643.3793 | BT35: =BQ35-BS35 -> 1723.0885
A36: Jul-25 | B36: =B7/B22 -> 6000.1057 | C36: =C7/C22 -> 6000.1057 | D36: =B36-C36 -> 0 | E36: =E7/E22 -> 5462.7607 | F36: =C36-E36 -> 537.345 | L36: Jul-25 | M36: =M7/M22 -> 7564.7727 | N36: =N7/N22 -> 7564.7727 | O36: =M36-N36 -> 0 | P36: =P7/P22 -> 5993.206 | Q36: =N36-P36 -> 1571.5667 | W36: Jul-25 | X36: =X7/X22 -> 9334.2857 | Y36: =Y7/Y22 -> 9334.2857 | Z36: =X36-Y36 -> 0 | AA36: =AA7/AA22 -> 5933.3333 | AB36: =Y36-AA36 -> 3400.9524 | AH36: Jul-25 | AI36: =AI7/AI22 -> 4090 | AJ36: =AJ7/AJ22 -> 4090 | AK36: =AI36-AJ36 -> 0 | AL36: =AL7/AL22 -> 3722.2044 | AM36: =AJ36-AL36 -> 367.79556 | AS36: Jul-25 | AT36: =AT7/AT22 -> 4266.635 | AU36: =AU7/AU22 -> 4266.635 | AV36: =AT36-AU36 -> 0 | AW36: =AW7/AW22 -> 4950 | AX36: =AU36-AW36 -> -683.365 | BD36: Jul-25 | BE36: =BE7/BE22 -> 3646.381 | BF36: =BF7/BF22 -> 3646.381 | BG36: =BE36-BF36 -> 0 | BH36: =BH7/BH22 -> 2746.3271 | BI36: =BF36-BH36 -> 900.05386 | BO36: Jul-25 | BP36: =BP7/BP22 -> 5707.2274 | BQ36: =BQ7/BQ22 -> 5707.2274 | BR36: =BP36-BQ36 -> 0 | BS36: =BS7/BS22 -> 4615.6205 | BT36: =BQ36-BS36 -> 1091.6068
A37: Aug-25 | B37: =B8/B23 -> 6005.0648 | C37: =C8/C23 -> 6005.0648 | D37: =B37-C37 -> 0 | E37: =E8/E23 -> 5459.5077 | F37: =C37-E37 -> 545.55707 | L37: Aug-25 | M37: =M8/M23 -> 5928.69 | N37: =N8/N23 -> 5928.69 | O37: =M37-N37 -> 0 | P37: =P8/P23 -> 5850 | Q37: =N37-P37 -> 78.69 | W37: Aug-25 | X37: =X8/X23 -> 600 | Y37: =Y8/Y23 -> 600 | Z37: =X37-Y37 -> 0 | AA37: =AA8/AA23 -> 5370 | AB37: =Y37-AA37 -> -4770 | AH37: Aug-25 | AI37: =AI8/AI23 -> 5307.1429 | AJ37: =AJ8/AJ23 -> 5307.1429 | AK37: =AI37-AJ37 -> 0 | AL37: =AL8/AL23 -> 2992.7867 | AM37: =AJ37-AL37 -> 2314.3562 | AS37: Aug-25 | AT37: =AT8/AT23 -> 4582.9029 | AU37: =AU8/AU23 -> 4582.9029 | AV37: =AT37-AU37 -> 0 | AW37: 0 | AX37: =AU37-AW37 -> 4582.9029 | BD37: Aug-25 | BE37: =BE8/BE23 -> 3285.3173 | BF37: =BF8/BF23 -> 3285.3173 | BG37: =BE37-BF37 -> 0 | BH37: =BH8/BH23 -> 3162.8471 | BI37: =BF37-BH37 -> 122.47025 | BO37: Aug-25 | BP37: =BP8/BP23 -> 4739.8792 | BQ37: =BQ8/BQ23 -> 4739.8792 | BR37: =BP37-BQ37 -> 0 | BS37: =BS8/BS23 -> 4013.5135 | BT37: =BQ37-BS37 -> 726.3657
A38: Sep-25 | B38: =B9/B24 -> 5923.8453 | C38: =C9/C24 -> 5923.8453 | D38: =B38-C38 -> 0 | E38: =E9/E24 -> 6022.2753 | F38: =C38-E38 -> -98.42993 | L38: Sep-25 | M38: =M9/M24 -> 4847.944 | N38: =N9/N24 -> 4847.944 | O38: =M38-N38 -> 0 | P38: =P9/P24 -> 7458.252 | Q38: =N38-P38 -> -2610.308 | W38: Sep-25 | X38: =X9/X24 -> 4123.5375 | Y38: =Y9/Y24 -> 4123.5375 | Z38: =X38-Y38 -> 0 | AA38: =AA9/AA24 -> 4243.3333 | AB38: =Y38-AA38 -> -119.79583 | AH38: Sep-25 | AI38: 0 | AJ38: 0 | AK38: =AI38-AJ38 -> 0 | AL38: =AL9/AL24 -> 3529.4533 | AM38: =AJ38-AL38 -> -3529.4533 | AS38: Sep-25 | AT38: =AT9/AT24 -> 4334.5543 | AU38: =AU9/AU24 -> 4334.5543 | AV38: =AT38-AU38 -> 0 | AW38: =AW9/AW24 -> 4616.6667 | AX38: =AU38-AW38 -> -282.11238 | BD38: Sep-25 | BE38: =BE9/BE24 -> 3270.99 | BF38: =BF9/BF24 -> 3270.99 | BG38: =BE38-BF38 -> 0 | BH38: =BH9/BH24 -> 3523.2083 | BI38: =BF38-BH38 -> -252.21833 | BO38: Sep-25 | BP38: =BP9/BP24 -> 4633.4438 | BQ38: =BQ9/BQ24 -> 4633.4438 | BR38: =BP38-BQ38 -> 0 | BS38: =BS9/BS24 -> 4789.1883 | BT38: =BQ38-BS38 -> -155.7445
A39: Oct-25 | B39: =B10/B25 -> 11077.5 | C39: =C10/C25 -> 11077.5 | D39: =B39-C39 -> 0 | E39: =E10/E25 -> 11325 | F39: =C39-E39 -> -247.5 | L39: Oct-25 | M39: =M10/M25 -> 8511.7745 | N39: =N10/N25 -> 8511.7745 | O39: =M39-N39 -> 0 | P39: =P10/P25 -> 9518.8889 | Q39: =N39-P39 -> -1007.1144 | W39: Oct-25 | X39: =X10/X25 -> 13805 | Y39: =Y10/Y25 -> 13805 | Z39: =X39-Y39 -> 0 | AA39: =AA10/AA25 -> 5240 | AB39: =Y39-AA39 -> 8565 | AH39: Oct-25 | AI39: =AI10/AI25 -> 6160 | AJ39: =AJ10/AJ25 -> 6160 | AK39: =AI39-AJ39 -> 0 | AL39: =AL10/AL25 -> 5750 | AM39: =AJ39-AL39 -> 410 | AS39: Oct-25 | AT39: 0 | AU39: 0 | AV39: =AT39-AU39 -> 0 | AW39: =AW10/AW25 -> 7150 | AX39: =AU39-AW39 -> -7150 | BD39: Oct-25 | BE39: =BE10/BE25 -> 5120.3883 | BF39: =BF10/BF25 -> 5120.3883 | BG39: =BE39-BF39 -> 0 | BH39: =BH10/BH25 -> 5043.75 | BI39: =BF39-BH39 -> 76.638333 | BO39: Oct-25 | BP39: =BP10/BP25 -> 8480.6594 | BQ39: =BQ10/BQ25 -> 8480.6594 | BR39: =BP39-BQ39 -> 0 | BS39: =BS10/BS25 -> 7231.0484 | BT39: =BQ39-BS39 -> 1249.6111
A40: Nov-25 | B40: =B11/B26 -> 10948.109 | C40: =C11/C26 -> 10948.109 | D40: =B40-C40 -> 0 | E40: =E11/E26 -> 11262.5 | F40: =C40-E40 -> -314.3908 | L40: Nov-25 | M40: =M11/M26 -> 8417.6936 | N40: =N11/N26 -> 8417.6936 | O40: =M40-N40 -> 0 | P40: =P11/P26 -> 9223.3182 | Q40: =N40-P40 -> -805.62458 | W40: Nov-25 | X40: =X11/X26 -> 9251.1 | Y40: =Y11/Y26 -> 9251.1 | Z40: =X40-Y40 -> 0 | AA40: =AA11/AA26 -> 8156.25 | AB40: =Y40-AA40 -> 1094.85 | AH40: Nov-25 | AI40: =AI11/AI26 -> 6542.4615 | AJ40: =AJ11/AJ26 -> 6542.4615 | AK40: =AI40-AJ40 -> 0 | AL40: =AL11/AL26 -> 5779.4444 | AM40: =AJ40-AL40 -> 763.01709 | AS40: Nov-25 | AT40: 0 | AU40: 0 | AV40: =AT40-AU40 -> 0 | AW40: =AW11/AW26 -> 6701.3378 | AX40: =AU40-AW40 -> -6701.3378 | BD40: Nov-25 | BE40: =BE11/BE26 -> 5145.3 | BF40: =BF11/BF26 -> 5145.3 | BG40: =BE40-BF40 -> 0 | BH40: =BH11/BH26 -> 4927.5 | BI40: =BF40-BH40 -> 217.8 | BO40: Nov-25 | BP40: =BP11/BP26 -> 7933.8867 | BQ40: =BQ11/BQ26 -> 7933.8867 | BR40: =BP40-BQ40 -> 0 | BS40: =BS11/BS26 -> 8075.8144 | BT40: =BQ40-BS40 -> -141.92767
...

Sheet 2026-7 F
A1: Tugela | Financial Year | 2026/27 | M1: Explorer's Club | Financial Year | 2026/27 | Y1: The Library | Financial Year | 2026/27 | AK1: Tockie's Cottage | Financial Year | 2026/27 | AW1: Kumbuk House | Financial Year | 2026/27 | BI1: Cook's Cottage | Financial Year | 2026/27 | BU1: The Cockpit | Financial Year | 2026/27 | CG1: Franschhoek | Financial Year | 2026/27
B2: OTB @ 13 Aug 2026 | C2: OTB @ 30 Jul 2026 | D2: Variance | E2: Last Year Actual | F2: OTB vs LY | N2: OTB @ 13 Aug 2026 | O2: OTB @ 30 Jul 2026 | P2: Variance | Q2: Last Year Actual | R2: OTB vs LY | Z2: OTB @ 13 Aug 2026 | AA2: OTB @ 30 Jul 2026 | AB2: Variance | AC2: Last Year Actual | AD2: OTB vs LY | AL2: OTB @ 13 Aug 2026 | AM2: OTB @ 30 Jul 2026 | AN2: Variance | AO2: Last Year Actual | AP2: OTB vs LY | AX2: OTB @ 13 Aug 2026 | AY2: OTB @ 30 Jul 2026 | AZ2: Variance | BA2: Last Year Actual | BB2: OTB vs LY | BJ2: OTB @ 13 Aug 2026 | BK2: OTB @ 30 Jul 2026 | BL2: Variance | BM2: Last Year Actual | BN2: OTB vs LY | BV2: OTB @ 13 Aug 2026 | BW2: OTB @ 30 Jul 2026 | BX2: Variance | BY2: Last Year Actual | BZ2: OTB vs LY | CH2: OTB @ 13 Aug 2026 | CI2: OTB @ 30 Jul 2026 | CJ2: Variance | CK2: Last Year Actual | CL2: OTB vs LY
A3: Mar-26 | B3: 193417 | C3: 193417 | D3: - | E3: 286407.56 | F3: =B3-E3 -> -92990.56 | M3: Mar-26 | N3: 233716 | O3: 233716 | P3: - | Q3: 214300 | R3: =N3-Q3 -> 19416 | Y3: Mar-26 | Z3: 209477 | AA3: 209477 | AB3: - | AC3: 169354 | AD3: =Z3-AC3 -> 40123 | AK3: Mar-26 | AL3: 150961 | AM3: 150961 | AN3: - | AO3: 136700 | AP3: =AL3-AO3 -> 14261 | AW3: Mar-26 | AX3: 0 | AY3: 0 | AZ3: - | BA3: 42900 | BB3: =AX3-BA3 -> -42900 | BI3: Mar-26 | BJ3: 110761 | BK3: 110761 | BL3: - | BM3: 130393.96 | BN3: =BJ3-BM3 -> -19632.96 | BU3: Mar-26 | BX3: - | BZ3: =BV3-BY3 -> 0 | CG3: Mar-26 | CH3: =B3+N3+Z3+AL3+AX3+BJ3+BV3 -> 898332 | CI3: =C3+O3+AA3+AM3+AY3+BK3+BW3 -> 898332 | CJ3: - | CK3: =E3+Q3+AC3+AO3+BA3+BM3+BY3 -> 980055.52 | CL3: =CH3-CK3 -> -81723.52
A4: Apr-26 | B4: 142941.78 | C4: 142941.78 | D4: - | E4: 228600 | F4: =B4-E4 -> -85658.22 | M4: Apr-26 | N4: 138057.5 | O4: 138057.5 | P4: - | Q4: 226776.92 | R4: =N4-Q4 -> -88719.42 | Y4: Apr-26 | Z4: 131430.48 | AA4: 131430.48 | AB4: - | AC4: 30525 | AD4: =Z4-AC4 -> 100905.48 | AK4: Apr-26 | AL4: 56101.45 | AM4: 56101.45 | AN4: - | AO4: 150623.62 | AP4: =AL4-AO4 -> -94522.17 | AW4: Apr-26 | AX4: 0 | AY4: 0 | AZ4: - | BA4: 94905.24 | BB4: =AX4-BA4 -> -94905.24 | BI4: Apr-26 | BJ4: 101965.72 | BK4: 101965.72 | BL4: - | BM4: 111633.39 | BN4: =BJ4-BM4 -> -9667.67 | BU4: Apr-26 | BX4: - | BZ4: =BV4-BY4 -> 0 | CG4: Apr-26 | CH4: =B4+N4+Z4+AL4+AX4+BJ4+BV4 -> 570496.93 | CI4: =C4+O4+AA4+AM4+AY4+BK4+BW4 -> 570496.93 | CJ4: - | CK4: =E4+Q4+AC4+AO4+BA4+BM4+BY4 -> 843064.17 | CL4: =CH4-CK4 -> -272567.24
A5: May-26 | B5: 84490.41 | C5: 84490.41 | D5: - | E5: 122925 | F5: =B5-E5 -> -38434.59 | M5: May-26 | N5: 107971.7 | O5: 107971.7 | P5: - | Q5: 68358.34 | R5: =N5-Q5 -> 39613.36 | Y5: May-26 | Z5: 29853.06 | AA5: 29853.06 | AB5: - | AC5: 43065 | AD5: =Z5-AC5 -> -13211.94 | AK5: May-26 | AL5: 26377.84 | AM5: 26377.84 | AN5: - | AO5: 46125.75 | AP5: =AL5-AO5 -> -19747.91 | AW5: May-26 | AX5: 0 | AY5: 0 | AZ5: - | BA5: 19710.9 | BB5: =AX5-BA5 -> -19710.9 | BI5: May-26 | BJ5: 9874.56 | BK5: 9874.56 | BL5: - | BM5: 60948.04 | BN5: =BJ5-BM5 -> -51073.48 | BU5: May-26 | BX5: - | BZ5: =BV5-BY5 -> 0 | CG5: May-26 | CH5: =B5+N5+Z5+AL5+AX5+BJ5+BV5 -> 258567.57 | CI5: =C5+O5+AA5+AM5+AY5+BK5+BW5 -> 258567.57 | CJ5: - | CK5: =E5+Q5+AC5+AO5+BA5+BM5+BY5 -> 361133.03 | CL5: =CH5-CK5 -> -102565.46
A6: Jun-26 | B6: 37748.6 | C6: 37748.6 | D6: - | E6: 53982.5 | F6: =B6-E6 -> -16233.9 | M6: Jun-26 | N6: 12420.2 | O6: 12420.2 | P6: - | Q6: 105182.25 | R6: =N6-Q6 -> -92762.05 | Y6: Jun-26 | Z6: 53059.97 | AA6: 53059.97 | AB6: - | AC6: 23363.19 | AD6: =Z6-AC6 -> 29696.78 | AK6: Jun-26 | AL6: 0 | AM6: 0 | AN6: - | AO6: 42350 | AP6: =AL6-AO6 -> -42350 | AW6: Jun-26 | AX6: 0 | AY6: 0 | AZ6: - | BA6: 11246.64 | BB6: =AX6-BA6 -> -11246.64 | BI6: Jun-26 | BJ6: 8698 | BK6: 8698 | BL6: - | BM6: 0 | BN6: =BJ6-BM6 -> 8698 | BU6: Jun-26 | BX6: - | BZ6: =BV6-BY6 -> 0 | CG6: Jun-26 | CH6: =B6+N6+Z6+AL6+AX6+BJ6+BV6 -> 111926.77 | CI6: =C6+O6+AA6+AM6+AY6+BK6+BW6 -> 111926.77 | CJ6: =CH6-CI6 -> 0 | CK6: =E6+Q6+AC6+AO6+BA6+BM6+BY6 -> 236124.58 | CL6: =CH6-CK6 -> -124197.81
A7: Jul-26 | B7: 58684 | C7: 58684 | D7: =B7-C7 -> 0 | E7: 84001.48 | F7: =B7-E7 -> -25317.48 | M7: Jul-26 | N7: 30979.74 | O7: 30779.74 | P7: =N7-O7 -> 200 | Q7: 83212.5 | R7: =N7-Q7 -> -52232.76 | Y7: Jul-26 | Z7: 25619.28 | AA7: 25019.28 | AB7: =Z7-AA7 -> 600 | AC7: 65340 | AD7: =Z7-AC7 -> -39720.72 | AK7: Jul-26 | AL7: 29145.22 | AM7: 29145.22 | AN7: =AL7-AM7 -> 0 | AO7: 44990 | AP7: =AL7-AO7 -> -15844.78 | AW7: Jul-26 | AX7: 0 | AY7: 0 | AZ7: =AX7-AY7 -> 0 | BA7: 34133.08 | BB7: =AX7-BA7 -> -34133.08 | BI7: Jul-26 | BJ7: 69148.925 | BK7: 69115.87 | BL7: =BJ7-BK7 -> 33.055 | BM7: 36463.81 | BN7: =BJ7-BM7 -> 32685.115 | BU7: Jul-26 | BX7: =BV7-BW7 -> 0 | BZ7: =BV7-BY7 -> 0 | CG7: Jul-26 | CH7: =B7+N7+Z7+AL7+AX7+BJ7+BV7 -> 213577.16 | CI7: =C7+O7+AA7+AM7+AY7+BK7+BW7 -> 212744.11 | CJ7: =CH7-CI7 -> 833.055 | CK7: =E7+Q7+AC7+AO7+BA7+BM7+BY7 -> 348140.87 | CL7: =CH7-CK7 -> -134563.71
