Workbook
Name channel_analysis: 'SM Dec 2019 vs 2018'!$A$1:$L$9
Name reservations_summary_report__15: Sheet4!$A$1:$AD$818

Sheet VA
A1: As at 30 August 2011
A2: V&A HOTEL
A3: 2011 | B3: BUDGET | G3: Opera
A4: August | B4: 2331 | C4: =(B4/2914)*100 -> 79.993137 | D4: 3030300 | E4: =D4/B4 -> 1300 | F4: =SUM(#REF!-(QV!F6+DH!F6)) -> #REF! | G4: =(F4/2914)*100 -> #REF! | H4: =SUM(#REF!-(QV!H6+DH!H6)) -> #REF! | I4: =H4/F4 -> #REF!
A5: September | B5: 2035 | C5: =(B5/2820)*100 -> 72.163121 | D5: 3376065 | E5: =D5/B5 -> 1659 | F5: =SUM(#REF!-(QV!F7+DH!F7)) -> #REF! | G5: =(F5/2820)*100 -> #REF! | H5: =SUM(#REF!-(QV!H7+DH!H7)) -> #REF! | I5: =H5/F5 -> #REF!
A6: October | B6: 2374 | C6: =(B6/2914)*100 -> 81.468771 | D6: 4118671 | E6: =D6/B6 -> 1734.9078 | F6: =SUM(#REF!-(QV!F8+DH!F8)) -> #REF! | G6: =(F6/2914)*100 -> #REF! | H6: =SUM(#REF!-(QV!H8+DH!H8)) -> #REF! | I6: =H6/F6 -> #REF!
A7: November | B7: 2369 | C7: =(B7/2820)*100 -> 84.007092 | D7: 4492365 | E7: =D7/B7 -> 1896.3128 | F7: =SUM(#REF!-(QV!F9+DH!F9)) -> #REF! | G7: =(F7/2820)*100 -> #REF! | H7: =SUM(#REF!-(QV!H9+DH!H9)) -> #REF! | I7: =H7/F7 -> #REF!
A8: December | B8: 2040 | C8: =(B8/2914)*100 -> 70.006863 | D8: 4006414 | E8: =D8/B8 -> 1963.9284 | F8: =SUM(#REF!-(QV!F10+DH!F10)) -> #REF! | G8: =(F8/2914)*100 -> #REF! | H8: =SUM(#REF!-(QV!H10+DH!H10)) -> #REF! | I8: =H8/F8 -> #REF!
A9: January | B9: 2001 | C9: =(B9/2914)*100 -> 68.668497 | D9: 3694124 | E9: =D9/B9 -> 1846.1389 | F9: =SUM(#REF!-(QV!F11+DH!F11)) -> #REF! | G9: =(F9/2914)*100 -> #REF! | H9: =SUM(#REF!-(QV!H11+DH!H11)) -> #REF! | I9: =H9/F9 -> #REF!
A10: January | B10: 1984 | C10: =(B10/3100)*100 -> 64 | D10: 4130004 | E10: =D10/B10 -> 2081.6552 | F10: =1268-1 -> 1267 | G10: =(F10/3100)*100 -> 40.870968 | H10: 2229977 | I10: =H10/F10 -> 1760.045 | J10: 2253 | K10: =(J10/3100)*100 -> 72.677419 | L10: 4153012 | M10: =L10/J10 -> 1843.3253 | N10: =1890-39 -> 1851 | O10: =(N10/3100)*100 -> 59.709677 | P10: 3697397.3 | Q10: =P10/N10 -> 1997.5134
A11: 2011 | B11: Revenue | D11: Room Nights
B12: Opera/ Budget | D12: Opera/ Budget
A13: August | C13: =H4-D4 -> #REF! | E13: =F4-B4 -> #REF!
A14: September | C14: =H5-D5 -> #REF! | E14: =F5-B5 -> #REF!
A15: October | C15: =H6-D6 -> #REF! | E15: =F6-B6 -> #REF!
A16: November | C16: =H7-D7 -> #REF! | E16: =F7-B7 -> #REF!
A17: December | C17: =H8-D8 -> #REF! | E17: =F8-B8 -> #REF!
A18: January | C18: =H9-D9 -> #REF! | E18: =F9-B9 -> #REF!
A19: 2011 | B19: As at 10 Aug | C19: Opera | F19: As at 23 Aug | G19: Opera | J19: As at 23 Aug | K19: Opera | N19: Pick Up since 10 Aug | Q19: Pick Up since 23 Aug
D20: REV | F20: RM NITES | G20: OCC % | H20: REV | I20: AVR Rate | J20: RM NITES | K20: OCC % | L20: REV | M20: AVR Rate | N20: Revenue | Q20: Revenue
A21: August | D21: 2478432 | F21: =SUM(#REF!-(QV!F25+DH!F25)) -> #REF! | G21: =(F21/2914)*100 -> #REF! | H21: =SUM(#REF!-(QV!H25+DH!H25)) -> #REF! | I21: =H21/F21 -> #REF! | J21: =SUM(#REF!-(QV!J25+DH!J25)) -> #REF! | K21: =(J21/2914)*100 -> #REF! | L21: =SUM(#REF!-(QV!L25+DH!L25)) -> #REF! | M21: =L21/J21 -> #REF! | N21: =L21-H21 -> #REF! | P21: =J21-F21 -> #REF! | Q21: =O21-K21 -> #REF!
A22: September | D22: 2297652 | F22: =SUM(#REF!-(QV!F26+DH!F26)) -> #REF! | G22: =(F22/2820)*100 -> #REF! | H22: =SUM(#REF!-(QV!H26+DH!H26)) -> #REF! | I22: =H22/F22 -> #REF! | J22: =SUM(#REF!-(QV!J26+DH!J26)) -> #REF! | K22: =(J22/2820)*100 -> #REF! | L22: =SUM(#REF!-(QV!L26+DH!L26)) -> #REF! | M22: =L22/J22 -> #REF! | N22: =L22-H22 -> #REF! | P22: =J22-F22 -> #REF! | Q22: =O22-K22 -> #REF!
A23: October | D23: 3064307 | F23: =SUM(#REF!-(QV!F27+DH!F27)) -> #REF! | G23: =(F23/2914)*100 -> #REF! | H23: =SUM(#REF!-(QV!H27+DH!H27)) -> #REF! | I23: =H23/F23 -> #REF! | J23: =SUM(#REF!-(QV!J27+DH!J27)) -> #REF! | K23: =(J23/2914)*100 -> #REF! | L23: =SUM(#REF!-(QV!L27+DH!L27)) -> #REF! | M23: =L23/J23 -> #REF! | N23: =L23-H23 -> #REF! | P23: =J23-F23 -> #REF! | Q23: =O23-K23 -> #REF!
A24: November | D24: 3585143 | F24: =SUM(#REF!-(QV!F28+DH!F28)) -> #REF! | G24: =(F24/2820)*100 -> #REF! | H24: =SUM(#REF!-(QV!H28+DH!H28)) -> #REF! | I24: =H24/F24 -> #REF! | J24: =SUM(#REF!-(QV!J28+DH!J28)) -> #REF! | K24: =(J24/2820)*100 -> #REF! | L24: =SUM(#REF!-(QV!L28+DH!L28)) -> #REF! | M24: =L24/J24 -> #REF! | N24: =L24-H24 -> #REF! | P24: =J24-F24 -> #REF! | Q24: =O24-K24 -> #REF!
A25: December | D25: 3659400 | F25: =SUM(#REF!-(QV!F29+DH!F29)) -> #REF! | G25: =(F25/2914)*100 -> #REF! | H25: =SUM(#REF!-(QV!H29+DH!H29)) -> #REF! | I25: =H25/F25 -> #REF! | J25: =SUM(#REF!-(QV!J29+DH!J29)) -> #REF! | K25: =(J25/2914)*100 -> #REF! | L25: =SUM(#REF!-(QV!L29+DH!L29)) -> #REF! | M25: =L25/J25 -> #REF! | N25: =L25-H25 -> #REF! | P25: =J25-F25 -> #REF! | Q25: =O25-K25 -> #REF!
A26: January | D26: 2613748 | F26: =SUM(#REF!-(QV!F30+DH!F30)) -> #REF! | G26: =(F26/2914)*100 -> #REF! | H26: =SUM(#REF!-(QV!H30+DH!H30)) -> #REF! | I26: =H26/F26 -> #REF! | J26: =SUM(#REF!-(QV!J30+DH!J30)) -> #REF! | K26: =(J26/2914)*100 -> #REF! | L26: =SUM(#REF!-(QV!L30+DH!L30)) -> #REF! | M26: =L26/J26 -> #REF! | N26: =L26-H26 -> #REF! | P26: =J26-F26 -> #REF! | Q26: =O26-K26 -> #REF!
A27: QUEEN VICTORIA HOTEL
A28: 2011 | B28: BUDGET | G28: Opera
A29: August | B29: 565 | C29: =(B29/1085)*100 -> 52.073733 | D29: 847500 | E29: =D29/B29 -> 1500 | F29: 531 | G29: =(F29/1085)*100 -> 48.940092 | H29: 556849 | I29: =H29/F29 -> 1048.6798
A30: September | B30: 688 | C30: =(B30/1050)*100 -> 65.52381 | D30: 1344286 | E30: =D30/B30 -> 1953.9041 | F30: 347 | G30: =(F30/1050)*100 -> 33.047619 | H30: 725946 | I30: =H30/F30 -> 2092.0634
A31: October | B31: 821 | C31: =(B31/1085)*100 -> 75.668203 | D31: 1623204 | E31: =D31/B31 -> 1977.106 | F31: 202 | G31: =(F31/1085)*100 -> 18.617512 | H31: 396659 | I31: =H31/F31 -> 1963.6584
A32: November | B32: 850 | C32: =(B32/1050)*100 -> 80.952381 | D32: 1602112 | E32: =D32/B32 -> 1884.8376 | F32: 511 | G32: =(F32/1050)*100 -> 48.666667 | H32: 974081 | I32: =H32/F32 -> 1906.225
A33: December | B33: 705 | C33: =(B33/1085)*100 -> 64.976959 | D33: 1618503 | E33: =D33/B33 -> 2295.7489 | F33: 517 | G33: =(F33/1085)*100 -> 47.64977 | H33: 916435 | I33: =H33/F33 -> 1772.6015
A34: January | B34: 762 | C34: =(B34/1085)*100 -> 70.230415 | D34: 1493506 | E34: =D34/B34 -> 1959.9816 | F34: 317 | G34: =(F34/1085)*100 -> 29.21659 | H34: 455018 | I34: =H34/F34 -> 1435.388
A35: 2011 | B35: Revenue | D35: Room Nights
B36: Opera/ Budget | D36: Opera/ Budget
A37: August | C37: =H29-D29 -> -290651 | E37: =F29-B29 -> -34
A38: September | C38: =H30-D30 -> -618340 | E38: =F30-B30 -> -341
A39: October | C39: =H31-D31 -> -1226545 | E39: =F31-B31 -> -619
A40: November | C40: =H32-D32 -> -628031 | E40: =F32-B32 -> -339
...

Sheet QV
A1: As at 30 August 2011
A3: QUEEN VICTORIA HOTEL
A5: 2011 | B5: BUDGET | G5: Opera
A6: August | B6: 565 | C6: =(B6/1085)*100 -> 52.073733 | D6: 847500 | E6: =D6/B6 -> 1500 | F6: 531 | G6: =(F6/1085)*100 -> 48.940092 | H6: 556849 | I6: =H6/F6 -> 1048.6798
A7: September | B7: 688 | C7: =(B7/1050)*100 -> 65.52381 | D7: 1344286 | E7: =D7/B7 -> 1953.9041 | F7: 347 | G7: =(F7/1050)*100 -> 33.047619 | H7: 725946 | I7: =H7/F7 -> 2092.0634
A8: October | B8: 821 | C8: =(B8/1085)*100 -> 75.668203 | D8: 1623204 | E8: =D8/B8 -> 1977.106 | F8: 202 | G8: =(F8/1085)*100 -> 18.617512 | H8: 396659 | I8: =H8/F8 -> 1963.6584
A9: November | B9: 850 | C9: =(B9/1050)*100 -> 80.952381 | D9: 1602112 | E9: =D9/B9 -> 1884.8376 | F9: 511 | G9: =(F9/1050)*100 -> 48.666667 | H9: 974081 | I9: =H9/F9 -> 1906.225
A10: December | B10: 705 | C10: =(B10/1085)*100 -> 64.976959 | D10: 1618503 | E10: =D10/B10 -> 2295.7489 | F10: 517 | G10: =(F10/1085)*100 -> 47.64977 | H10: 916435 | I10: =H10/F10 -> 1772.6015
A11: January | B11: 762 | C11: =(B11/1085)*100 -> 70.230415 | D11: 1493506 | E11: =D11/B11 -> 1959.9816 | F11: 317 | G11: =(F11/1085)*100 -> 29.21659 | H11: 455018 | I11: =H11/F11 -> 1435.388
A12: January | B12: 1984 | C12: =(B12/3100)*100 -> 64 | D12: 4130004 | E12: =D12/B12 -> 2081.6552 | F12: =1268-1 -> 1267 | G12: =(F12/3100)*100 -> 40.870968 | H12: 2229977 | I12: =H12/F12 -> 1760.045 | J12: 2253 | K12: =(J12/3100)*100 -> 72.677419 | L12: 4153012 | M12: =L12/J12 -> 1843.3253 | N12: =1890-39 -> 1851 | O12: =(N12/3100)*100 -> 59.709677 | P12: 3697397.3 | Q12: =P12/N12 -> 1997.5134
A14: 2011 | B14: Revenue | D14: Room Nights
B15: Opera/ Budget | D15: Opera/ Budget
A16: August | C16: =H6-D6 -> -290651 | E16: =F6-B6 -> -34
A17: September | C17: =H7-D7 -> -618340 | E17: =F7-B7 -> -341
A18: October | C18: =H8-D8 -> -1226545 | E18: =F8-B8 -> -619
A19: November | C19: =H9-D9 -> -628031 | E19: =F9-B9 -> -339
A20: December | C20: =H10-D10 -> -702068 | E20: =F10-B10 -> -188
A21: January | C21: =H11-D11 -> -1038488 | E21: =F11-B11 -> -445
A23: 2011 | B23: As at 10 Aug | C23: Opera | F23: As at 23 Aug | G23: Opera | J23: As at 23 Aug | K23: Opera | N23: Pick Up since 10 Aug | Q23: Pick Up since 23 Aug
D24: REV | F24: RM NITES | G24: OCC % | H24: REV | I24: AVR Rate | J24: RM NITES | K24: OCC % | L24: REV | M24: AVR Rate | N24: Revenue | Q24: Revenue
A25: August | D25: 236039 | F25: 531 | G25: =(F25/1085)*100 -> 48.940092 | H25: 556849 | I25: =H25/F25 -> 1048.6798 | J25: 531 | K25: =(J25/1085)*100 -> 48.940092 | L25: 556849 | M25: =L25/J25 -> 1048.6798 | N25: =L25-H25 -> 0 | P25: =J25-F25 -> 0 | Q25: =O25-K25 -> -48.940092
A26: September | D26: 544244 | F26: 347 | G26: =(F26/1050)*100 -> 33.047619 | H26: 725946 | I26: =H26/F26 -> 2092.0634 | J26: 347 | K26: =(J26/1050)*100 -> 33.047619 | L26: 725946 | M26: =L26/J26 -> 2092.0634 | N26: =L26-H26 -> 0 | P26: =J26-F26 -> 0 | Q26: =O26-K26 -> -33.047619
A27: October | D27: 301903 | F27: 202 | G27: =(F27/1085)*100 -> 18.617512 | H27: 396659 | I27: =H27/F27 -> 1963.6584 | J27: 202 | K27: =(J27/1085)*100 -> 18.617512 | L27: 396659 | M27: =L27/J27 -> 1963.6584 | N27: =L27-H27 -> 0 | P27: =J27-F27 -> 0 | Q27: =O27-K27 -> -18.617512
A28: November | D28: 713164 | F28: 511 | G28: =(F28/1050)*100 -> 48.666667 | H28: 974081 | I28: =H28/F28 -> 1906.225 | J28: 511 | K28: =(J28/1050)*100 -> 48.666667 | L28: 974081 | M28: =L28/J28 -> 1906.225 | N28: =L28-H28 -> 0 | P28: =J28-F28 -> 0 | Q28: =O28-K28 -> -48.666667
A29: December | D29: 898118 | F29: 517 | G29: =(F29/1085)*100 -> 47.64977 | H29: 916435 | I29: =H29/F29 -> 1772.6015 | J29: 517 | K29: =(J29/1085)*100 -> 47.64977 | L29: 916435 | M29: =L29/J29 -> 1772.6015 | N29: =L29-H29 -> 0 | P29: =J29-F29 -> 0 | Q29: =O29-K29 -> -47.64977
A30: January | D30: 441440 | F30: 317 | G30: =(F30/1085)*100 -> 29.21659 | H30: 455018 | I30: =H30/F30 -> 1435.388 | J30: 317 | K30: =(J30/1085)*100 -> 29.21659 | L30: 455018 | M30: =L30/J30 -> 1435.388 | N30: =L30-H30 -> 0 | P30: =J30-F30 -> 0 | Q30: =O30-K30 -> -29.21659

Sheet DH
A1: As at 30 August 2011
A3: DOCK HOUSE HOTEL
A5: 2011 | B5: BUDGET | G5: Opera
A6: August | B6: 127.5 | C6: =(B6/186)*100 -> 68.548387 | D6: 225293 | E6: =D6/B6 -> 1767.0039 | F6: 104 | G6: =(F6/186)*100 -> 55.913978 | H6: 142701 | I6: =H6/F6 -> 1372.125
A7: September | B7: 135 | C7: =(B7/180)*100 -> 75 | D7: 329721 | E7: =D7/B7 -> 2442.3778 | F7: 76 | G7: =(F7/180)*100 -> 42.222222 | H7: 165081 | I7: =H7/F7 -> 2172.1184
A8: October | B8: 151.3 | C8: =(B8/186)*100 -> 81.344086 | D8: 373888 | E8: =D8/B8 -> 2471.1699 | F8: 71 | G8: =(F8/186)*100 -> 38.172043 | H8: 206440 | I8: =H8/F8 -> 2907.6056
A9: November | B9: 135 | C9: =(B9/180)*100 -> 75 | D9: 318066 | E9: =D9/B9 -> 2356.0444 | F9: 71 | G9: =(F9/180)*100 -> 39.444444 | H9: 159019 | I9: =H9/F9 -> 2239.7042
A10: December | B10: 151.2 | C10: =(B10/186)*100 -> 81.290323 | D10: 434040 | E10: =D10/B10 -> 2870.6349 | F10: 56 | G10: =(F10/186)*100 -> 30.107527 | H10: 195885 | I10: =H10/F10 -> 3497.9464
A11: January | B11: 140 | C11: =(B11/186)*100 -> 75.268817 | D11: 342997 | E11: =D11/B11 -> 2449.9786 | F11: 46 | G11: =(F11/186)*100 -> 24.731183 | H11: 159918 | I11: =H11/F11 -> 3476.4783
A12: January | B12: 1984 | C12: =(B12/3100)*100 -> 64 | D12: 4130004 | E12: =D12/B12 -> 2081.6552 | F12: =1268-1 -> 1267 | G12: =(F12/3100)*100 -> 40.870968 | H12: 2229977 | I12: =H12/F12 -> 1760.045 | J12: 2253 | K12: =(J12/3100)*100 -> 72.677419 | L12: 4153012 | M12: =L12/J12 -> 1843.3253 | N12: =1890-39 -> 1851 | O12: =(N12/3100)*100 -> 59.709677 | P12: 3697397.3 | Q12: =P12/N12 -> 1997.5134
A14: 2011 | B14: Revenue | D14: Room Nights
B15: Opera/ Budget | D15: Opera/ Budget
A16: August | C16: =H6-D6 -> -82592 | E16: =F6-B6 -> -23.5
A17: September | C17: =H7-D7 -> -164640 | E17: =F7-B7 -> -59
A18: October | C18: =H8-D8 -> -167448 | E18: =F8-B8 -> -80.3
A19: November | C19: =H9-D9 -> -159047 | E19: =F9-B9 -> -64
A20: December | C20: =H10-D10 -> -238155 | E20: =F10-B10 -> -95.2
A21: January | C21: =H11-D11 -> -183079 | E21: =F11-B11 -> -94
A23: 2011 | B23: As at 10 Aug | C23: Opera | F23: As at 23 Aug | G23: Opera | J23: As at 23 Aug | K23: Opera | N23: Pick Up since 10 Aug | Q23: Pick Up since 23 Aug
D24: REV | F24: RM NITES | G24: OCC % | H24: REV | I24: AVR Rate | J24: RM NITES | K24: OCC % | L24: REV | M24: AVR Rate | N24: Revenue | Q24: Revenue
A25: August | D25: 103623 | F25: 104 | G25: =(F25/186)*100 -> 55.913978 | H25: 142701 | I25: =H25/F25 -> 1372.125 | J25: 104 | K25: =(J25/186)*100 -> 55.913978 | L25: 142701 | M25: =L25/J25 -> 1372.125 | N25: =L25-H25 -> 0 | P25: =J25-F25 -> 0 | Q25: =O25-K25 -> -55.913978
A26: September | D26: 149866 | F26: 76 | G26: =(F26/180)*100 -> 42.222222 | H26: 165081 | I26: =H26/F26 -> 2172.1184 | J26: 76 | K26: =(J26/180)*100 -> 42.222222 | L26: 165081 | M26: =L26/J26 -> 2172.1184 | N26: =L26-H26 -> 0 | P26: =J26-F26 -> 0 | Q26: =O26-K26 -> -42.222222
A27: October | D27: 187725 | F27: 71 | G27: =(F27/186)*100 -> 38.172043 | H27: 206440 | I27: =H27/F27 -> 2907.6056 | J27: 71 | K27: =(J27/186)*100 -> 38.172043 | L27: 206440 | M27: =L27/J27 -> 2907.6056 | N27: =L27-H27 -> 0 | P27: =J27-F27 -> 0 | Q27: =O27-K27 -> -38.172043
A28: November | D28: 244345 | F28: 71 | G28: =(F28/180)*100 -> 39.444444 | H28: 159019 | I28: =H28/F28 -> 2239.7042 | J28: 71 | K28: =(J28/180)*100 -> 39.444444 | L28: 159019 | M28: =L28/J28 -> 2239.7042 | N28: =L28-H28 -> 0 | P28: =J28-F28 -> 0 | Q28: =O28-K28 -> -39.444444
A29: December | D29: 276122 | F29: 56 | G29: =(F29/186)*100 -> 30.107527 | H29: 195885 | I29: =H29/F29 -> 3497.9464 | J29: 56 | K29: =(J29/186)*100 -> 30.107527 | L29: 195885 | M29: =L29/J29 -> 3497.9464 | N29: =L29-H29 -> 0 | P29: =J29-F29 -> 0 | Q29: =O29-K29 -> -30.107527
A30: January | D30: 70050 | F30: 46 | G30: =(F30/186)*100 -> 24.731183 | H30: 159918 | I30: =H30/F30 -> 3476.4783 | J30: 46 | K30: =(J30/186)*100 -> 24.731183 | L30: 159918 | M30: =L30/J30 -> 3476.4783 | N30: =L30-H30 -> 0 | P30: =J30-F30 -> 0 | Q30: =O30-K30 -> -24.731183

Sheet Online Res
B1: V&A | C1: AH | D1: LS
A2: 40689 | B2: 33 res
A3: 40690 | B3: 17 res
A4: 40691 | B4: 4 res
A5: 40692 | B5: 1 res
A6: 40693 | B6: 11 res -
A7: 40694 | B7: 26 res | C7: 5
A8: 40695 | B8: 21 res | C8: 3
A9: 40696 | B9: 26 res * | C9: 9
A10: 40697 | B10: 18 res | C10: 1
A11: 40698 | B11: 10 res
A12: 40699 | C12: 11
A13: 40700 | B13: 35 res | C13: 5
A14: 40701 | B14: 21 res | C14: 6
A15: 40702 | B15: 11 res
A16: 40703 | B16: 40 res
A17: 40704 | B17: 18 res | C17: 9
A18: 40705 | B18: 14 res | C18: 7
A19: 40706 | B19: 3 res
A20: 40707 | B20: 42 res | C20: 9
A21: 40708 | B21: 18 res - | C21: 15
A22: 40709 | B22: 28 res | C22: 6
A23: 40710 | B23: 14 res | C23: 3
A24: 40711 | B24: 20 res | C24: 8
A25: 40712 | B25: 19 res | C25: 3
A26: 40713
A27: 40714 | B27: 34 res | C27: 7

Sheet Web Comparison
A1: mid July
C2: WOTIF 1N | D2: WOTIF 1N+ | E2: EXPEDIA 1N | F2: EXPEDIA 3N | G2: BOOKING 1N | H2: BOOKING 3N
A3: V&A | C3: 1640 | D3: 1640 | E3: 1640 | F3: 1097 * | G3: 1640 * | H3: 1093 * | I3: * ranking : 1
A4: DH | C4: 2430 | D4: 2430 | E4: 2430 | F4: 1810 | G4: 2430 | H4: 1810
A5: QV | C5: 1875 | D5: 1875 | E5: 1875 | F5: 1875 | G5: 1875 | H5: 1875
A6: AH | C6: 995 | D6: 995 | E6: 995 | F6: 669 ** | G6: 995 | H6: 663 | I6: ** ranking : 4
A7: LS | E7: 800 | F7: 666 | G7: 800 | H7: 650
A8: Bantry Bay Luxury Suites | D8: 1100 | E8: 955 | F8: 636 | G8: 955 | H8: 955
A9: Cape Royale | C9: 1430 | D9: 1430 | E9: 1435 | F9: 1435 | G9: 1400 | H9: 1400
A10: Commodore | C10: 2180 | D10: 2180 | E10: 1600 | F10: 1493 | G10: 1700 | H10: 1490
A11: Pepper Club | D11: 1216 | H11: 1600
A12: Radisson | C12: 2310 | D12: 2310 | E12: 2310 | F12: 2310 | G12: 2310 | H12: 2310
A13: TAJ | C13: 2150 | D13: 2150 | G13: 2150 | H13: 2150
A14: Westin | C14: 1589 | D14: 1112 | F14: 994 | G14: 1409 | H14: 1127.2
A15: President | C15: 1140 (1660) | D15: 1140 (1660) | G15: 1160 | H15: 996
A16: Breakwater | C16: 1295 | D16: 1101 | E16: 971 | G16: 970 | H16: 976
A17: Hilton | E17: 738 | G17: 816 | H17: 738
A18: Vineyard | C18: 945

Sheet All
A1: AMBASSADOR
B2: BUDGET | C2: OPERA | D2: OCC % | E2: IDEAS | F2: LAST YEAR | G2: REVENUE | I2: P/UP SINCE 25/10 | J2: P/UP SINCE 13/9
C3: as @ 01/11 | G3: Opera/ Budget | H3: Ideas/ Budget | I3: REV | J3: REV
A4: Nov | B4: 2000656 | C4: =#REF! -> #REF! | D4: =#REF! -> #REF! | E4: =#REF! -> #REF! | F4: 1874949 | G4: =#REF! -> #REF! | H4: =#REF! -> #REF! | I4: =#REF! -> #REF! | J4: =#REF! -> #REF!
A5: Dec | B5: 2672018 | C5: =#REF! -> #REF! | D5: =#REF! -> #REF! | E5: =#REF! -> #REF! | F5: 2544779 | G5: =#REF! -> #REF! | H5: =#REF! -> #REF! | I5: =#REF! -> #REF! | J5: =#REF! -> #REF!
A6: Jan | B6: 2329289 | C6: =#REF! -> #REF! | D6: =#REF! -> #REF! | E6: =#REF! -> #REF! | F6: 2194352 | G6: =#REF! -> #REF! | H6: =#REF! -> #REF! | I6: =#REF! -> #REF! | J6: =#REF! -> #REF!
A7: Feb | B7: 2200750 | C7: =#REF! -> #REF! | D7: =#REF! -> #REF! | E7: =#REF! -> #REF! | F7: 2397167 | G7: =#REF! -> #REF! | H7: =#REF! -> #REF! | I7: =#REF! -> #REF! | J7: =#REF! -> #REF!
A8: Mar | C8: =#REF! -> #REF! | D8: =#REF! -> #REF! | E8: =#REF! -> #REF! | F8: 2261197 | I8: =#REF! -> #REF! | J8: =#REF! -> #REF!
A9: April | C9: =#REF! -> #REF! | D9: =#REF! -> #REF! | E9: =#REF! -> #REF! | F9: 1605796 | J9: =#REF! -> #REF!
A10: V&A PROPERTIES COMBINED
B11: BUDGET | C11: OPERA | D11: OCC % | E11: IDEAS | F11: LAST YEAR | G11: REVENUE | I11: P/UP SINCE 25/10 | J11: P/UP SINCE 13/9
C12: as @ 01/11 | G12: Opera/ Budget | H12: Ideas/ Budget | I12: REV | J12: REV
A13: Nov | B13: 6412543 | C13: =#REF! -> #REF! | D13: =#REF! -> #REF! | E13: =#REF! -> #REF! | F13: 4679927 | G13: =#REF! -> #REF! | H13: =#REF! -> #REF! | I13: =#REF! -> #REF! | J13: =#REF! -> #REF!
A14: Dec | B14: 6058957 | C14: =#REF! -> #REF! | D14: =#REF! -> #REF! | E14: =#REF! -> #REF! | F14: 3963564 | G14: =#REF! -> #REF! | H14: =#REF! -> #REF! | I14: =#REF! -> #REF! | J14: =#REF! -> #REF!
A15: Jan | B15: 5530627 | C15: =#REF! -> #REF! | D15: =#REF! -> #REF! | E15: =#REF! -> #REF! | F15: 3786131 | G15: =#REF! -> #REF! | H15: =#REF! -> #REF! | I15: =#REF! -> #REF! | J15: =#REF! -> #REF!
A16: Feb | B16: 7074513 | C16: =#REF! -> #REF! | D16: =#REF! -> #REF! | E16: =#REF! -> #REF! | F16: 5065519 | G16: =#REF! -> #REF! | H16: =#REF! -> #REF! | I16: =#REF! -> #REF! | J16: =#REF! -> #REF!
A17: Mar | C17: =#REF! -> #REF! | D17: =#REF! -> #REF! | E17: =#REF! -> #REF! | F17: 4445403 | I17: =#REF! -> #REF! | J17: =#REF! -> #REF!
A18: April | C18: =#REF! -> #REF! | D18: =#REF! -> #REF! | E18: =#REF! -> #REF! | F18: 3899614 | J18: =#REF! -> #REF!
A19: LA SPLENDIDA
B20: BUDGET | C20: HOTELIER | D20: OCC % | E20: LAST YEAR | G20: REVENUE | I20: P/UP SINCE 25/10 | J20: P/UP SINCE 13/9
B21: as @ 01/11 | G21: Hotelier/ Budget | I21: REV | J21: REV
A22: Nov | B22: 296280 | C22: =#REF! -> #REF! | D22: =#REF! -> #REF! | E22: 254742 | G22: =#REF! -> #REF! | I22: =#REF! -> #REF! | J22: =#REF! -> #REF!
A23: Dec | B23: 321780 | C23: =#REF! -> #REF! | D23: =#REF! -> #REF! | E23: 324829 | G23: =#REF! -> #REF! | I23: =#REF! -> #REF! | J23: =#REF! -> #REF!
A24: Jan | B24: 312852 | C24: =#REF! -> #REF! | D24: =#REF! -> #REF! | E24: 330355 | G24: =#REF! -> #REF! | I24: =#REF! -> #REF! | J24: =#REF! -> #REF!
A25: Feb | B25: 280560 | C25: =#REF! -> #REF! | D25: =#REF! -> #REF! | E25: 479590 | G25: =#REF! -> #REF! | I25: =#REF! -> #REF! | J25: =#REF! -> #REF!
A26: Mar | C26: =#REF! -> #REF! | D26: =#REF! -> #REF! | E26: 481432 | I26: =#REF! -> #REF! | J26: =#REF! -> #REF!
A27: April | C27: =#REF! -> #REF! | D27: =#REF! -> #REF! | E27: 359095 | J27: =#REF! -> #REF!
A28: AH: | B28: Great pick up for November in the last 7 days : R297k - AVR dropped by R48
B29: December also good pick in the last 7 days, however, AVR dropped by R57
A30: VA: | B30: Pick up November slower than previously reported
B31: Good pick up in Dec R286k in the last 7 days and AVR up by R10
B32: Great pick up for Jan R317k as well as AVR up by R14
A33: LS: | B33: Great pick in in the last 7 days, R32k over budget already
B34: Steady pick up Dec & Jan

Sheet 09.12.19
A1: Devonvale Revenue Report 09 December 2019
B2: OTB @ 09 Dec 2019 | C2: Target | D2: LY Actual | E2: OTB vrs Target | G2: Target vrs LY | I2: Variance last 7 days | J2: as @ 03 June 2014 | K2: Variance last 14 days | L2: OTB @ 25 Nov 2019 | M2: Actual vrs LY | O2: as @ 8 Nov 2017 | P2: Variance 2018 vrs 2017 | Q2: OTB @ 8 Nov 2018 | R2: Variance OTB vrs LY OTB | S2: OTB @ 20 Dec 2018 | T2: Variance
A3: Mar | B3: 976369 | C3: =(D3*1.175) -> 940156.28 | D3: 800133 | E3: =B3-C3 -> 36212.725 | F3: =(B3-C3)/C3 -> 0.038517772 | G3: =(C3-D3) -> 140023.28 | H3: =(C3-D3)/D3 -> 0.175 | I3: =B3-J3 -> 815149 | J3: 161220 | L3: 976369 | M3: =B3-D3 -> 176236 | N3: =(B3-D3)/D3 -> 0.22025838 | O3: 1191028
A4: Apr | B4: 766954 | C4: =(D4*1.175) -> 589504.55 | D4: 501706 | E4: =B4-C4 -> 177449.45 | F4: =(B4-C4)/C4 -> 0.30101456 | G4: =(C4-D4) -> 87798.55 | H4: =(C4-D4)/D4 -> 0.175 | I4: =B4-J4 -> 605734 | J4: 161220 | L4: 766954 | M4: =B4-D4 -> 265248 | N4: =(B4-D4)/D4 -> 0.5286921 | O4: 1245578
A5: May | B5: 644339 | C5: =(D5*1.175) -> 621985.08 | D5: 529349 | E5: =B5-C5 -> 22353.925 | F5: =(B5-C5)/C5 -> 0.035939649 | G5: =(C5-D5) -> 92636.075 | H5: =(C5-D5)/D5 -> 0.175 | I5: =B5-J5 -> 483119 | J5: 161220 | L5: 644339 | M5: =B5-D5 -> 114990 | N5: =(B5-D5)/D5 -> 0.21722909 | O5: 1488076
A6: Jun | B6: 530924 | C6: =(D6*1.175) -> 427825.73 | D6: 364107 | E6: =B6-C6 -> 103098.27 | F6: =(B6-C6)/C6 -> 0.24098194 | G6: =(C6-D6) -> 63718.725 | H6: =(C6-D6)/D6 -> 0.175 | I6: =B6-J6 -> 369704 | J6: 161220 | L6: 530924 | M6: =B6-D6 -> 166817 | N6: =(B6-D6)/D6 -> 0.45815378 | O6: 1449686
A7: July | B7: 658052 | C7: =(D7*1.175) -> 519911.65 | D7: 442478 | E7: =B7-C7 -> 138140.35 | F7: =(B7-C7)/C7 -> 0.26569966 | G7: =(C7-D7) -> 77433.65 | H7: =(C7-D7)/D7 -> 0.175 | I7: =B7-J7 -> 496832 | J7: 161220 | L7: 658052 | M7: =B7-D7 -> 215574 | N7: =(B7-D7)/D7 -> 0.4871971 | O7: 770876
A8: Aug | B8: 648180 | C8: =(D8*1.175) -> 513073.15 | D8: 436658 | E8: =B8-C8 -> 135106.85 | F8: =(B8-C8)/C8 -> 0.26332863 | G8: =(C8-D8) -> 76415.15 | H8: =(C8-D8)/D8 -> 0.175 | I8: =B8-J8 -> 438056 | J8: 210124 | L8: 648180 | M8: =B8-D8 -> 211522 | N8: =(B8-D8)/D8 -> 0.48441114 | O8: 570574
A9: Sept | B9: =310920.68+365482.43 -> 676403.11 | C9: =(D9*1.175) -> 639303.4 | D9: 544088 | E9: =B9-C9 -> 37099.71 | F9: =(B9-C9)/C9 -> 0.05803146 | G9: =(C9-D9) -> 95215.4 | H9: =(C9-D9)/D9 -> 0.175 | I9: =B9-J9 -> 387627.11 | J9: 288776 | L9: =310920.68+365482.43 -> 676403.11 | M9: =B9-D9 -> 132315.11 | N9: =(B9-D9)/D9 -> 0.24318697
A10: Oct | B10: 910865 | C10: =(D10*1.175) -> 747056.78 | D10: 635793 | E10: =B10-C10 -> 163808.22 | F10: =(B10-C10)/C10 -> 0.21927145 | G10: =(C10-D10) -> 111263.78 | H10: =(C10-D10)/D10 -> 0.175 | I10: =B10-J10 -> 697139 | J10: 213726 | L10: 910865 | M10: =B10-D10 -> 275072 | N10: =(B10-D10)/D10 -> 0.43264396
A11: Nov | B11: 1045436 | C11: =(D11*1.175) -> 905782.83 | D11: 770879 | E11: =B11-C11 -> 139653.17 | F11: =(B11-C11)/C11 -> 0.15417954 | G11: =(C11-D11) -> 134903.83 | H11: =(C11-D11)/D11 -> 0.175 | I11: =B11-J11 -> 884526 | J11: 160910 | L11: 1045436 | M11: =B11-D11 -> 274557 | N11: =(B11-D11)/D11 -> 0.35616095
A12: Dec | B12: 1178518 | C12: =(D12*1.175) -> 1112324.3 | D12: 946659 | E12: =B12-C12 -> 66193.675 | F12: =(B12-C12)/C12 -> 0.05950933 | G12: =(C12-D12) -> 165665.32 | H12: =(C12-D12)/D12 -> 0.175 | L12: 1178518 | M12: =B12-D12 -> 231859 | N12: =(B12-D12)/D12 -> 0.24492346
A13: Jan | B13: 1117894 | C13: =(D13*1.175) -> 1100221.8 | D13: 936359 | E13: =B13-C13 -> 17672.175 | F13: =(B13-C13)/C13 -> 0.016062375 | G13: =(C13-D13) -> 163862.82 | H13: =(C13-D13)/D13 -> 0.175 | L13: 1117894 | M13: =B13-D13 -> 181535 | N13: =(B13-D13)/D13 -> 0.19387329
A14: Feb | B14: 1103333 | C14: =(D14*1.175) -> 1065344.3 | D14: 906676 | E14: =B14-C14 -> 37988.7 | F14: =(B14-C14)/C14 -> 0.035658613 | G14: =(C14-D14) -> 158668.3 | H14: =(C14-D14)/D14 -> 0.175 | L14: 1103333 | M14: =B14-D14 -> 196657 | N14: =(B14-D14)/D14 -> 0.21689887
A15: Fin Year | B15: =SUM(B3:B14) -> 10257267 | C15: =SUM(C3:C14) -> 9182489.9 | D15: =SUM(D3:D14) -> 7814885 | E15: =SUM(E3:E14) -> 1074777.2 | G15: =SUM(G3:G14) -> 1367604.9 | H15: =(C15-D15)/D15 -> 0.175 | L15: =SUM(L3:L14) -> 10257267 | M15: =B15-D15 -> 2442382.1 | N15: =(B15-D15)/D15 -> 0.3125295
A16: Oct | B16: 1187356 | C16: =D16*1.1 -> 1007437.2 | D16: 915852 | E16: =B16-C16 -> 179918.8 | F16: =(B16-C16)/C16 -> 0.17859059 | G16: =(C16-D16) -> 91585.2 | H16: =(C16-D16)/D16 -> 0.1 | L16: 1187356 | M16: =B16-D16 -> 271504 | N16: =(B16-D16)/D16 -> 0.29644964
A17: Nov | B17: 1465604 | C17: =D17*1.1 -> 1517958.2 | D17: 1379962 | E17: =B17-C17 -> -52354.2 | F17: =(B17-C17)/C17 -> -0.034489883 | G17: =(C17-D17) -> 137996.2 | H17: =(C17-D17)/D17 -> 0.1 | L17: 1465604 | M17: =B17-D17 -> 85642 | N17: =(B17-D17)/D17 -> 0.062061129
A18: Dec | B18: 1353583 | C18: 1074639 | D18: 979969 | E18: =B18-C18 -> 278944 | F18: =(B18-C18)/C18 -> 0.25956996 | G18: =(C18-D18) -> 94670 | H18: =(C18-D18)/D18 -> 0.096605097 | L18: 1353583 | M18: =B18-D18 -> 373614 | N18: =(B18-D18)/D18 -> 0.38125084
A19: Jan | B19: 1039316 | C19: =D19*1.1 -> 762835.7 | D19: 693487 | E19: =B19-C19 -> 276480.3 | F19: =(B19-C19)/C19 -> 0.36243755 | G19: =(C19-D19) -> 69348.7 | H19: =(C19-D19)/D19 -> 0.1 | L19: 1039316 | M19: =B19-D19 -> 345829 | N19: =(B19-D19)/D19 -> 0.4986813
A20: Feb | B20: 2032270 | C20: =D20*1.1 -> 1590482.3 | D20: 1445893 | E20: =B20-C20 -> 441787.7 | F20: =(B20-C20)/C20 -> 0.27776964 | G20: =(C20-D20) -> 144589.3 | H20: =(C20-D20)/D20 -> 0.1 | L20: 2032270 | M20: =B20-D20 -> 586377 | N20: =(B20-D20)/D20 -> 0.40554661
A21: Mar | B21: 1805608 | C21: =D21*1.1 -> 1752617.9 | D21: 1593289 | E21: =B21-C21 -> 52990.1 | F21: =(B21-C21)/C21 -> 0.030234828 | G21: =(C21-D21) -> 159328.9 | H21: =(C21-D21)/D21 -> 0.1 | L21: 1805608 | M21: =B21-D21 -> 212319 | N21: =(B21-D21)/D21 -> 0.13325831
A22: Apr | B22: 1145562 | C22: =D22*1.1 -> 1300503.6 | D22: 1182276 | E22: =B22-C22 -> -154941.6 | F22: =(B22-C22)/C22 -> -0.11913969 | G22: =(C22-D22) -> 118227.6 | H22: =(C22-D22)/D22 -> 0.1 | L22: 1145562 | M22: =B22-D22 -> -36714 | N22: =(B22-D22)/D22 -> -0.031053663
A23: May | B23: 1022011 | C23: =D23*1.1 -> 507736.9 | D23: 461579 | E23: =B23-C23 -> 514274.1 | F23: =(B23-C23)/C23 -> 1.0128752 | G23: =(C23-D23) -> 46157.9 | H23: =(C23-D23)/D23 -> 0.1 | L23: 1022011 | M23: =B23-D23 -> 560432 | N23: =(B23-D23)/D23 -> 1.2141627
A24: Apr | B24: 1244430 | C24: =D24*1.1 -> 1522590.3 | D24: 1384173 | E24: =B24-C24 -> -278160.3 | F24: =(B24-C24)/C24 -> -0.18268887 | G24: =(C24-D24) -> 138417.3 | H24: =(C24-D24)/D24 -> 0.1 | K24: =B24-L24 -> 0 | L24: 1244430 | M24: =B24-D24 -> -139743 | N24: =(B24-D24)/D24 -> -0.10095776
A25: May | B25: 282761 | C25: =D25*1.1 -> 1417482 | D25: 1288620 | E25: =B25-C25 -> -1134721 | F25: =(B25-C25)/C25 -> -0.80051881 | G25: =(C25-D25) -> 128862 | H25: =(C25-D25)/D25 -> 0.1 | K25: =B25-L25 -> 0 | L25: 282761 | M25: =B25-D25 -> -1005859 | N25: =(B25-D25)/D25 -> -0.78057069
A26: June | B26: 108882 | C26: =D26*1.1 -> 818774 | D26: 744340 | E26: =B26-C26 -> -709892 | F26: =(B26-C26)/C26 -> -0.86701825 | G26: =(C26-D26) -> 74434 | H26: =(C26-D26)/D26 -> 0.1 | K26: =B26-L26 -> 0 | L26: 108882 | M26: =B26-D26 -> -635458 | N26: =(B26-D26)/D26 -> -0.85372007
A27: July | B27: 1267953 | C27: =D27*1.1 -> 939474.8 | D27: 854068 | E27: =B27-C27 -> 328478.2 | F27: =(B27-C27)/C27 -> 0.34964025 | G27: =(C27-D27) -> 85406.8 | H27: =(C27-D27)/D27 -> 0.1 | L27: 1267953 | M27: =B27-D27 -> 413885 | N27: =(B27-D27)/D27 -> 0.48460427
A28: August | B28: 300416 | C28: =D28*1.1 -> 417312.5 | D28: 379375 | E28: =B28-C28 -> -116896.5 | F28: =(B28-C28)/C28 -> -0.28011742 | G28: =(C28-D28) -> 37937.5 | H28: =(C28-D28)/D28 -> 0.1 | L28: 300416 | M28: =B28-D28 -> -78959 | N28: =(B28-D28)/D28 -> -0.20812916
A29: September | B29: 484160 | C29: =D29*1.1 -> 628629.1 | D29: 571481 | E29: =B29-C29 -> -144469.1 | F29: =(B29-C29)/C29 -> -0.22981612 | G29: =(C29-D29) -> 57148.1 | H29: =(C29-D29)/D29 -> 0.1 | K29: =B29-L29 -> 0 | L29: 484160 | M29: =B29-D29 -> -87321 | N29: =(B29-D29)/D29 -> -0.15279773
A30: October | B30: 403884 | C30: =D30*1.1 -> 730540.8 | D30: 664128 | E30: =B30-C30 -> -326656.8 | F30: =(B30-C30)/C30 -> -0.44714381 | G30: =(C30-D30) -> 66412.8 | H30: =(C30-D30)/D30 -> 0.1 | K30: =B30-L30 -> 0 | L30: 403884 | M30: =B30-D30 -> -260244 | N30: =(B30-D30)/D30 -> -0.3918582
A31: November | B31: 1196163 | C31: =D31*1.1 -> 1536906.8 | D31: 1397188 | E31: =B31-C31 -> -340743.8 | F31: =(B31-C31)/C31 -> -0.22170752 | G31: =(C31-D31) -> 139718.8 | H31: =(C31-D31)/D31 -> 0.1 | K31: =B31-L31 -> 0 | L31: 1196163 | M31: =B31-D31 -> -201025 | N31: =(B31-D31)/D31 -> -0.14387828
A32: December | B32: 1310080 | C32: =D32*1.1 -> 1936268.4 | D32: 1760244 | E32: =B32-C32 -> -626188.4 | F32: =(B32-C32)/C32 -> -0.32339959 | G32: =(C32-D32) -> 176024.4 | H32: =(C32-D32)/D32 -> 0.1 | K32: =B32-L32 -> 0 | L32: 1310080 | M32: =B32-D32 -> -450164 | N32: =(B32-D32)/D32 -> -0.25573955
A33: January | B33: 1659145 | C33: =D33*1.1 -> 1825997.8 | D33: 1659998 | E33: =B33-C33 -> -166852.8 | F33: -0.61325998 | G33: 350895.35 | H33: 0.1 | K33: =B33-L33 -> 0 | L33: 1659145 | M33: =B33-D33 -> -853 | N33: -0.57458598
A34: Feb | B34: 1879453 | C34: =D34*1.1 -> 1819609 | D34: 1654190 | E34: =B34-C34 -> 59844 | F34: =(B34-C34)/C34 -> 0.032888384 | G34: =(C34-D34) -> 165419 | H34: =(C34-D34)/D34 -> 0.1 | K34: =B34-L34 -> 0 | L34: 1879453 | M34: =B34-D34 -> 225263 | N34: =(B34-D34)/D34 -> 0.13617722
A35: March | B35: 1257902 | C35: =D35*1.1 -> 1439953.9 | D35: 1309049 | E35: =B35-C35 -> -182051.9 | F35: =(B35-C35)/C35 -> -0.12642898 | G35: =(C35-D35) -> 130904.9 | H35: =(C35-D35)/D35 -> 0.1 | K35: =B35-L35 -> 0 | L35: 1257902 | M35: =B35-D35 -> -51147 | N35: =(B35-D35)/D35 -> -0.039071876
A36: Apr | B36: 641964 | C36: 552499.2 | D36: 502272 | E36: =B36-C36 -> 89464.8 | F36: 0.032714618 | G36: 50227.2 | H36: 0.1 | K36: =B36-L36 -> 0 | L36: 641964 | M36: =B36-D36 -> 139692 | N36: =(B36-D36)/D36 -> 0.27812022
A37: May | B37: 291306 | C37: =D37*1.1 -> 343454.1 | D37: 312231 | E37: =B37-C37 -> -52148.1 | F37: =(B37-C37)/C37 -> -0.15183426 | G37: =(C37-D37) -> 31223.1 | H37: =(C37-D37)/D37 -> 0.1 | K37: =B37-L37 -> 0 | L37: 291306 | M37: =B37-D37 -> -20925 | N37: =(B37-D37)/D37 -> -0.067017689
A38: June | B38: 345442 | C38: 350000 | D38: 0 | E38: =B38-C38 -> -4558 | F38: =(B38-C38)/C38 -> -0.013022857 | G38: =(C38-D38) -> 350000 | H38: =(C38-D38)/D38 -> #DIV/0! | K38: =B38-L38 -> 0 | L38: 345442 | M38: =B38-D38 -> 345442 | N38: =(B38-D38)/D38 -> #DIV/0!
A39: July | B39: 245810 | C39: =D39*1.1 -> 398643.3 | D39: 362403 | E39: =B39-C39 -> -152833.3 | F39: =(B39-C39)/C39 -> -0.38338359 | G39: =(C39-D39) -> 36240.3 | H39: =(C39-D39)/D39 -> 0.1 | K39: =B39-L39 -> 0 | L39: 245810 | M39: =B39-D39 -> -116593 | N39: =(B39-D39)/D39 -> -0.32172195
A40: Aug | B40: 493056 | C40: =D40*1.1 -> 330457.6 | D40: 300416 | E40: =B40-C40 -> 162598.4 | F40: =(B40-C40)/C40 -> 0.49204013 | G40: =(C40-D40) -> 30041.6 | H40: =(C40-D40)/D40 -> 0.1 | K40: =B40-L40 -> 0 | L40: 493056 | M40: =B40-D40 -> 192640 | N40: =(B40-D40)/D40 -> 0.64124414
...

Sheet Revenue
A2: Grande Roche Revenue On the Books @ 14 August 2026
B3: OTB 14.08.26 | C3: OTB 29.07.26 | D3: Variance | E3: Last Year Actual | F3: OTB vs LY Actual | G3: Budget / Target | H3: Variance last 7 days | I3: as @ 03 June 2014 | J3: OTB vs Target | K3: as @ 8 Nov 2017 | L3: Variance 2018 vrs 2017 | M3: OTB @ 8 Nov 2018 | N3: LY Actal vs Target | O3: OTB 25.05.22 | P3: Variance OTB Current vs LY
A4: 46204 | B4: 435432.83 | C4: 432236.3 | D4: =B4-C4 -> 3196.5217 | E4: 863725.25 | F4: =B4-E4 -> -428292.43 | N4: =E4-G4 -> 863725.25 | O4: 294981.16 | P4: =B4-O4 -> 140451.67 | Q4: =(B4-E4)/E4 -> -0.49586651
A5: 46235 | B5: 351047.55 | C5: 325201.4 | D5: =B5-C5 -> 25846.148 | E5: 727787.78 | F5: =B5-E5 -> -376740.23 | N5: =E5-G5 -> 727787.78 | O5: 294981.16 | P5: =B5-O5 -> 56066.388 | Q5: =(B5-E5)/E5 -> -0.51765122
A6: 46266 | B6: 1769805.8 | C6: 1772264.3 | D6: =B6-C6 -> -2458.5217 | E6: 740532.12 | F6: 119243.9 | N6: 740532.12 | O6: 294981.16 | P6: 564794.86 | Q6: 0.16102461
A7: 46296 | B7: 1145575.6 | C7: 1123059.8 | D7: =B7-C7 -> 22515.843 | E7: 1689533.9 | F7: =B7-E7 -> -543958.28 | N7: =E7-G7 -> 1689533.9 | O7: 294981.16 | P7: =B7-O7 -> 850594.46 | Q7: =(B7-E7)/E7 -> -0.3219576
A8: 46327 | B8: 2324453.2 | C8: 1920241.7 | D8: =B8-C8 -> 404211.48 | E8: 2489720.7 | F8: =B8-E8 -> -165267.57 | N8: =E8-G8 -> 2489720.7 | O8: 294981.16 | P8: =B8-O8 -> 2029472 | Q8: =(B8-E8)/E8 -> -0.066379961
A9: 46357 | B9: 1371059.3 | C9: 1224549.7 | D9: =B9-C9 -> 146509.63 | E9: 2575263.1 | F9: =B9-E9 -> -1204203.8 | N9: =E9-G9 -> 2575263.1 | O9: 294981.16 | P9: =B9-O9 -> 1076078.2 | Q9: =(B9-E9)/E9 -> -0.46760418
A10: 46388 | B10: 1956805 | E10: 3549116.3 | F10: =B10-E10 -> -1592311.3 | N10: =E10-G10 -> 3549116.3 | O10: 294981.16 | P10: =B10-O10 -> 1661823.8 | Q10: =(B10-E10)/E10 -> -0.44865007
A11: TOTAL | B11: =SUM(B4:B10) -> 9354179.3 | C11: =SUM(C4:C10) -> 6797553.2 | D11: =SUM(D4:D10) -> 599821.1 | E11: =SUM(E4:E10) -> 12635679 | F11: =B11-E11 -> -3281499.9 | G11: 1508477 | J11: =B11-G11 -> 7845702.2 | N11: =E11-G11 -> 11127202 | O11: 294981.16 | P11: =B11-O11 -> 9059198.1
A12: Occupancy
B13: OTB 14.08.26 | C13: OTB 29.07.26 | D13: Variance | E13: Last Year Actual | F13: OTB vs LY Actual | G13: Room Nights | K13: as @ 8 Nov 2017 | L13: Variance 2018 vrs 2017 | M13: OTB @ 8 Nov 2018 | N13: LY Actal vs Target | O13: OTB 25.05.22 | P13: Variance OTB Current vs LY
A14: 46204 | B14: 0.1238 | C14: 0.1238 | D14: =B14-C14 -> 0 | E14: 0.252 | F14: =B14-E14 -> -0.1282 | G14: 66 | O14: 0.0947 | P14: =#REF!-O14 -> #REF!
A15: 46235 | B15: 0.101 | C15: 0.092 | D15: =B15-C15 -> 0.009 | E15: 0.2541 | F15: =B15-E15 -> -0.1531 | G15: 66 | O15: 0.0947 | P15: =#REF!-O15 -> #REF!
A16: 46266 | B16: 0.356 | C16: 0.348 | D16: =B16-C16 -> 0.008 | E16: 0.239 | F16: =B16-E16 -> 0.117 | G16: 66 | O16: 0.0947 | P16: =#REF!-O16 -> #REF!
A17: 46296 | B17: 0.327 | C17: 0.284 | D17: =B17-C17 -> 0.043 | E17: 0.277 | F17: =B17-E17 -> 0.05 | G17: 66 | O17: 0.0947 | P17: =#REF!-O17 -> #REF!
A18: 46327 | B18: 0.423 | C18: 0.365 | D18: =B18-C18 -> 0.058 | E18: 0.499 | F18: =B18-E18 -> -0.076 | G18: 66 | O18: 0.0947 | P18: =#REF!-O18 -> #REF!
A19: 46357 | B19: 0.254 | C19: 0.229 | D19: =B19-C19 -> 0.025 | E19: 0.463 | F19: =B19-E19 -> -0.209 | G19: 66 | O19: 0.0947 | P19: =#REF!-O19 -> #REF!
A20: 46388 | B20: 0.377 | E20: 0.663 | F20: =B20-E20 -> -0.286 | G20: 66 | O20: 0.0947 | P20: =#REF!-O20 -> #REF!
A21: Average Room Rate
B22: OTB 14.08.26 | C22: OTB 29.07.26 | D22: Variance | E22: Last Year Actual | F22: OTB vs LY Actual | K22: as @ 8 Nov 2017 | L22: Variance 2018 vrs 2017 | M22: OTB @ 8 Nov 2018 | N22: LY Actal vs Target | O22: OTB 25.05.22 | P22: Variance OTB Current vs LY
A23: 46204 | B23: 3690.1087 | C23: 3663.0195 | D23: =B23-C23 -> 27.089167 | E23: 3855.9163 | F23: =B23-E23 -> -165.80761 | O23: 3241.55 | P23: =B23-O23 -> 448.5587 | Q23: =(B23-E23)/E23 -> -0.043000832
A24: 46235 | B24: 3734.5484 | C24: 3737.9471 | D24: =B24-C24 -> -3.3987453 | E24: 3465.6561 | F24: =B24-E24 -> 268.89227 | O24: 3241.55 | P24: =B24-O24 -> 492.99838
A25: 46266 | B25: 5346.8452 | C25: 5469.9515 | D25: =B25-C25 -> -123.10629 | E25: 3509.6309 | F25: =B25-E25 -> 1837.2143 | O25: 3241.55 | P25: =B25-O25 -> 2105.2952
A26: 46296 | B26: 3648.33 | C26: 4113.7721 | D26: =B26-C26 -> -465.44207 | E26: 4100.8104 | F26: =B26-E26 -> -452.48043 | O26: 3241.55 | P26: =B26-O26 -> 406.77999
A27: 46327 | B27: 5914.6391 | C27: 5664.4298 | D27: =B27-C27 -> 250.20934 | E27: 5483.9664 | F27: =B27-E27 -> 430.67274 | O27: 3241.55 | P27: =B27-O27 -> 2673.0891
A28: 46357 | B28: 5619.0955 | C28: 5566.1349 | D28: =B28-C28 -> 52.960644 | E28: 5852.8707 | F28: =B28-E28 -> -233.77519 | O28: 3241.55 | P28: =B28-O28 -> 2377.5455
A29: 46388 | B29: 5406 | E29: 5780.3197 | F29: =B29-E29 -> -374.31967 | O29: 3241.55 | P29: =B29-O29 -> 2164.45
A30: RevPAR
B31: OTB 14.08.26 | C31: OTB 29.07.26 | D31: Variance | E31: Last Year Actual | F31: OTB vs LY Actual | K31: as @ 8 Nov 2017 | L31: Variance 2018 vrs 2017 | M31: OTB @ 8 Nov 2018 | N31: LY Actal vs Target
A32: 46204 | B32: =B4/931 -> 467.70443 | C32: =C4/931 -> 464.271 | D32: =B32-C32 -> 3.4334283 | E32: =E4/961 -> 898.77758 | F32: =B32-E32 -> -431.07315
A33: 46235 | B33: =B5/931 -> 377.06504 | C33: =C5/931 -> 349.30333 | D33: =B33-C33 -> 27.761706 | E33: =E4/961 -> 898.77758 | F33: =B33-E33 -> -521.71254
A34: 46266 | B34: =B6/930 -> 1903.017 | C34: =C6/930 -> 1905.6605 | D34: =B34-C34 -> -2.6435718 | E34: =E6/930 -> 796.2711 | F34: =B34-E34 -> 1106.7459
A35: 46296 | B35: =B7/930 -> 1231.8017 | C35: =C7/930 -> 1207.5912 | D35: =B35-C35 -> 24.210584 | E35: =E7/930 -> 1816.7031 | F35: =B35-E35 -> -584.90137
A36: 46327 | B36: =B8/930 -> 2499.412 | C36: =C8/930 -> 2064.776 | D36: =B36-C36 -> 434.636 | E36: =E8/930 -> 2677.1191 | F36: =B36-E36 -> -177.70706
A37: 46357 | B37: =B9/930 -> 1474.2573 | C37: =C9/930 -> 1316.7201 | D37: =B37-C37 -> 157.53724 | E37: =E9/930 -> 2769.1001 | F37: =B37-E37 -> -1294.8428
A38: 46388 | B38: =B10/930 -> 2104.0914 | E38: =E10/930 -> 3816.2541 | F38: =B38-E38 -> -1712.1627

Sheet Historical Stats
A1: Revenue | B1: 2015 | C1: 2016 | D1: 2017 | E1: 2018 | F1: 2019 | G1: 2020 | H1: 2021 | I1: 2022 | J1: 2023 | K1: 2024 | L1: 2024 vs 2023 | M1: 2025 | N1: 2025 vs 2024 | O1: 2026 | P1: 2026 vs 2025
A2: Jan | B2: 1718793 | C2: 2023712 | D2: 2418238 | E2: 1623338 | F2: 1207727 | G2: 1522489 | H2: 72956 | I2: 659046 | J2: 2498047 | K2: 2485056 | L2: =K2-J2 -> -12991 | M2: 3204276 | N2: =M2-K2 -> 719220 | O2: 3549116.3 | P2: =O2-M2 -> 344840.28
A3: Feb | B3: 1765442 | C3: 1975466 | D3: 2216803 | E3: 2361566 | F3: 1612636 | G3: 1444683 | H3: 83348 | I3: 840294 | J3: 2499745 | K3: 3228558 | L3: =K3-J3 -> 728813 | M3: 2887163 | N3: =M3-K3 -> -341395 | O3: 3704860.7 | P3: =O3-M3 -> 817697.68
A4: Mar | B4: 1471651 | C4: 1659573 | D4: 1463345 | E4: 1408186 | F4: 1175922 | G4: 602778 | H4: 277529 | I4: 1467641 | J4: 1749406 | K4: 2361474 | L4: =K4-J4 -> 612068 | M4: 2027095 | N4: =M4-K4 -> -334379 | O4: 2617605.3 | P4: =O4-M4 -> 590510.31
A5: Apr | B5: 824985 | C5: 968707 | D5: 1008032 | E5: 728074 | F5: 613675 | G5: 0 | H5: 224332 | I5: 574007 | J5: 1086555 | K5: 1265502 | L5: =K5-J5 -> 178947 | M5: 907467 | N5: =M5-K5 -> -358035 | O5: 1256934.5 | P5: =O5-M5 -> 349467.46
A6: May | B6: 459536 | C6: 618319 | D6: 565371 | E6: 550572 | F6: 375263 | G6: 0 | H6: 219470 | I6: 807859 | J6: 654864 | K6: 1103983 | L6: =K6-J6 -> 449119 | M6: 924687 | N6: =M6-K6 -> -179296 | O6: 1047829.8 | P6: =O6-M6 -> 123142.77
A7: Jun | B7: 214357 | C7: 242401 | D7: 74892 | E7: 17834 | F7: 0 | G7: 0 | H7: 110446 | I7: 512847 | J7: 696645 | K7: 563280 | L7: =K7-J7 -> -133365 | M7: 110096.24 | N7: =M7-K7 -> -453183.76 | O7: 156811.45 | P7: =O7-M7 -> 46715.209
A8: Jul | B8: 332063 | C8: 531416 | D8: 374229 | E8: 454148 | F8: 153553 | G8: 0 | H8: 9730 | I8: 307176 | J8: 494973 | K8: 312573 | L8: =K8-J8 -> -182400 | M8: 791881 | N8: =M8-K8 -> 479308 | O8: 435432.83 | P8: =O8-M8 -> -356448.17
A9: Aug | B9: 537492 | C9: 623992 | D9: 570476 | E9: 599899 | F9: 208432 | G9: 97630 | H9: 124240 | I9: 683405 | J9: 915373 | K9: 679553 | L9: =K9-J9 -> -235820 | M9: 727788 | N9: =M9-K9 -> 48235 | P9: =O9-M9 -> -727788
A10: Sept | B10: 620453 | C10: 742639 | D10: 862336 | E10: 632926 | F10: 447850 | G10: 91121 | H10: 166491 | I10: 533400 | J10: 1119922 | K10: 731645 | L10: =K10-J10 -> -388277 | M10: 740532 | N10: =M10-K10 -> 8887 | P10: =O10-M10 -> -740532
A11: Oct | B11: 620453 | C11: 1265295 | D11: 1190523 | E11: 1026027 | F11: 702864 | G11: 23158 | H11: 417374 | I11: 888602 | K11: 1449720 | L11: =K11-J11 -> 1449720 | M11: 1689533.9 | N11: =M11-K11 -> 239813.9 | P11: =O11-M11 -> -1689533.9
A12: Nov | B12: 1690415 | C12: 2330335 | D12: 2072040 | E12: 1420642 | F12: 985451 | G12: 194846 | H12: 896516 | I12: 1295261 | J12: 2266072 | K12: 2219563 | L12: =K12-J12 -> -46509 | M12: 2476242 | N12: =M12-K12 -> 256679 | P12: =O12-M12 -> -2476242
A13: Dec | B13: 1556105 | C13: 1772437 | D13: 1870761 | E13: 1217273 | F13: 1115715 | G13: 101357 | H13: 545030 | I13: 2355614 | J13: 2209046 | K13: 2918132 | L13: =K13-J13 -> 709086 | M13: 2575263.1 | N13: =M13-K13 -> -342868.88 | P13: =O13-M13 -> -2575263.1
A14: TOTAL | B14: =SUM(B2:B13) -> 11811745 | C14: =SUM(C2:C13) -> 14754292 | D14: =SUM(D2:D13) -> 14687046 | E14: =SUM(E2:E13) -> 12040485 | F14: =SUM(F2:F13) -> 8599088 | G14: =SUM(G2:G13) -> 4078062 | H14: =SUM(H2:H13) -> 3147462 | I14: =SUM(I2:I13) -> 10925152 | ... K14: =SUM(K2:K13) -> 19319039 | L14: =K14-J14 -> 3128391 | M14: =SUM(M2:M13) -> 19062024 | N14: =M14-K14 -> -257014.74 | O14: =SUM(O2:O13) -> 12768591 | P14: =O14-M14 -> -6293433.5
A15: Occupancy | B15: 2015 | C15: 2016 | D15: 2017 | E15: 2018 | F15: 2019 | G15: 2020 | H15: 2021 | I15: 2022 | J15: 2023 | K15: 2024 | L15: 2024 vs 2023 | M15: 2025 | N15: 2025 vs 2024 | O15: 2026 | P15: 2026 vs 2025
A16: Jan | B16: 0.7614 | C16: 0.7192 | D16: 0.7353 | E16: 0.5209 | F16: 0.3927 | G16: 0.481 | H16: 0.0387 | I16: 0.2169 | J16: 0.5551 | K16: 0.5203 | L16: =K16-J16 -> -0.0348 | M16: 0.589 | N16: =M16-K16 -> 0.0687 | O16: 0.6543 | P16: =O16-M16 -> 0.0653
A17: Feb | B17: 0.861 | C17: 0.7919 | D17: 0.815 | E17: 0.7672 | F17: 0.5218 | G17: 0.4826 | H17: 0.033 | I17: 0.27 | J17: 0.6778 | K17: 0.7041 | L17: =K17-J17 -> 0.0263 | M17: 0.6509 | N17: =M17-K17 -> -0.0532 | O17: 0.7405 | P17: =O17-M17 -> 0.0896
A18: Mar | B18: 0.7459 | C18: 0.6601 | D18: 0.5558 | E18: 0.4968 | F18: 0.4215 | G18: 0.3579 | H18: 0.1181 | I18: 0.5366 | J18: 0.5665 | K18: 0.5702 | L18: =K18-J18 -> 0.0037 | M18: 0.4745 | N18: =M18-K18 -> -0.0957 | O18: 0.5629 | P18: =O18-M18 -> 0.0884
A19: Apr | B19: 0.6369 | C19: 0.6059 | D19: 0.4583 | E19: 0.3829 | F19: 0.3196 | G19: 0 | H19: 0.103 | I19: 0.207 | J19: 0.4155 | K19: 0.3473 | L19: =K19-J19 -> -0.0682 | M19: 0.229 | N19: =M19-K19 -> -0.1183 | O19: 0.3151 | P19: =O19-M19 -> 0.0861
A20: May | B20: 0.4011 | C20: 0.4182 | D20: 0.3017 | E20: 0.2756 | F20: 0.2312 | G20: 0 | H20: 0.1065 | I20: 0.2994 | J20: 0.3777 | K20: 0.3392 | L20: =K20-J20 -> -0.0385 | M20: 0.2633 | N20: =M20-K20 -> -0.0759 | O20: 0.2868 | P20: =O20-M20 -> 0.0235
A21: Jun | B21: 0.228 | C21: 0.2401 | D21: 0.4266 | E21: 0.0114 | F21: 0 | G21: 0 | H21: 0.0536 | I21: 0.1914 | J21: 0.3695 | K21: 0.19 | L21: =K21-J21 -> -0.1795 | M21: 0.0495 | N21: =M21-K21 -> -0.1405 | O21: 0.0528 | P21: =O21-M21 -> 0.0033
A22: Jul | B22: 0.2153 | C22: 0.3753 | D22: 0.2899 | E22: 0.1927 | F22: 0.161 | G22: 0 | H22: 0.0258 | I22: 0.3899 | J22: 0.2479 | K22: 0.107 | L22: =K22-J22 -> -0.1409 | M22: 0.223 | N22: =M22-K22 -> 0.116 | O22: 0.1238 | P22: =O22-M22 -> -0.0992
A23: Aug | B23: 0.4023 | C23: 0.3521 | D23: 0.3392 | E23: 0.3238 | F23: 0.2301 | G23: 1 | H23: 0.088 | I23: 0.4005 | J23: 0.4811 | K23: 0.2237 | L23: =K23-J23 -> -0.2574 | M23: 0.229 | N23: =M23-K23 -> 0.0053 | P23: =O23-M23 -> -0.229
A24: Sept | B24: 0.439 | C24: 0.4562 | D24: 0.485 | E24: 0.3278 | F24: 0.3369 | G24: 1 | H24: 0.0704 | I24: 0.2268 | J24: 0.4116 | K24: 0.227 | L24: =K24-J24 -> -0.1846 | M24: 0.2484 | N24: =M24-K24 -> 0.0214 | P24: =O24-M24 -> -0.2484
A25: Oct | B25: 0.439 | C25: 0.6685 | D25: 0.5691 | E25: 0.4905 | F25: 0.442 | G25: 0.0909 | H25: 0.1899 | I25: 0.2836 | K25: 0.3673 | L25: =K25-J25 -> 0.3673 | M25: 0.439 | N25: =M25-K25 -> 0.0717 | P25: =O25-M25 -> -0.439
A26: Nov | B26: 0.7596 | C26: 0.826 | D26: 0.6709 | E26: 0.4587 | F26: 0.3701 | G26: 0.1099 | H26: 0.247 | I26: 0.3296 | J26: 0.5602 | K26: 0.4946 | L26: =K26-J26 -> -0.0656 | M26: 0.489 | N26: =M26-K26 -> -0.0056 | P26: =O26-M26 -> -0.489
A27: Dec | B27: 0.5898 | C27: 0.6107 | D27: 0.5154 | E27: 0.3499 | F27: 0.364 | G27: 0.0474 | H27: 0.1513 | I27: 0.5363 | J27: 0.4964 | K27: 0.5328 | L27: =K27-J27 -> 0.0364 | M27: 0.4632 | N27: =M27-K27 -> -0.0696 | P27: =O27-M27 -> -0.4632
A28: TOTAL | B28: =SUM(B16:B27)/12 -> 0.53994167 | C28: =SUM(C16:C27)/12 -> 0.56035 | D28: =SUM(D16:D27)/12 -> 0.51351667 | E28: =SUM(E16:E27)/12 -> 0.38318333 | F28: =SUM(F16:F27)/12 -> 0.31590833 | G28: =SUM(G16:G27)/12 -> 0.297475 | H28: =SUM(H16:H27)/12 -> 0.10210833 | I28: =SUM(I16:I27)/12 -> 0.324 | J28: =SUM(J16:J27)/11 -> 0.46902727 | K28: =SUM(K16:K27)/12 -> 0.38529167 | L28: =K28-J28 -> -0.083735606 | M28: =SUM(M16:M27)/12 -> 0.36231667 | N28: =M28-K28 -> -0.022975 | O28: =SUM(O16:O27)/6 -> 0.45603333 | P28: =O28-M28 -> 0.093716667
A29: ADR | B29: 2015 | C29: 2016 | D29: 2017 | E29: 2018 | F29: 2019 | G29: 2020 | H29: 2021 | I29: 2022 | J29: 2023 | K29: 2024 | L29: 2024 vs 2023 | M29: 2025 | N29: 2025 vs 2024 | O29: 2026 | P29: 2026 vs 2025
A30: Jan | B30: 2516 | C30: 2687 | D30: 3076 | E30: 2956 | F30: 2960 | G30: 3346 | H30: 2026 | I30: 3414 | J30: 4722 | K30: 4970 | L30: =K30-J30 -> 248 | M30: 5661.27 | N30: =M30-K30 -> 691.27 | O30: 5780.3197 | P30: =O30-M30 -> 119.04967
A31: Feb | B31: 2272 | C31: 2460 | D31: 2795 | E31: 3157 | F31: 3366 | G31: 3602 | H31: 2976 | I31: 3718 | J31: 4385 | K31: 5100 | L31: =K31-J31 -> 715 | M31: 5110.02 | N31: =M31-K31 -> 10.02 | O31: 5806.9917 | P31: =O31-M31 -> 696.97166
A32: Mar | B32: 2180 | C32: 2469 | D32: 2426 | E32: 2612 | F32: 2806 | G32: 3107 | H32: 2477 | I32: 3641 | J32: 3450 | K32: 4309 | L32: =K32-J32 -> 859 | M32: 4445.39 | N32: =M32-K32 -> 136.39 | O32: 4874.4978 | P32: =O32-M32 -> 429.10779
A33: Apr | B33: 1465 | C33: 1800 | D33: 2108 | E33: 1811 | F33: 1923 | G33: 0 | H33: 2412 | I33: 3224 | J33: 2851 | K33: 3918 | L33: =K33-J33 -> 1067 | M33: 4260.41 | N33: =M33-K33 -> 342.41 | O33: 4290 | P33: =O33-M33 -> 29.59
A34: May | B34: 1272 | C34: 1530 | D34: 1728 | E34: 1841 | F34: 1653 | G34: 0 | H34: 2172 | I34: 2864 | J34: 1804 | K34: 3386 | L34: =K34-J34 -> 1582 | M34: 3654.89 | N34: =M34-K34 -> 268.89 | O34: 3838 | P34: =O34-M34 -> 183.11
A35: Jun | B35: 1134 | C35: 1731 | D35: 1227 | E35: 1486 | F35: 0 | G35: 0 | H35: 2300 | I35: 2897 | J35: 2067 | K35: 3182.38 | L35: =K35-J35 -> 1115.38 | M35: 2393.3966 | N35: =M35-K35 -> -788.9834 | O35: 3200.2337 | P35: =O35-M35 -> 806.83712
A36: Jul | B36: 1573 | C36: 1312 | D36: 1218 | E36: 2193 | F36: 1476 | G36: 0 | H36: 2432 | I36: 2477 | J36: 2115 | K36: 3034.69 | L36: =K36-J36 -> 919.69 | M36: 3535.19 | N36: =M36-K36 -> 500.5 | O36: 3690.1087 | P36: =O36-M36 -> 154.9187
A37: Aug | B37: 1273 | C37: 1633 | D37: 1728 | E37: 1759 | F37: 1680 | G37: 2169 | H37: 1592 | I37: 2648 | J37: 2878 | K37: 3160.71 | L37: =K37-J37 -> 282.71 | M37: 3465.66 | N37: =M37-K37 -> 304.95 | P37: =O37-M37 -> -3465.66
A38: Sept | B38: 1449 | C38: 1550 | D38: 1774 | E38: 1872 | F38: 1777 | G38: 2169 | H38: 2729 | I38: 2540 | J38: 3209 | K38: 3167.29 | L38: =K38-J38 -> -41.71 | M38: 3509.63 | N38: =M38-K38 -> 342.34 | P38: =O38-M38 -> -3509.63
A39: Oct | B39: 1449 | C39: 1757 | D39: 1980 | E39: 1976 | F39: 1920 | G39: 1929 | H39: 2358 | I39: 3340 | K39: 4106.86 | L39: =K39-J39 -> 4106.86 | M39: 4100.81 | N39: =M39-K39 -> -6.05 | P39: =O39-M39 -> -4100.81
A40: Nov | B40: 2184 | C40: 2596 | D40: 3033 | E40: 3009 | F40: 2941 | G40: 2706 | H40: 4020 | I40: 4375 | J40: 4349 | K40: 4825.14 | L40: =K40-J40 -> 476.14 | M40: 2662.6258 | N40: =M40-K40 -> -2162.5142 | P40: =O40-M40 -> -2662.6258
...

Sheet Sheet4
A1: Booking reference | B1: Guest names | C1: Check-in | D1: Check-out | E1: Channel | F1: Affiliated Channel | G1: Referral | H1: Room | I1: Booked-on date | J1: Modified-on date | K1: Cancelled-on date | L1: Booking status | M1: Occupancy | N1: Total price | O1: Connectivity status | P1: Connectivity last sent at | Q1: Guest title | R1: Guest name | S1: Guest first name | T1: Guest last name | U1: Guest address | V1: Guest address2 | W1: Guest state | X1: Guest postcode | Y1: Guest country | Z1: Guest email | AA1: Guest phone | AB1: GDPR consent | AC1: GDPR consent date | AD1: Promo code
A2: 567284087 | B2: Victoria Moya | C2: 45889 | D2: 45894 | E2: Agoda | F2: Private Sale | H2: 1 x Legacy Suite | I2: 45880.406 | K2: 45880.445 | L2: Cancelled | M2: 2 - 0 - 0 | N2: ZAR 21627.55 | O2: Delivered | P2: 45880.447 | Q2: -
A3: 1970859923 | B3: Janis Oberbrunner | C3: 46033 | D3: 46036 | E3: Agoda | F3: Retail | H3: 1 x Terrace Suite | I3: 46029.471 | K3: 46034.328 | L3: Cancelled | M3: 2 - 0 - 0 | N3: ZAR 42498.00 | O3: Delivered | P3: 46034.334 | Q3: -
A4: 1972277093 | B4: Lauriane Stehr | C4: 46037 | D4: 46041 | E4: Agoda | F4: Retail | H4: 1 x Terrace Suite | I4: 46033.712 | K4: 46038.374 | L4: Cancelled | M4: 2 - 0 - 0 | N4: ZAR 56664.00 | O4: Delivered | P4: 46038.377 | Q4: -
A5: 620361463 | B5: TEST TEST | C5: 46072 | D5: 46073 | E5: Agoda | F5: Private Sale | H5: 1 x Heritage Suite | I5: 46045.447 | K5: 46045.449 | L5: Cancelled | M5: 1 - 0 - 0 | N5: ZAR 8921.80 | O5: Delivered | P5: 46045.456 | Q5: -
A6: 1 x Terrace Suite - Grande Reserve Experience" | B6: 45822.554 | E6: Booked | F6: 4 - 0 - 0 | G6: ZAR 10340.00 | H6: Delivered | I6: 45822.56 | K6: Babalwa Nyoka | L6: Babalwa | M6: Nyoka | N6: Babalwa.nyoka@gmail.com | O6: 90 Ashley Drive | Q6: 3610 | R6: South Africa | S6: Babalwa.nyoka@gmail.com | T6: 728774036 | U6: FALSE | V6: 2025-06-14T00:00:00.000Z
A7: 1 x Terrace Suite - Book Direct save 15%" | B7: 45832.828 | E7: Booked | F7: 4 - 0 - 0 | G7: ZAR 44409.00 | H7: Delivered | I7: 45832.834 | K7: Mlungisi Kwini | L7: Mlungisi | M7: Kwini | N7: 204 Anderson Avenue | O7: Northcliff | Q7: 2195 | R7: South Africa | S7: mlungisi.kwini@lukhanyo.com | T7: 823301640 | U7: TRUE | V7: 2025-06-24T00:00:00.000Z
A8: 1 x Terrace Suite - Book Direct save 15%" | B8: 45832.839 | E8: Booked | F8: 4 - 0 - 0 | G8: ZAR 10766.00 | H8: Delivered | I8: 45832.841 | K8: Mlungisi Kwini | L8: Mlungisi | M8: Kwini | N8: 204 Anderson Avenue | O8: Northcliff | Q8: 2195 | R8: South Africa | S8: mlungisi.kwini@lukhanyo.com | T8: 823301640 | U8: TRUE | V8: 2025-06-24T00:00:00.000Z
A9: 1 x Heritage Suite - Book Direct save 15%" | B9: 45834.418 | E9: Booked | F9: 4 - 0 - 0 | G9: ZAR 15202.00 | H9: Delivered | I9: 45834.421 | K9: Julian Naik | L9: Julian | M9: Naik | N9: 15 Rimal, 334 Bryanston Drive | Q9: 2192 | R9: South Africa | S9: julian@spiritsandbubbles.co.za | T9: 27825626099 | U9: FALSE | V9: 2025-06-26T00:00:00.000Z
A10: 1 x Heritage Suite - Book Direct save 15%" | B10: 45876.872 | E10: Booked | F10: 36528 | G10: ZAR 25934.00 | H10: Delivered | I10: 45876.876 | K10: Morten Sommerfeldt | L10: Morten | M10: Sommerfeldt | N10: Prins Constantins Vej 5 | P10: Copenhagen | Q10: 2000 | R10: Denmark | S10: morten.westergaard@gmail.com | T10: 4528558665 | U10: FALSE | V10: 2025-08-07T00:00:00.000Z
A11: 1 x Studio - General - Breakfast included - Domestic" | B11: 45939.41 | E11: Booked | F11: 13 - 0 - 0 | G11: ZAR 77246.46 | H11: Delivered | I11: 45939.415 | J11: -
A12: 1 x Studio - Non-refundable - Breakfast included - Non-refundable" | B12: 45953.887 | E12: Booked | F12: 36559 | G12: ZAR 27246.80 | H12: Delivered | I12: 45953.889 | J12: -
A13: 1 x Legacy Room - General - Breakfast included - United Kingdom" | B13: 45974.642 | E13: Booked | F13: 3 - 0 - 0 | G13: ZAR 49183.20 | H13: Delivered | I13: 45974.647 | J13: -
A14: 1 x Legacy Room - General - Breakfast included - European Economic Area" | B14: 45978.65 | E14: Booked | F14: 2 - 0 - 0 | G14: ZAR 109296.00 | H14: Delivered | I14: 45978.655 | J14: -
A15: 1 x Garden Suite - Partially refundable - Breakfast included - Flexible 5 days" | B15: 46009.064 | E15: Booked | F15: 4 - 0 - 0 | G15: ZAR 20319.62 | H15: Delivered | I15: 46009.068 | J15: -
A16: 1 x Legacy Room - Non-refundable - Breakfast included - Non-refundable" | B16: 46024.515 | E16: Booked | F16: 36560 | G16: ZAR 9338.95 | H16: Delivered | I16: 46024.52 | J16: -
A17: 1 x Terrace Suite - General - Breakfast included" | B17: 46037.413 | E17: Booked | F17: 4 - 0 - 0 | G17: ZAR 40373.10 | H17: Delivered | I17: 46037.417 | J17: -
A18: 1 x Heritage Suite - Book Direct save 15%" | B18: 46037.868 | E18: Booked | F18: 4 - 0 - 0 | G18: ZAR 25338.00 | H18: Delivered | I18: 46037.872 | K18: Valery Borisov | L18: Valery | M18: Borisov | N18: 48B Regent‚Äôs Park Road | Q18: NW17SX | R18: United Kingdom | S18: borisovvn@yahoo.com | T18: 447586328973 | U18: FALSE | V18: 2026-01-15T00:00:00.000Z
A19: 1 x Terrace Suite - General - Breakfast included" | B19: 46044.723 | E19: Booked | F19: 3 - 0 - 0 | G19: ZAR 54648.00 | H19: Delivered | I19: 46044.726 | J19: -
A20: 5693386589 | B20: Frank Tippmann, | C20: 45939 | D20: 45945 | E20: Booking.com | F20: BDC | H20: 1 x Duplex Suite - General - Breakfast included - European Economic Area | I20: 45814.54 | L20: Booked | M20: 36527 | N20: ZAR 34228.80 | O20: Delivered | P20: 45814.544 | Q20: -
A21: 6794248259 | B21: Luke Cassell | C21: 45819 | D21: 45820 | E21: Booking.com | F21: BDC | H21: 1 x Studio - General - Breakfast included - Getaway Deal | I21: 45816.595 | L21: Booked | M21: 2 - 0 - 0 | N21: ZAR 3656.70 | O21: Delivered | P21: 45816.6 | Q21: -
A22: 6640931778 | B22: Stephen Rich | C22: 46073 | D22: 46075 | E22: Booking.com | F22: BDC | H22: 1 x Studio - General - Breakfast included - Domestic | I22: 45818.016 | K22: 46037.579 | L22: Cancelled | M22: 2 - 0 - 0 | N22: ZAR 15183.00 | O22: Delivered | P22: 46037.582 | Q22: -
A23: 5655435537 | B23: Ivo Schepers | C23: 45972 | D23: 45973 | E23: Booking.com | F23: BDC | H23: 1 x Studio - General - Breakfast included - European Economic Area | I23: 45819.375 | L23: Booked | M23: 2 - 0 - 0 | N23: ZAR 6832.80 | O23: Delivered | P23: 45819.379 | Q23: -
A24: 5665130610 | B24: Iain Burgess | C24: 45944 | D24: 45946 | E24: Booking.com | F24: BDC | H24: 1 x Studio - General - Breakfast included - United Kingdom | I24: 45821.444 | L24: Booked | M24: 2 - 0 - 0 | N24: ZAR 10578.60 | O24: Delivered | P24: 45821.447 | Q24: -
A25: 5357215519 | B25: Sfiso Mazibuko | C25: 45828 | D25: 45830 | E25: Booking.com | F25: BDC | H25: 1 x Studio - General - Breakfast included - Getaway Deal | I25: 45821.943 | L25: Booked | M25: 2 - 0 - 0 | N25: ZAR 7770.70 | O25: Delivered | P25: 45821.946 | Q25: -
A26: 5686314473 | B26: Helmut Richter | C26: 46018 | D26: 46021 | E26: Booking.com | F26: BDC | H26: 1 x Studio - General - Breakfast included - European Economic Area | I26: 45822.487 | K26: 45824.368 | L26: Cancelled | M26: 2 - 0 - 0 | N26: ZAR 18979.20 | O26: Delivered | P26: 45824.371 | Q26: -
A27: 5955611653 | B27: Sandra McDiarmid | C27: 46012 | D27: 46018 | E27: Booking.com | F27: BDC | H27: 1 x Studio - General - Breakfast included - Domestic | I27: 45823.668 | K27: 45824.605 | L27: Cancelled | M27: 2 - 0 - 0 | N27: ZAR 39476.70 | O27: Delivered | P27: 45824.611 | Q27: -
A28: 6755179000 | B28: Theo Basson, Christine Basson | C28: 45870 | D28: 45872 | E28: Booking.com | F28: BDC | H28: 2 x Studio - General - Breakfast included - Getaway Deal | I28: 45824.414 | L28: Booked | M28: 4 - 0 - 0 | N28: ZAR 18285.20 | O28: Delivered | P28: 45824.418 | Q28: -
A29: 5700688008 | B29: Kebonye Aubrey Kgwaadira | C29: 45826 | D29: 45830 | E29: Booking.com | F29: BDC | H29: 1 x Suite with Terrace - General - Breakfast included - Getaway Deal | I29: 45825.582 | L29: Booked | M29: 2 - 0 - 0 | N29: ZAR 21753.20 | O29: Delivered | P29: 45825.587 | Q29: -
A30: 5899806030 | B30: Gil Givoni | C30: 45907 | D30: 45911 | E30: Booking.com | F30: BDC | H30: 1 x Studio - General - Breakfast included - Getaway Deal | I30: 45833.882 | L30: Booked | M30: 1 - 0 - 0 | N30: ZAR 18316.65 | O30: Delivered | P30: 45833.886 | Q30: -
A31: 6259891503 | B31: Fiona Reynolds | C31: 46006 | D31: 46008 | E31: Booking.com | F31: BDC | H31: 2 x Studio - General - Breakfast included - Mobile(App) Rate | I31: 45834.336 | K31: 45973.44 | L31: Cancelled | M31: 4 - 0 - 0 | N31: ZAR 25812.00 | O31: Delivered | P31: 45973.444 | Q31: -
A32: 5583792421 | B32: Lara Klebor | C32: 46024 | D32: 46026 | E32: Booking.com | F32: BDC | H32: 3 x Studio - General - Breakfast included - European Economic Area | I32: 45835.461 | L32: Booked | M32: 5 - 0 - 0 | N32: ZAR 38718.00 | O32: Delivered | P32: 45835.464 | Q32: -
A33: 6405365691 | B33: Roland Vogt | C33: 45918 | D33: 45920 | E33: Booking.com | F33: BDC | H33: 1 x Duplex Suite - General - Breakfast included - Getaway Deal | I33: 45835.907 | L33: Booked | M33: 2 - 0 - 0 | N33: ZAR 10775.45 | O33: Delivered | P33: 45835.912 | Q33: -
A34: 5426292376 | B34: Holly Littlewood | C34: 45953 | D34: 45956 | E34: Booking.com | F34: BDC | H34: 1 x Duplex Suite - General - Breakfast included - United Kingdom | I34: 45837.914 | L34: Booked | M34: 2 - 0 - 0 | N34: ZAR 17115.30 | O34: Delivered | P34: 45837.917 | Q34: -
A35: 6981190735 | B35: Helge Weber | C35: 46011 | D35: 46018 | E35: Booking.com | F35: BDC | H35: 2 x Studio - General - Breakfast included - European Economic Area | I35: 45838.371 | L35: Booked | M35: 3 - 0 - 0 | N35: ZAR 94136.40 | O35: Delivered | P35: 45838.376 | Q35: -
A36: 6798414745 | B36: sophia korduner | C36: 46012 | D36: 46013 | E36: Booking.com | F36: BDC | H36: 1 x Studio - General - Breakfast included - European Economic Area | I36: 45838.918 | K36: 45948.397 | L36: Cancelled | M36: 2 - 0 - 0 | N36: ZAR 6832.80 | O36: Delivered | P36: 45948.4 | Q36: -
A37: 6463303278 | B37: Sabine Amelung-Hildebrand | C37: 46036 | D37: 46038 | E37: Booking.com | F37: BDC | H37: 1 x Suite with Terrace - General - Breakfast included - European Economic Area | I37: 45840.061 | J37: 45840.997 | K37: 46004.914 | L37: Cancelled | M37: 2 - 0 - 0 | N37: ZAR 21249.00 | O37: Delivered | P37: 46004.917 | Q37: -
A38: 6114200722 | B38: HANNA KALIADA | C38: 45977 | D38: 45979 | E38: Booking.com | F38: BDC | H38: 1 x Studio - General - Breakfast included - Mobile(App) Rate | I38: 45841.992 | K38: 45842.041 | L38: Cancelled | M38: 2 - 0 - 0 | N38: ZAR 15183.00 | O38: Delivered | P38: 45842.044 | Q38: -
A39: 6759759726 | B39: HANNA KALIADA | C39: 45977 | D39: 45980 | E39: Booking.com | F39: BDC | H39: 1 x Studio - General - Breakfast included - Mobile(App) Rate | I39: 45842.04 | K39: 45935.954 | L39: Cancelled | M39: 2 - 0 - 0 | N39: ZAR 22015.80 | O39: Delivered | P39: 45935.958 | Q39: -
A40: 5983995454 | B40: Krishnee Murugan, Rajendra Balmakhun | C40: 45847 | D40: 45848 | E40: Booking.com | F40: BDC | H40: 1 x Studio - General - Breakfast included - Getaway Deal | I40: 45843.489 | L40: Booked | M40: 1 - 0 - 0 | N40: ZAR 4114.00 | O40: Delivered | P40: 45843.491 | Q40: -
...

Sheet 24.08.2020
A1: Devonvale Revenue Report 6 August 2020
B2: OTB 2020/2021 @ 24 Aug 2020 | C2: OTB 2020/2021 @ 06 August 2020 | D2: Variance 24 Aug vs 6 Aug | E2: Actual 2019/2020 | F2: 24 Aug 2020 vs 2019/2020 | G2: Actual 2018/2019 | H2: Variance last 7 days | I2: as @ 03 June 2014 | J2: 2019/2020 vs 2018/2019 | K2: as @ 8 Nov 2017 | L2: Variance 2018 vrs 2017 | M2: OTB @ 8 Nov 2018 | N2: Actual 2017/2018 | O2: Variance last 7 days | P2: as @ 03 June 2014 | Q2: 2018/2019 vs 2017/18
A3: Mar | B3: 976369 | C3: 976369 | E3: 800133 | F3: =C3-#REF! -> #REF! | G3: =(#REF!-E3) -> #REF! | H3: =C3-I3 -> 815149 | I3: 161220 | J3: =C3-E3 -> 176236 | K3: 1191028 | N3: =(#REF!-L3) -> #REF! | O3: =K3-P3 -> 1029808 | P3: 161220 | Q3: =K3-L3 -> 1191028
