Workbook

Sheet OTB
A1: 55 on Main Guest House & Spa | 14 August 2026
B2: OTB @ 14 Aug 2026 | C2: OTB @ 31 Jul 2026 | D2: Variance | E2: Last Year Actual | F2: OTB vs LY | G2: Target (+10%) | H2: OTB vs Target | J2: OTB vs LY | K2: OTB vs Target
A3: Jul | B3: 121385.09 | C3: 121385.09 | D3: =B3-C3 -> 0 | E3: 176856 | F3: =B3-E3 -> -55470.91 | G3: =E3*1.1 -> 194541.6 | H3: =B3-G3 -> -73156.51 | J3: =(B3-E3)/E3 -> -0.31365014 | K3: =(B3-G3)/G3 -> -0.37604559
A4: Aug | B4: 56761.11 | C4: 20635.13 | D4: =B4-C4 -> 36125.98 | E4: 226583 | F4: =B4-E4 -> -169821.89 | G4: =E4*1.1 -> 249241.3 | H4: =B4-G4 -> -192480.19 | J4: =(B4-E4)/E4 -> -0.74949087 | K4: =(B4-G4)/G4 -> -0.77226443
A5: Sept | B5: 66051.82 | C5: 62151.82 | D5: =B5-C5 -> 3900 | E5: 247125.59 | F5: =B5-E5 -> -181073.77 | G5: =E5*1.1 -> 271838.14 | H5: =B5-G5 -> -205786.32 | J5: =(B5-E5)/E5 -> -0.73271962 | K5: =(B5-G5)/G5 -> -0.75701784
A6: Oct | B6: 3223.8 | C6: 3223.8 | D6: =B6-C6 -> 0 | E6: 311992.72 | F6: =B6-E6 -> -308768.92 | G6: =E6*1.1 -> 343191.99 | H6: =B6-G6 -> -339968.19 | J6: =(B6-E6)/E6 -> -0.98966707 | K6: =(B6-G6)/G6 -> -0.99060642
A7: Nov | B7: 44744.94 | C7: 4545.14 | D7: =B7-C7 -> 40199.8 | E7: 366638 | F7: =B7-E7 -> -321893.06 | G7: =E7*1.1 -> 403301.8 | H7: =B7-G7 -> -358556.86 | J7: =(B7-E7)/E7 -> -0.8779588 | K7: =(B7-G7)/G7 -> -0.88905346
A8: Dec | B8: 44744.94 | C8: 31244.94 | D8: =B8-C8 -> 13500 | E8: 385027.26 | F8: =B8-E8 -> -340282.32 | G8: =E8*1.1 -> 423529.99 | H8: =B8-G8 -> -378785.05 | J8: =(B8-E8)/E8 -> -0.88378761 | K8: =(B8-G8)/G8 -> -0.89435237
A9: 46388 | B9: 45743.94 | C9: 41243.94 | D9: =B9-C9 -> 4500 | E9: 394823.5 | F9: =B9-E9 -> -349079.56 | G9: =E9*1.1 -> 434305.85 | H9: =B9-G9 -> -388561.91 | J9: =(B9-E9)/E9 -> -0.88414079 | K9: =(B9-G9)/G9 -> -0.89467344
A10: TOTAL | B10: =SUM(B3:B9) -> 382655.64 | C10: =SUM(C3:C9) -> 284429.86 | D10: =SUM(D3:D9) -> 98225.78 | E10: =SUM(E3:E9) -> 2109046.1 | F10: =B10-E10 -> -1726390.4 | G10: =SUM(G3:G9) -> 2319950.7 | H10: =(B10-G10) -> -1937295 | J10: =(B10-E10)/E10 -> -0.81856459 | K10: =(B10-G10)/G10 -> -0.83505872
A11: Room Nights | G11: Occupancy
B12: OTB @ 14 Aug 2026 | C12: OTB @ 31 Jul 2026 | D12: Variance | E12: Last Year Actual | F12: OTB vs LY | G12: OTB @ 14 Aug 2026 | H12: OTB @ 31 Jul 2026 | I12: Variance | J12: Last Year Actual | K12: OTB vs LY
A13: Jul | B13: 114 | C13: 114 | D13: =B13-C13 -> 0 | E13: 190 | F13: =B13-E13 -> -76 | G13: =B13/465 -> 0.24516129 | H13: =C13/465 -> 0.24516129 | I13: =G13-H13 -> 0 | J13: =E13/465 -> 0.40860215 | K13: =G13-J13 -> -0.16344086 | M13: 15 Rooms
A14: Aug | B14: 52 | C14: 16 | D14: =B14-C14 -> 36 | E14: 225 | F14: =B14-E14 -> -173 | G14: =B14/465 -> 0.11182796 | H14: =C14/465 -> 0.034408602 | I14: =G14-H14 -> 0.077419355 | J14: =E14/465 -> 0.48387097 | K14: =G14-J14 -> -0.37204301 | M14: 28 = 420
A15: Sept | B15: 61 | C15: 58 | D15: =B15-C15 -> 3 | E15: 259 | F15: =B15-E15 -> -198 | G15: =B15/450 -> 0.13555556 | H15: =C15/450 -> 0.12888889 | I15: =G15-H15 -> 0.0066666667 | J15: =E15/450 -> 0.57555556 | K15: =G15-J15 -> -0.44 | M15: 29 = 435
A16: Oct | B16: 2 | C16: 2 | D16: =B16-C16 -> 0 | E16: 311 | F16: =B16-E16 -> -309 | G16: =B16/465 -> 0.0043010753 | H16: =C16/465 -> 0.0043010753 | I16: =G16-H16 -> 0 | J16: =E16/465 -> 0.6688172 | K16: =G16-J16 -> -0.66451613 | M16: 30 = 450
A17: Nov | B17: 23 | C17: 2 | D17: =B17-C17 -> 21 | E17: 387 | F17: =B17-E17 -> -364 | G17: =B17/450 -> 0.051111111 | H17: =C17/450 -> 0.0044444444 | I17: =G17-H17 -> 0.046666667 | J17: =E17/450 -> 0.86 | K17: =G17-J17 -> -0.80888889 | M17: 31 = 465
A18: Dec | B18: 23 | C18: 14 | D18: =B18-C18 -> 9 | E18: 299 | F18: =B18-E18 -> -276 | G18: =B18/465 -> 0.049462366 | H18: =C18/465 -> 0.030107527 | I18: =G18-H18 -> 0.019354839 | J18: =E18/465 -> 0.64301075 | K18: =G18-J18 -> -0.59354839
A19: 46388 | B19: 21 | C19: 18 | D19: =B19-C19 -> 3 | E19: 315 | F19: =B19-E19 -> -294 | G19: =B19/465 -> 0.04516129 | H19: =C19/465 -> 0.038709677 | I19: =G19-H19 -> 0.0064516129 | J19: =E19/465 -> 0.67741935 | K19: =G19-J19 -> -0.63225806
A20: ADR
B21: OTB @ 14 Aug 2026 | C21: OTB @ 31 Jul 2026 | D21: Variance | E21: Last Year Actual | F21: OTB vs LY
A22: Jul | B22: =B3/B13 -> 1064.7815 | C22: =C3/C13 -> 1064.7815 | D22: =B22-C22 -> 0 | E22: =E3/E13 -> 930.82105 | F22: =B22-E22 -> 133.96044 | G22: =(B22-E22)/E22 -> 0.14391643
A23: Aug | B23: =B4/B14 -> 1091.5598 | C23: =C4/C14 -> 1289.6956 | D23: =B23-C23 -> -198.13582 | E23: =E4/E14 -> 1007.0356 | F23: =B23-E23 -> 84.524252 | G23: =(B23-E23)/E23 -> 0.083933732
A24: Sept | B24: =B5/B15 -> 1082.8167 | C24: =C5/C15 -> 1071.5831 | D24: =B24-C24 -> 11.233618 | E24: =E5/E15 -> 954.15284 | F24: =B24-E24 -> 128.66388 | G24: =(B24-E24)/E24 -> 0.1348462
A25: Oct | B25: =B6/B16 -> 1611.9 | C25: =C6/C16 -> 1611.9 | D25: =B25-C25 -> 0 | E25: =E6/E16 -> 1003.192 | F25: =B25-E25 -> 608.70797 | G25: =(B25-E25)/E25 -> 0.60677115
A26: Nov | B26: =B7/B17 -> 1945.4322 | C26: =C7/C17 -> 2272.57 | D26: =B26-C26 -> -327.13783 | E26: =E7/E17 -> 947.38501 | F26: =B26-E26 -> 998.04716 | G26: =(B26-E26)/E26 -> 1.0534758
A27: Dec | B27: =B8/B18 -> 1945.4322 | C27: =C8/C18 -> 2231.7814 | D27: =B27-C27 -> -286.34925 | E27: =E8/E18 -> 1287.7166 | F27: =B27-E27 -> 657.71559 | G27: =(B27-E27)/E27 -> 0.51076113
A28: 46388 | B28: =B9/B19 -> 2178.2829 | C28: =C9/C19 -> 2291.33 | D28: =B28-C28 -> -113.04714 | E28: =E9/E19 -> 1253.4079 | F28: =B28-E28 -> 924.87492 | G28: =(B28-E28)/E28 -> 0.7378882

Sheet Sheet2
A1: Revenue
B2: OTB @ 30 Jun 2026 | C2: Pick-up @ 15 Jul 2026 | D2: Drop @ 15 Jul 2026
A3: Jun | B3: =IF(OTB!#REF!="","",OTB!#REF!) -> #REF! | C3: =IF(OTB!#REF!>0,OTB!#REF!,0) -> #REF! | D3: =IF(OTB!#REF!<0,ABS(OTB!#REF!),0) -> #REF!
A4: Jul | B4: =IF(OTB!B3="","",OTB!C3) -> 121385.09 | C4: =IF(OTB!D3>0,OTB!D3,0) -> 0 | D4: =IF(OTB!D3<0,ABS(OTB!D3),0) -> 0
A5: Aug | B5: =IF(OTB!B4="","",OTB!C4) -> 20635.13 | C5: =IF(OTB!D4>0,OTB!D4,0) -> 36125.98 | D5: =IF(OTB!D4<0,ABS(OTB!D4),0) -> 0
A6: Sept | B6: =IF(OTB!B5="","",OTB!C5) -> 62151.82 | C6: =IF(OTB!D5>0,OTB!D5,0) -> 3900 | D6: =IF(OTB!D5<0,ABS(OTB!D5),0) -> 0
A7: Oct | B7: =IF(OTB!B6="","",OTB!C6) -> 3223.8 | C7: =IF(OTB!D6>0,OTB!D6,0) -> 0 | D7: =IF(OTB!D6<0,ABS(OTB!D6),0) -> 0
A8: Nov | B8: =IF(OTB!B7="","",OTB!C7) -> 4545.14 | C8: =IF(OTB!D7>0,OTB!D7,0) -> 40199.8 | D8: =IF(OTB!D7<0,ABS(OTB!D7),0) -> 0
A9: Dec | B9: =IF(OTB!B9="","",OTB!C9) -> 41243.94 | C9: =IF(OTB!D9>0,OTB!D9,0) -> 4500 | D9: =IF(OTB!D9<0,ABS(OTB!D9),0) -> 0
C10: OTB @ 30 Jun 2026 | D10: Achieved @ 15 Jul 2026 | E10: Trailing @ 15 Jul 2026
A11: Jun | B11: LY | C11: =IF(OTB!#REF!="","",OTB!#REF!) -> #REF! | D11: =IF(OTB!#REF!>0,OTB!#REF!,0) -> #REF! | E11: =IF(OTB!#REF!<0,ABS(OTB!#REF!),0) -> #REF!
B12: Target | C12: =OTB!#REF! -> #REF! | D12: =IF(OTB!#REF!>0,OTB!#REF!,0) -> #REF! | E12: =IF(OTB!#REF!<0,ABS(OTB!#REF!),0) -> #REF!
A13: Jul | B13: LY | C13: =IF(OTB!B3="","",OTB!E3) -> 176856 | D13: =IF(OTB!F3>0,OTB!F3,0) -> 0 | E13: =IF(OTB!F3<0,ABS(OTB!F3),0) -> 55470.91
B14: Target | C14: =OTB!G3 -> 194541.6 | D14: =IF(OTB!H3>0,OTB!H3,0) -> 0 | E14: =IF(OTB!H3<0,ABS(OTB!H3),0) -> 73156.51
A15: Aug | B15: LY | C15: =IF(OTB!B4="","",OTB!E4) -> 226583 | D15: =IF(OTB!F4>0,OTB!F4,0) -> 0 | E15: =IF(OTB!F4<0,ABS(OTB!F4),0) -> 169821.89
B16: Target | C16: =OTB!G4 -> 249241.3 | D16: =IF(OTB!H4>0,OTB!H4,0) -> 0 | E16: =IF(OTB!H4<0,ABS(OTB!H4),0) -> 192480.19
A17: Sep | B17: LY | C17: =IF(OTB!B5="","",OTB!E5) -> 247125.59 | D17: =IF(OTB!F5>0,OTB!F5,0) -> 0 | E17: =IF(OTB!F5<0,ABS(OTB!F5),0) -> 181073.77
B18: Target | C18: =OTB!G5 -> 271838.14 | D18: =IF(OTB!H5>0,OTB!H5,0) -> 0 | E18: =IF(OTB!H5<0,ABS(OTB!H5),0) -> 205786.32
A19: Oct | B19: LY | C19: =IF(OTB!B6="","",OTB!E6) -> 311992.72 | D19: =IF(OTB!F6>0,OTB!F6,0) -> 0 | E19: =IF(OTB!F6<0,ABS(OTB!F6),0) -> 308768.92
B20: Target | C20: =OTB!G6 -> 343191.99 | D20: =IF(OTB!H6>0,OTB!H6,0) -> 0 | E20: =IF(OTB!H6<0,ABS(OTB!H6),0) -> 339968.19
A21: Nov | B21: LY | C21: =IF(OTB!B7="","",OTB!E7) -> 366638 | D21: =IF(OTB!F7>0,OTB!F7,0) -> 0 | E21: =IF(OTB!F7<0,ABS(OTB!F7),0) -> 321893.06
B22: Target | C22: =OTB!G7 -> 403301.8 | D22: =IF(OTB!H7>0,OTB!H7,0) -> 0 | E22: =IF(OTB!H7<0,ABS(OTB!H7),0) -> 358556.86
A23: Dec | B23: LY | C23: =IF(OTB!B9="","",OTB!E9) -> 394823.5 | D23: =IF(OTB!F9>0,OTB!F9,0) -> 0 | E23: =IF(OTB!F9<0,ABS(OTB!F9),0) -> 349079.56
B24: Target | C24: =OTB!G9 -> 434305.85 | D24: =IF(OTB!H9>0,OTB!H9,0) -> 0 | E24: =IF(OTB!H9<0,ABS(OTB!H9),0) -> 388561.91
A25: Occupancy %
C26: OTB @ 15 Jul 2026 | D26: Increase | E26: Decrease
A27: Jun | B27: OTB | C27: =IF(OTB!#REF!="","",OTB!#REF!) -> #REF! | D27: =IF(OTB!#REF!>0,OTB!#REF!,0) -> #REF! | E27: =IF(OTB!#REF!<0,ABS(OTB!#REF!),0) -> #REF!
A28: Jun | B28: LY | C28: =IF(OTB!#REF!="","",OTB!#REF!) -> #REF! | D28: =IF(OTB!#REF!>0,OTB!#REF!,0) -> #REF! | E28: =IF(OTB!#REF!<0,ABS(OTB!#REF!),0) -> #REF!
A29: Jul | B29: OTB | C29: =IF(OTB!G13="","",OTB!H13) -> 0.24516129 | D29: =IF(OTB!I13>0,OTB!I13,0) -> 0 | E29: =IF(OTB!I13<0,ABS(OTB!I13),0) -> 0
A30: Jul | B30: LY | C30: =IF(OTB!G13="","",OTB!J13) -> 0.40860215 | D30: =IF(OTB!K13>0,OTB!K13,0) -> 0 | E30: =IF(OTB!K13<0,ABS(OTB!K13),0) -> 0.16344086
A31: Aug | B31: OTB | C31: =IF(OTB!G14="","",OTB!H14) -> 0.034408602 | D31: =IF(OTB!I14>0,OTB!I14,0) -> 0.077419355 | E31: =IF(OTB!I14<0,ABS(OTB!I14),0) -> 0
A32: Aug | B32: LY | C32: =IF(OTB!G14="","",OTB!J14) -> 0.48387097 | D32: =IF(OTB!K14>0,OTB!K14,0) -> 0 | E32: =IF(OTB!K14<0,ABS(OTB!K14),0) -> 0.37204301
A33: Sept | B33: OTB | C33: =IF(OTB!G15="","",OTB!H15) -> 0.12888889 | D33: =IF(OTB!I15>0,OTB!I15,0) -> 0.0066666667 | E33: =IF(OTB!I15<0,ABS(OTB!I15),0) -> 0
A34: Sept | B34: LY | C34: =IF(OTB!G15="","",OTB!J15) -> 0.57555556 | D34: =IF(OTB!K15>0,OTB!K15,0) -> 0 | E34: =IF(OTB!K15<0,ABS(OTB!K15),0) -> 0.44
A35: Oct | B35: OTB | C35: =IF(OTB!G16="","",OTB!H16) -> 0.0043010753 | D35: =IF(OTB!I16>0,OTB!I16,0) -> 0 | E35: =IF(OTB!I16<0,ABS(OTB!I16),0) -> 0
A36: Oct | B36: LY | C36: =IF(OTB!G16="","",OTB!J16) -> 0.6688172 | D36: =IF(OTB!K16>0,OTB!K16,0) -> 0 | E36: =IF(OTB!K16<0,ABS(OTB!K16),0) -> 0.66451613
A37: Nov | B37: OTB | C37: =IF(OTB!G17="","",OTB!H17) -> 0.0044444444 | D37: =IF(OTB!I17>0,OTB!I17,0) -> 0.046666667 | E37: =IF(OTB!I17<0,ABS(OTB!I17),0) -> 0
A38: Nov | B38: LY | C38: =IF(OTB!G17="","",OTB!J17) -> 0.86 | D38: =IF(OTB!K17>0,OTB!K17,0) -> 0 | E38: =IF(OTB!K17<0,ABS(OTB!K17),0) -> 0.80888889
A39: Dec | B39: OTB | C39: =IF(OTB!G19="","",OTB!H19) -> 0.038709677 | D39: =IF(OTB!I19>0,OTB!I19,0) -> 0.0064516129 | E39: =IF(OTB!I19<0,ABS(OTB!I19),0) -> 0
A40: Dec | B40: LY | C40: =IF(OTB!G19="","",OTB!J19) -> 0.67741935 | D40: =IF(OTB!K19>0,OTB!K19,0) -> 0 | E40: =IF(OTB!K19<0,ABS(OTB!K19),0) -> 0.63225806
...

Sheet YOY
A1: Revenue | B1: 2020 | C1: 2021 | D1: 2022 | E1: 2023 | F1: 2024 | G1: 2025 | H1: 2026 | I1: 2026 vs 2025
A2: Jan | I2: =H2-G2 -> 0 | J2: =(H2-G2)/G2 -> #DIV/0!
A3: Feb | I3: =H3-G3 -> 0 | J3: =(H3-G3)/G3 -> #DIV/0!
A4: Mar | I4: =H4-G4 -> 0 | J4: =(H4-G4)/G4 -> #DIV/0!
A5: Apr | I5: =H5-G5 -> 0 | J5: =(H5-G5)/G5 -> #DIV/0!
A6: May | I6: =H6-G6 -> 0 | J6: =(H6-G6)/G6 -> #DIV/0!
A7: Jun | I7: =H7-G7 -> 0 | J7: =(H7-G7)/G7 -> #DIV/0!
A8: Jul | I8: =H8-G8 -> 0 | J8: =(H8-G8)/G8 -> #DIV/0!
A9: Aug | I9: =H9-G9 -> 0 | J9: =(H9-G9)/G9 -> #DIV/0!
A10: Sept | I10: =H10-G10 -> 0 | J10: =(H10-G10)/G10 -> #DIV/0!
A11: Oct | I11: =H11-G11 -> 0 | J11: =(H11-G11)/G11 -> #DIV/0!
A12: Nov | I12: =H12-G12 -> 0 | J12: =(H12-G12)/G12 -> #DIV/0!
A13: Dec | I13: =H13-G13 -> 0 | J13: =(H13-G13)/G13 -> #DIV/0!
A14: TOTAL | B14: =SUM(B2:B13) -> 0 | C14: =SUM(C2:C13) -> 0 | D14: =SUM(D2:D13) -> 0 | E14: =SUM(E2:E13) -> 0 | F14: =SUM(F2:F13) -> 0 | G14: =SUM(G2:G13) -> 0 | H14: =SUM(H2:H13) -> 0 | I14: =H14-G14 -> 0 | J14: =(H14-G14)/G14 -> #DIV/0!
A15: Room Nights | B15: 2020 | C15: 2021 | D15: 2022 | E15: 2023 | F15: 2024 | G15: 2025 | H15: 2026 | I15: 2026 vs 2025
A16: Jan | I16: =H16-G16 -> 0 | J16: =(H16-G16)/G16 -> #DIV/0!
A17: Feb | I17: =H17-G17 -> 0 | J17: =(H17-G17)/G17 -> #DIV/0!
A18: Mar | I18: =H18-G18 -> 0 | J18: =(H18-G18)/G18 -> #DIV/0!
A19: Apr | I19: =H19-G19 -> 0 | J19: =(H19-G19)/G19 -> #DIV/0!
A20: May | I20: =H20-G20 -> 0 | J20: =(H20-G20)/G20 -> #DIV/0!
A21: Jun | I21: =H21-G21 -> 0 | J21: =(H21-G21)/G21 -> #DIV/0!
A22: Jul | I22: =H22-G22 -> 0 | J22: =(H22-G22)/G22 -> #DIV/0!
A23: Aug | I23: =H23-G23 -> 0 | J23: =(H23-G23)/G23 -> #DIV/0!
A24: Sept | I24: =H24-G24 -> 0 | J24: =(H24-G24)/G24 -> #DIV/0!
A25: Oct | I25: =H25-G25 -> 0 | J25: =(H25-G25)/G25 -> #DIV/0!
A26: Nov | I26: =H26-G26 -> 0 | J26: =(H26-G26)/G26 -> #DIV/0!
A27: Dec | I27: =H27-G27 -> 0 | J27: =(H27-G27)/G27 -> #DIV/0!
A28: TOTAL | B28: =SUM(B16:B27) -> 0 | C28: =SUM(C16:C27) -> 0 | D28: =SUM(D16:D27) -> 0 | E28: =SUM(E16:E27) -> 0 | F28: =SUM(F16:F27) -> 0 | G28: =SUM(G16:G27) -> 0 | H28: =SUM(H16:H27) -> 0 | I28: =H28-G28 -> 0 | J28: =(H28-G28)/G28 -> #DIV/0!
A29: Occupancy | B29: 2020 | C29: 2021 | D29: 2022 | E29: 2023 | F29: 2024 | G29: 2025 | H29: 2026 | I29: 2026 vs 2025
A30: Jan | B30: =(B16/310) -> 0 | C30: =(C16/310) -> 0 | D30: =(D16/310) -> 0 | E30: =(E16/310) -> 0 | F30: =(F16/403) -> 0 | G30: =(G16/465) -> 0 | H30: =(H16/465) -> 0 | I30: =H30-G30 -> 0 | J30: =(H30-G30)/G30 -> #DIV/0!
A31: Feb | B31: =(B17/290) -> 0 | C31: =(C17/280) -> 0 | D31: =(D17/280) -> 0 | E31: =(E17/280) -> 0 | F31: =(F17/377) -> 0 | G31: =(G17/420) -> 0 | H31: =(H17/420) -> 0 | I31: =H31-G31 -> 0 | J31: =(H31-G31)/G31 -> #DIV/0!
A32: Mar | B32: =(B18/310) -> 0 | C32: =(C18/310) -> 0 | D32: =(D18/310) -> 0 | E32: =(E18/310) -> 0 | F32: =(F18/403) -> 0 | G32: =(G18/465) -> 0 | H32: =(H18/465) -> 0 | I32: =H32-G32 -> 0 | J32: =(H32-G32)/G32 -> #DIV/0!
A33: Apr | B33: =(B19/300) -> 0 | C33: =(C19/300) -> 0 | D33: =(D19/300) -> 0 | E33: =(E19/300) -> 0 | F33: =(F19/390) -> 0 | G33: =(G19/350) -> 0 | H33: =(H19/350) -> 0 | I33: =H33-G33 -> 0 | J33: =(H33-G33)/G33 -> #DIV/0!
A34: May | B34: =(B20/310) -> 0 | C34: =(C20/310) -> 0 | D34: =(D20/310) -> 0 | E34: =(E20/310) -> 0 | F34: =(F20/465) -> 0 | G34: =(G20/465) -> 0 | H34: =(H20/465) -> 0 | I34: =H34-G34 -> 0 | J34: =(H34-G34)/G34 -> #DIV/0!
A35: Jun | B35: =(B21/300) -> 0 | C35: =(C21/300) -> 0 | D35: =(D21/300) -> 0 | E35: =(E21/300) -> 0 | F35: =(F21/450) -> 0 | G35: =(G21/450) -> 0 | H35: =(H21/450) -> 0 | I35: =H35-G35 -> 0 | J35: =(H35-G35)/G35 -> #DIV/0!
A36: Jul | B36: =(B22/310) -> 0 | C36: =(C22/310) -> 0 | D36: =(D22/310) -> 0 | E36: =(E22/310) -> 0 | F36: =(F22/465) -> 0 | G36: =(G22/465) -> 0 | H36: =(H22/465) -> 0 | I36: =H36-G36 -> 0 | J36: =(H36-G36)/G36 -> #DIV/0!
A37: Aug | B37: =(B23/310) -> 0 | C37: =(C23/310) -> 0 | D37: =(D23/310) -> 0 | E37: =(E23/310) -> 0 | F37: =(F23/465) -> 0 | G37: =(G23/465) -> 0 | H37: =(H23/465) -> 0 | I37: =H37-G37 -> 0 | J37: =(H37-G37)/G37 -> #DIV/0!
A38: Sept | B38: =(B24/300) -> 0 | C38: =(C24/300) -> 0 | D38: =(D24/300) -> 0 | E38: =(E24/300) -> 0 | F38: =(F24/450) -> 0 | G38: =(G24/450) -> 0 | H38: =(H24/450) -> 0 | I38: =H38-G38 -> 0 | J38: =(H38-G38)/G38 -> #DIV/0!
A39: Oct | B39: =(B25/310) -> 0 | C39: =(C25/310) -> 0 | D39: =(D25/310) -> 0 | E39: =(E25/403) -> 0 | F39: =(F25/465) -> 0 | G39: =(G25/465) -> 0 | H39: =(H25/465) -> 0 | I39: =H39-G39 -> 0 | J39: =(H39-G39)/G39 -> #DIV/0!
A40: Nov | B40: =(B26/300) -> 0 | C40: =(C26/300) -> 0 | D40: =(D26/300) -> 0 | E40: =(E26/390) -> 0 | F40: =(F26/450) -> 0 | G40: =(G26/450) -> 0 | H40: =(H26/450) -> 0 | I40: =H40-G40 -> 0 | J40: =(H40-G40)/G40 -> #DIV/0!
...

Sheet Sheet1
A1: | YOY
B2: 2026 | C2: 2025 | D2: 2026 vs 2025 | F2: 2024 | G2: 2025 vs 2024 | M2: 2025 Target | N2: 2025 vs Target | P2: 2026 Target | Q2: 2026 vs Target
A3: Jan | D3: =B3-C3 -> 0 | E3: =(B3-C3)/C3 -> #DIV/0! | G3: =C3-F3 -> 0 | H3: =(C3-F3)/F3 -> #DIV/0! | M3: =C3*1.1 -> 0 | N3: =C3-M3 -> 0 | O3: =(C3-M3)/M3 -> #DIV/0! | P3: =B3*1.1 -> 0 | Q3: =B3-P3 -> 0 | R3: =(B3-P3)/P3 -> #DIV/0!
A4: Feb | D4: =B4-C4 -> 0 | E4: =(B4-C4)/C4 -> #DIV/0! | G4: =C4-F4 -> 0 | H4: =(C4-F4)/F4 -> #DIV/0! | M4: =C4*1.1 -> 0 | N4: =C4-M4 -> 0 | O4: =(C4-M4)/M4 -> #DIV/0! | P4: =B4*1.1 -> 0 | Q4: =B4-P4 -> 0 | R4: =(B4-P4)/P4 -> #DIV/0!
A5: Mar | D5: =B5-C5 -> 0 | E5: =(B5-C5)/C5 -> #DIV/0! | G5: =C5-F5 -> 0 | H5: =(C5-F5)/F5 -> #DIV/0! | M5: =C5*1.1 -> 0 | N5: =C5-M5 -> 0 | O5: =(C5-M5)/M5 -> #DIV/0! | P5: =B5*1.1 -> 0 | Q5: =B5-P5 -> 0 | R5: =(B5-P5)/P5 -> #DIV/0!
A6: Apr | D6: =B6-C6 -> 0 | E6: =(B6-C6)/C6 -> #DIV/0! | G6: =C6-F6 -> 0 | H6: =(C6-F6)/F6 -> #DIV/0! | M6: =C6*1.1 -> 0 | N6: =C6-M6 -> 0 | O6: =(C6-M6)/M6 -> #DIV/0! | P6: =B6*1.1 -> 0 | Q6: =B6-P6 -> 0 | R6: =(B6-P6)/P6 -> #DIV/0!
A7: May | D7: =B7-C7 -> 0 | E7: =(B7-C7)/C7 -> #DIV/0! | G7: =C7-F7 -> 0 | H7: =(C7-F7)/F7 -> #DIV/0! | M7: =C7*1.1 -> 0 | N7: =C7-M7 -> 0 | O7: =(C7-M7)/M7 -> #DIV/0! | P7: =B7*1.1 -> 0 | Q7: =B7-P7 -> 0 | R7: =(B7-P7)/P7 -> #DIV/0!
A8: Jun | D8: =B8-C8 -> 0 | E8: =(B8-C8)/C8 -> #DIV/0! | G8: =C8-F8 -> 0 | H8: =(C8-F8)/F8 -> #DIV/0! | M8: =C8*1.1 -> 0 | N8: =C8-M8 -> 0 | O8: =(C8-M8)/M8 -> #DIV/0! | P8: =B8*1.1 -> 0 | Q8: =B8-P8 -> 0 | R8: =(B8-P8)/P8 -> #DIV/0!
A9: Jul | D9: =B9-C9 -> 0 | E9: =(B9-C9)/C9 -> #DIV/0! | G9: =C9-F9 -> 0 | H9: =(C9-F9)/F9 -> #DIV/0! | M9: =C9*1.1 -> 0 | N9: =C9-M9 -> 0 | O9: =(C9-M9)/M9 -> #DIV/0! | P9: =B9*1.1 -> 0 | Q9: =B9-P9 -> 0 | R9: =(B9-P9)/P9 -> #DIV/0!
A10: Aug | D10: =B10-C10 -> 0 | E10: =(B10-C10)/C10 -> #DIV/0! | G10: =C10-F10 -> 0 | H10: =(C10-F10)/F10 -> #DIV/0! | M10: =C10*1.1 -> 0 | N10: =C10-M10 -> 0 | O10: =(C10-M10)/M10 -> #DIV/0! | P10: =B10*1.1 -> 0 | Q10: =B10-P10 -> 0 | R10: =(B10-P10)/P10 -> #DIV/0!
A11: Sep | D11: =B11-C11 -> 0 | E11: =(B11-C11)/C11 -> #DIV/0! | G11: =C11-F11 -> 0 | H11: =(C11-F11)/F11 -> #DIV/0! | M11: =C11*1.1 -> 0 | N11: =C11-M11 -> 0 | O11: =(C11-M11)/M11 -> #DIV/0! | P11: =B11*1.1 -> 0 | Q11: =B11-P11 -> 0 | R11: =(B11-P11)/P11 -> #DIV/0!
A12: Oct | D12: =B12-C12 -> 0 | E12: =(B12-C12)/C12 -> #DIV/0! | G12: =C12-F12 -> 0 | H12: =(C12-F12)/F12 -> #DIV/0! | M12: =C12*1.1 -> 0 | N12: =C12-M12 -> 0 | O12: =(C12-M12)/M12 -> #DIV/0! | P12: =B12*1.1 -> 0 | Q12: =B12-P12 -> 0 | R12: =(B12-P12)/P12 -> #DIV/0!
A13: Nov | D13: =B13-C13 -> 0 | E13: =(B13-C13)/C13 -> #DIV/0! | G13: =C13-F13 -> 0 | H13: =(C13-F13)/F13 -> #DIV/0! | M13: =C13*1.1 -> 0 | N13: =C13-M13 -> 0 | O13: =(C13-M13)/M13 -> #DIV/0! | P13: =B13*1.1 -> 0 | Q13: =B13-P13 -> 0 | R13: =(B13-P13)/P13 -> #DIV/0!
A14: Dec | D14: =B14-C14 -> 0 | E14: =(B14-C14)/C14 -> #DIV/0! | G14: =C14-F14 -> 0 | H14: =(C14-F14)/F14 -> #DIV/0! | M14: =C14*1.1 -> 0 | N14: =C14-M14 -> 0 | O14: =(C14-M14)/M14 -> #DIV/0! | P14: =B14*1.1 -> 0 | Q14: =B14-P14 -> 0 | R14: =(B14-P14)/P14 -> #DIV/0!
A15: TOTAL | B15: =SUM(B3:B14) -> 0 | C15: =SUM(C3:C14) -> 0 | D15: =SUM(D3:D14) -> 0 | E15: =(B15-C15)/C15 -> #DIV/0! | F15: =SUM(F3:F14) -> 0 | G15: =SUM(G3:G14) -> 0 | H15: =(C15-F15)/F15 -> #DIV/0! | M15: =SUM(M3:M14) -> 0 | N15: =C15-M15 -> 0 | O15: =(C15-M15)/M15 -> #DIV/0! | P15: =SUM(P3:P14) -> 0 | Q15: =B15-P15 -> 0 | R15: =(B15-P15)/P15 -> #DIV/0!
A16: Room Nights | G16: Occupancy
B17: 2026 | C17: 2025 | D17: 2026 vs 2025 | E17: 2024 | F17: 2026 vs 2025 | G17: 2026 | H17: 2025 | I17: 2026 vs 2025 | J17: 2024 | K17: 2025 vs 2024
A18: Jan | D18: =B18-C18 -> 0 | F18: =C18-E18 -> 0 | G18: =B18 -> 0 | H18: =C18 -> 0 | I18: =G18-H18 -> 0 | J18: =E18 -> 0 | K18: =H18-J18 -> 0 | M18: 7 Rooms
A19: Feb | D19: =B19-C19 -> 0 | F19: =C19-E19 -> 0 | G19: =B19 -> 0 | H19: =C19 -> 0 | I19: =G19-H19 -> 0 | J19: =E19 -> 0 | K19: =H19-J19 -> 0 | M19: 28 = 196
A20: Mar | D20: =B20-C20 -> 0 | F20: =C20-E20 -> 0 | G20: =B20 -> 0 | H20: =C20 -> 0 | I20: =G20-H20 -> 0 | J20: =E20 -> 0 | K20: =H20-J20 -> 0 | M20: 29 = 203
A21: Apr | D21: =B21-C21 -> 0 | F21: =C21-E21 -> 0 | G21: =B21 -> 0 | H21: =C21 -> 0 | I21: =G21-H21 -> 0 | J21: =E21 -> 0 | K21: =H21-J21 -> 0 | M21: 30 = 210
A22: May | D22: =B22-C22 -> 0 | F22: =C22-E22 -> 0 | G22: =B22 -> 0 | H22: =C22 -> 0 | I22: =G22-H22 -> 0 | J22: =E22 -> 0 | K22: =H22-J22 -> 0 | M22: 31 = 217
A23: Jun | D23: =B23-C23 -> 0 | F23: =C23-E23 -> 0 | G23: =B23 -> 0 | H23: =C23 -> 0 | I23: =G23-H23 -> 0 | J23: =E23 -> 0 | K23: =H23-J23 -> 0
A24: Jul | D24: =B24-C24 -> 0 | F24: =C24-E24 -> 0 | G24: =B24 -> 0 | H24: =C24 -> 0 | I24: =G24-H24 -> 0 | J24: =E24 -> 0 | K24: =H24-J24 -> 0
A25: Aug | D25: =B25-C25 -> 0 | F25: =C25-E25 -> 0 | G25: =B25 -> 0 | H25: =C25 -> 0 | I25: =G25-H25 -> 0 | J25: =E25 -> 0 | K25: =H25-J25 -> 0
A26: Sep | D26: =B26-C26 -> 0 | F26: =C26-E26 -> 0 | G26: =B26 -> 0 | H26: =C26 -> 0 | I26: =G26-H26 -> 0 | J26: =E26 -> 0 | K26: =H26-J26 -> 0
A27: Oct | D27: =B27-C27 -> 0 | F27: =C27-E27 -> 0 | G27: =B27 -> 0 | H27: =C27 -> 0 | I27: =G27-H27 -> 0 | J27: =E27 -> 0 | K27: =H27-J27 -> 0
A28: Nov | D28: =B28-C28 -> 0 | F28: =C28-E28 -> 0 | G28: =B28 -> 0 | H28: =C28 -> 0 | I28: =G28-H28 -> 0 | J28: =E28 -> 0 | K28: =H28-J28 -> 0
A29: Dec | D29: =B29-C29 -> 0 | F29: =C29-E29 -> 0 | G29: =B29 -> 0 | H29: =C29 -> 0 | I29: =G29-H29 -> 0 | J29: =E29 -> 0 | K29: =H29-J29 -> 0
A30: ADR
B31: 2026 | C31: 2025 | D31: 2026 vs 2025 | F31: 2024 | G31: 2025 vs 2024
A32: Jan | B32: =B3/B18 -> #DIV/0! | C32: =C3/C18 -> #DIV/0! | D32: =B32-C32 -> #DIV/0! | E32: =(B32-C32)/C32 -> #DIV/0! | F32: =F3/E18 -> #DIV/0! | G32: =C32-F32 -> #DIV/0! | H32: =(C32-F32)/F32 -> #DIV/0!
A33: Feb | B33: =B4/B19 -> #DIV/0! | C33: =C4/C19 -> #DIV/0! | D33: =B33-C33 -> #DIV/0! | E33: =(B33-C33)/C33 -> #DIV/0! | F33: =F4/E19 -> #DIV/0! | G33: =C33-F33 -> #DIV/0! | H33: =(C33-F33)/F33 -> #DIV/0!
A34: Mar | B34: =B5/B20 -> #DIV/0! | C34: =C5/C20 -> #DIV/0! | D34: =B34-C34 -> #DIV/0! | E34: =(B34-C34)/C34 -> #DIV/0! | F34: =F5/E20 -> #DIV/0! | G34: =C34-F34 -> #DIV/0! | H34: =(C34-F34)/F34 -> #DIV/0!
A35: Apr | B35: =B6/B21 -> #DIV/0! | C35: =C6/C21 -> #DIV/0! | D35: =B35-C35 -> #DIV/0! | E35: =(B35-C35)/C35 -> #DIV/0! | F35: =F6/E21 -> #DIV/0! | G35: =C35-F35 -> #DIV/0! | H35: =(C35-F35)/F35 -> #DIV/0!
A36: May | B36: =B7/B22 -> #DIV/0! | C36: =C7/C22 -> #DIV/0! | D36: =B36-C36 -> #DIV/0! | E36: =(B36-C36)/C36 -> #DIV/0! | F36: =F7/E22 -> #DIV/0! | G36: =C36-F36 -> #DIV/0! | H36: =(C36-F36)/F36 -> #DIV/0!
A37: Jun | B37: =B8/B23 -> #DIV/0! | C37: =C8/C23 -> #DIV/0! | D37: =B37-C37 -> #DIV/0! | E37: =(B37-C37)/C37 -> #DIV/0! | F37: =F8/E23 -> #DIV/0! | G37: =C37-F37 -> #DIV/0! | H37: =(C37-F37)/F37 -> #DIV/0!
A38: Jul | B38: =B9/B24 -> #DIV/0! | C38: =C9/C24 -> #DIV/0! | D38: =B38-C38 -> #DIV/0! | E38: =(B38-C38)/C38 -> #DIV/0! | F38: =F9/E24 -> #DIV/0! | G38: =C38-F38 -> #DIV/0! | H38: =(C38-F38)/F38 -> #DIV/0!
A39: Aug | B39: =B10/B25 -> #DIV/0! | C39: =C10/C25 -> #DIV/0! | D39: =B39-C39 -> #DIV/0! | E39: =(B39-C39)/C39 -> #DIV/0! | F39: =F10/E25 -> #DIV/0! | G39: =C39-F39 -> #DIV/0! | H39: =(C39-F39)/F39 -> #DIV/0!
A40: Sep | B40: =B11/B26 -> #DIV/0! | C40: =C11/C26 -> #DIV/0! | D40: =B40-C40 -> #DIV/0! | E40: =(B40-C40)/C40 -> #DIV/0! | F40: =F11/E26 -> #DIV/0! | G40: =C40-F40 -> #DIV/0! | H40: =(C40-F40)/F40 -> #DIV/0!
...

Sheet Fin Year
A1: 55 on Main Guest House & Spa | Financial Year
B2: 2025 | C2: 2024 | D2: 2025 vs 2024 | F2: Target (+10%) | G2: 2025 vs Target
A3: Jan | B3: 290938.14 | C3: 228038.64 | D3: =B3-C3 -> 62899.5 | E3: =(B3-C3)/C3 -> 0.27582825 | F3: =C3*1.1 -> 250842.5 | G3: =B3-F3 -> 40095.636 | H3: =(B3-F3)/F3 -> 0.15984387
A4: Feb | B4: 370732.61 | C4: 361297.38 | D4: =B4-C4 -> 9435.23 | E4: =(B4-C4)/C4 -> 0.026114859 | F4: =C4*1.1 -> 397427.12 | G4: =B4-F4 -> -26694.508 | H4: =(B4-F4)/F4 -> -0.06716831
A5: Mar | B5: 337311.68 | C5: 336377.52 | D5: =B5-C5 -> 934.16 | E5: =(B5-C5)/C5 -> 0.0027771178 | F5: =C5*1.1 -> 370015.27 | G5: =B5-F5 -> -32703.592 | H5: =(B5-F5)/F5 -> -0.088384438
A6: Apr | B6: 197918.58 | C6: 207915.67 | D6: =B6-C6 -> -9997.09 | E6: =(B6-C6)/C6 -> -0.048082427 | F6: =C6*1.1 -> 228707.24 | G6: =B6-F6 -> -30788.657 | H6: =(B6-F6)/F6 -> -0.13462039
A7: May | B7: 230486.7 | C7: 297538.78 | D7: =B7-C7 -> -67052.08 | E7: =(B7-C7)/C7 -> -0.22535577 | F7: =C7*1.1 -> 327292.66 | G7: =B7-F7 -> -96805.958 | H7: =(B7-F7)/F7 -> -0.29577797
A8: Jun | B8: 188786.06 | C8: 258087.04 | D8: =B8-C8 -> -69300.98 | E8: =(B8-C8)/C8 -> -0.26851786 | F8: =C8*1.1 -> 283895.74 | G8: =B8-F8 -> -95109.684 | H8: =(B8-F8)/F8 -> -0.33501624
A9: Jul | B9: 176855.65 | C9: 193845.47 | D9: =B9-C9 -> -16989.82 | E9: =(B9-C9)/C9 -> -0.087646206 | F9: =C9*1.1 -> 213230.02 | G9: =B9-F9 -> -36374.367 | H9: =(B9-F9)/F9 -> -0.17058746
A10: Aug | B10: 226582.83 | C10: 160018.71 | D10: =B10-C10 -> 66564.12 | E10: =(B10-C10)/C10 -> 0.41597711 | F10: =C10*1.1 -> 176020.58 | G10: =B10-F10 -> 50562.249 | H10: =(B10-F10)/F10 -> 0.28725192
A11: Sep | B11: 247125.59 | C11: 201721.21 | D11: =B11-C11 -> 45404.38 | E11: =(B11-C11)/C11 -> 0.22508481 | F11: =C11*1.1 -> 221893.33 | G11: =B11-F11 -> 25232.259 | H11: =(B11-F11)/F11 -> 0.11371346
A12: Oct | B12: 311992.72 | C12: 300450.93 | D12: =B12-C12 -> 11541.79 | E12: =(B12-C12)/C12 -> 0.038414892 | F12: =C12*1.1 -> 330496.02 | G12: =B12-F12 -> -18503.303 | H12: =(B12-F12)/F12 -> -0.055986462
A13: Nov | B13: 366637.7 | C13: 329332.85 | D13: =B13-C13 -> 37304.85 | E13: =(B13-C13)/C13 -> 0.113274 | F13: =C13*1.1 -> 362266.14 | G13: =B13-F13 -> 4371.565 | H13: =(B13-F13)/F13 -> 0.012067275
A14: Dec | B14: 385027.26 | C14: 305756.28 | D14: =B14-C14 -> 79270.98 | E14: =(B14-C14)/C14 -> 0.25926198 | F14: =C14*1.1 -> 336331.91 | G14: =B14-F14 -> 48695.352 | H14: =(B14-F14)/F14 -> 0.14478362
A15: TOTAL | B15: =SUM(B3:B14) -> 3330395.5 | C15: =SUM(C3:C14) -> 3180380.5 | D15: =B15-C15 -> 150015.04 | E15: =(B15-C15)/C15 -> 0.047168897 | F15: =SUM(F3:F14) -> 3498418.5 | G15: =B15-F15 -> -168023.01 | H15: =(B15-F15)/F15 -> -0.048028275
A16: Room Nights | E16: Occupancy
B17: 2025 | C17: 2024 | D17: 2025 vs 2024 | F17: 2025 | G17: 2024 | H17: 2025 vs 2024
A18: Jan | B18: 259 | C18: 204 | D18: =B18-C18 -> 55 | F18: =B18/465 -> 0.55698925 | G18: =C18/403 -> 0.50620347 | H18: =F18-G18 -> 0.050785773 | J18: 15 Rooms | K18: 13 Rooms
A19: Feb | B19: 341 | C19: 314 | D19: =B19-C19 -> 27 | F19: =B19/420 -> 0.81190476 | G19: =C19/377 -> 0.83289125 | H19: =F19-G19 -> -0.020986485 | J19: 28 = 420 | K19: Until May 2024
A20: Mar | B20: 342 | C20: 336 | D20: =B20-C20 -> 6 | F20: =B20/465 -> 0.73548387 | G20: =C20/403 -> 0.8337469 | H20: =F20-G20 -> -0.098263027 | J20: 29 = 435 | K20: 28 = 364
A21: Apr | B21: 185 | C21: 223 | D21: =B21-C21 -> -38 | F21: =B21/450 -> 0.41111111 | G21: =C21/390 -> 0.57179487 | H21: =F21-G21 -> -0.16068376 | J21: 30 = 450 | K21: 29 = 377
A22: May | B22: 229 | C22: 343 | D22: =B22-C22 -> -114 | F22: =B22/465 -> 0.49247312 | G22: =C22/465 -> 0.73763441 | H22: =F22-G22 -> -0.24516129 | J22: 31 = 465 | K22: 30 = 390
A23: Jun | B23: 199 | C23: 311 | D23: =B23-C23 -> -112 | F23: =B23/450 -> 0.44222222 | G23: =C23/450 -> 0.69111111 | H23: =F23-G23 -> -0.24888889 | K23: 31 = 403
A24: Jul | B24: 190 | C24: 262 | D24: =B24-C24 -> -72 | F24: =B24/465 -> 0.40860215 | G24: =C24/465 -> 0.56344086 | H24: =F24-G24 -> -0.15483871
A25: Aug | B25: 225 | C25: 183 | D25: =B25-C25 -> 42 | F25: =B25/465 -> 0.48387097 | G25: =C25/465 -> 0.39354839 | H25: =F25-G25 -> 0.090322581
A26: Sep | B26: 258 | C26: 215 | D26: =B26-C26 -> 43 | F26: =B26/450 -> 0.57333333 | G26: =C26/450 -> 0.47777778 | H26: =F26-G26 -> 0.095555556
A27: Oct | B27: 303 | C27: 332 | D27: =B27-C27 -> -29 | F27: =B27/465 -> 0.6516129 | G27: =C27/465 -> 0.71397849 | H27: =F27-G27 -> -0.062365591
A28: Nov | B28: 387 | C28: 384 | D28: =B28-C28 -> 3 | F28: =B28/450 -> 0.86 | G28: =C28/450 -> 0.85333333 | H28: =F28-G28 -> 0.0066666667
A29: Dec | B29: 299 | C29: 253 | D29: =B29-C29 -> 46 | F29: =B29/465 -> 0.64301075 | G29: =C29/465 -> 0.54408602 | H29: =F29-G29 -> 0.098924731
A30: ADR
B31: 2025 | C31: 2024 | D31: 2025 vs 2024
A32: Jan | B32: =B3/B18 -> 1123.3133 | C32: =C3/C18 -> 1117.8365 | D32: =B32-C32 -> 5.4768113 | E32: =(B32-C32)/C32 -> 0.0048994745
A33: Feb | B33: =B4/B19 -> 1087.1924 | C33: =C4/C19 -> 1150.6286 | D33: =B33-C33 -> -63.436194 | E33: =(B33-C33)/C33 -> -0.055131772
A34: Mar | B34: =B5/B20 -> 986.29146 | C34: =C5/C20 -> 1001.1236 | D34: =B34-C34 -> -14.832109 | E34: =(B34-C34)/C34 -> -0.014815463
A35: Apr | B35: =B6/B21 -> 1069.8302 | C35: =C6/C21 -> 932.35726 | D35: =B35-C35 -> 137.4729 | E35: =(B35-C35)/C35 -> 0.14744659
A36: May | B36: =B7/B22 -> 1006.4921 | C36: =C7/C22 -> 867.46 | D36: =B36-C36 -> 139.03214 | E36: =(B36-C36)/C36 -> 0.16027499
A37: Jun | B37: =B8/B23 -> 948.67367 | C37: =C8/C23 -> 829.86186 | D37: =B37-C37 -> 118.8118 | E37: =(B37-C37)/C37 -> 0.14317058
A38: Jul | B38: =B9/B24 -> 930.81921 | C38: =C9/C24 -> 739.86821 | D38: =B38-C38 -> 190.951 | E38: =(B38-C38)/C38 -> 0.25808786
A39: Aug | B39: =B10/B25 -> 1007.0348 | C39: =C10/C25 -> 874.41918 | D39: =B39-C39 -> 132.61562 | E39: =(B39-C39)/C39 -> 0.15166138
A40: Sep | B40: =B11/B26 -> 957.85112 | C40: =C11/C26 -> 938.23819 | D40: =B40-C40 -> 19.612938 | E40: =(B40-C40)/C40 -> 0.020904007
...
